Workbook

Sheet สัปดาห์ที่ 1
A1: แบบบันทึกการเล่นตามมุมประสบการณ์ของเด็กปฐมวัยรายสัปดาห์
A2: โรงเรียนเทศบาลบ้านเพ ๑ สังกัดกองการศึกษา เทศบาลตำบลบ้านเพ ชั้น อ.๑/๓
A3: สัปดาห์ที่ 1 | D3: วันที่ .............. ถึง .............. เดือน .............. พ.ศ. ..............
D4: มุมเสริมประสบการณ์แหล่งเรียนรู้ นอกห้องเรียน | J4: สรุปมุม ที่เล่น | K4: หมายเหตุ
A5: ที่ | B5: ชื่อ | C5: นามสกุล | D5: คัดแยกขยะ (mRS) | E5: ขยะอินทรีย์ | F5: แปลงปลูกผัก | G5: ห้องแหล่ง เรียนรู้ | H5: ห้อง คอมพิวเตอร์ | I5: เครื่องหมาย จราจร | J5: จำนวน มุม
A6: 1 | B6: เด็กชายชวคริต | J6: =COUNTIF(D6:I6,"✓") -> 0
A7: 2 | B7: เด็กชายตะวัน | C7: เจริญผล | J7: =COUNTIF(D7:I7,"✓") -> 0
A8: 3 | B8: เด็กชายภิมรภัทร | C8: คำนึงคิด | J8: =COUNTIF(D8:I8,"✓") -> 0
A9: 4 | B9: เด็กชายธิรพงศ์ | C9: อู่อ่อน | J9: =COUNTIF(D9:I9,"✓") -> 0
A10: 5 | B10: เด็กชายสรวิชญ์ | C10: เตชสงค์ | J10: =COUNTIF(D10:I10,"✓") -> 0
A11: 6 | B11: เด็กหญิงธัญญามาศ | C11: วิมลศรี | J11: =COUNTIF(D11:I11,"✓") -> 0
A12: 7 | B12: เด็กชายวสิน | C12: เม็ด | J12: =COUNTIF(D12:I12,"✓") -> 0
A13: 8 | B13: เด็กหญิงลีนา | C13: ออง | J13: =COUNTIF(D13:I13,"✓") -> 0
A14: 9 | B14: เด็กชายพชร | C14: ธรรมหลวง | J14: =COUNTIF(D14:I14,"✓") -> 0
A15: 10 | B15: เด็กชายศิวกรณ์ | C15: ถึงวงศ์ | J15: =COUNTIF(D15:I15,"✓") -> 0
A16: 11 | B16: เด็กหญิงนิตยาภรณ์ | C16: กาสิงห์ | J16: =COUNTIF(D16:I16,"✓") -> 0
A17: 12 | B17: เด็กชายภาณุวิชญ์ | C17: โยชนะ | J17: =COUNTIF(D17:I17,"✓") -> 0
A18: 13 | B18: เด็กหญิงธรรณชนก | C18: ขอบอรัญ | J18: =COUNTIF(D18:I18,"✓") -> 0
... A23: 18 | B23: เด็กหญิงพิชญาพร | C23: อุดร | J23: =COUNTIF(D23:I23,"✓") -> 0
A24: 19 | J24: =COUNTIF(D24:I24,"✓") -> 0
A25: 20 | J25: =COUNTIF(D25:I25,"✓") -> 0
A26: 21 | J26: =COUNTIF(D26:I26,"✓") -> 0
A27: 22 | J27: =COUNTIF(D27:I27,"✓") -> 0
A28: 23 | J28: =COUNTIF(D28:I28,"✓") -> 0
A29: รวมจำนวนนักเรียนที่เล่นแต่ละมุม | D29: =COUNTIF(D6:D28,"✓") -> 0 | E29: =COUNTIF(E6:E28,"✓") -> 0 | F29: =COUNTIF(F6:F28,"✓") -> 0 | G29: =COUNTIF(G6:G28,"✓") -> 0 | H29: =COUNTIF(H6:H28,"✓") -> 0 | I29: =COUNTIF(I6:I28,"✓") -> 0 | J29: =SUM(J6:J28) -> 0
A31: ลงชื่อ .................................................. ผู้บันทึก ( นางสาววรพรรณ เจนการกิจ )

Sheet สัปดาห์ที่ 2
A1: แบบบันทึกการเล่นตามมุมประสบการณ์ของเด็กปฐมวัยรายสัปดาห์
A2: โรงเรียนเทศบาลบ้านเพ ๑ สังกัดกองการศึกษา เทศบาลตำบลบ้านเพ ชั้น อ.๑/๓
A3: สัปดาห์ที่ 2 | D3: วันที่ .............. ถึง .............. เดือน .............. พ.ศ. ..............
D4: มุมเสริมประสบการณ์แหล่งเรียนรู้ นอกห้องเรียน | J4: สรุปมุม ที่เล่น | K4: หมายเหตุ
A5: ที่ | B5: ชื่อ | C5: นามสกุล | D5: คัดแยกขยะ (mRS) | E5: ขยะอินทรีย์ | F5: แปลงปลูกผัก | G5: ห้องแหล่ง เรียนรู้ | H5: ห้อง คอมพิวเตอร์ | I5: เครื่องหมาย จราจร | J5: จำนวน มุม
A6: 1 | B6: เด็กชายชวคริต | J6: =COUNTIF(D6:I6,"✓") -> 0
A7: 2 | B7: เด็กชายตะวัน | C7: เจริญผล | J7: =COUNTIF(D7:I7,"✓") -> 0
A8: 3 | B8: เด็กชายภิมรภัทร | C8: คำนึงคิด | J8: =COUNTIF(D8:I8,"✓") -> 0
A9: 4 | B9: เด็กชายธิรพงศ์ | C9: อู่อ่อน | J9: =COUNTIF(D9:I9,"✓") -> 0
A10: 5 | B10: เด็กชายสรวิชญ์ | C10: เตชสงค์ | J10: =COUNTIF(D10:I10,"✓") -> 0
A11: 6 | B11: เด็กหญิงธัญญามาศ | C11: วิมลศรี | J11: =COUNTIF(D11:I11,"✓") -> 0
A12: 7 | B12: เด็กชายวสิน | C12: เม็ด | J12: =COUNTIF(D12:I12,"✓") -> 0
A13: 8 | B13: เด็กหญิงลีนา | C13: ออง | J13: =COUNTIF(D13:I13,"✓") -> 0
A14: 9 | B14: เด็กชายพชร | C14: ธรรมหลวง | J14: =COUNTIF(D14:I14,"✓") -> 0
A15: 10 | B15: เด็กชายศิวกรณ์ | C15: ถึงวงศ์ | J15: =COUNTIF(D15:I15,"✓") -> 0
A16: 11 | B16: เด็กหญิงนิตยาภรณ์ | C16: กาสิงห์ | J16: =COUNTIF(D16:I16,"✓") -> 0
A17: 12 | B17: เด็กชายภาณุวิชญ์ | C17: โยชนะ | J17: =COUNTIF(D17:I17,"✓") -> 0
A18: 13 | B18: เด็กหญิงธรรณชนก | C18: ขอบอรัญ | J18: =COUNTIF(D18:I18,"✓") -> 0
... A23: 18 | B23: เด็กหญิงพิชญาพร | C23: อุดร | J23: =COUNTIF(D23:I23,"✓") -> 0
A24: 19 | J24: =COUNTIF(D24:I24,"✓") -> 0
A25: 20 | J25: =COUNTIF(D25:I25,"✓") -> 0
A26: 21 | J26: =COUNTIF(D26:I26,"✓") -> 0
A27: 22 | J27: =COUNTIF(D27:I27,"✓") -> 0
A28: 23 | J28: =COUNTIF(D28:I28,"✓") -> 0
A29: รวมจำนวนนักเรียนที่เล่นแต่ละมุม | D29: =COUNTIF(D6:D28,"✓") -> 0 | E29: =COUNTIF(E6:E28,"✓") -> 0 | F29: =COUNTIF(F6:F28,"✓") -> 0 | G29: =COUNTIF(G6:G28,"✓") -> 0 | H29: =COUNTIF(H6:H28,"✓") -> 0 | I29: =COUNTIF(I6:I28,"✓") -> 0 | J29: =SUM(J6:J28) -> 0
A31: ลงชื่อ .................................................. ผู้บันทึก ( นางสาววรพรรณ เจนการกิจ )

Sheet สัปดาห์ที่ 3
A1: แบบบันทึกการเล่นตามมุมประสบการณ์ของเด็กปฐมวัยรายสัปดาห์
A2: โรงเรียนเทศบาลบ้านเพ ๑ สังกัดกองการศึกษา เทศบาลตำบลบ้านเพ ชั้น อ.๑/๓
A3: สัปดาห์ที่ 3 | D3: วันที่ .............. ถึง .............. เดือน .............. พ.ศ. ..............
D4: มุมเสริมประสบการณ์แหล่งเรียนรู้ นอกห้องเรียน | J4: สรุปมุม ที่เล่น | K4: หมายเหตุ
A5: ที่ | B5: ชื่อ | C5: นามสกุล | D5: คัดแยกขยะ (mRS) | E5: ขยะอินทรีย์ | F5: แปลงปลูกผัก | G5: ห้องแหล่ง เรียนรู้ | H5: ห้อง คอมพิวเตอร์ | I5: เครื่องหมาย จราจร | J5: จำนวน มุม
A6: 1 | B6: เด็กชายชวคริต | J6: =COUNTIF(D6:I6,"✓") -> 0
A7: 2 | B7: เด็กชายตะวัน | C7: เจริญผล | J7: =COUNTIF(D7:I7,"✓") -> 0
A8: 3 | B8: เด็กชายภิมรภัทร | C8: คำนึงคิด | J8: =COUNTIF(D8:I8,"✓") -> 0
A9: 4 | B9: เด็กชายธิรพงศ์ | C9: อู่อ่อน | J9: =COUNTIF(D9:I9,"✓") -> 0
A10: 5 | B10: เด็กชายสรวิชญ์ | C10: เตชสงค์ | J10: =COUNTIF(D10:I10,"✓") -> 0
A11: 6 | B11: เด็กหญิงธัญญามาศ | C11: วิมลศรี | J11: =COUNTIF(D11:I11,"✓") -> 0
A12: 7 | B12: เด็กชายวสิน | C12: เม็ด | J12: =COUNTIF(D12:I12,"✓") -> 0
A13: 8 | B13: เด็กหญิงลีนา | C13: ออง | J13: =COUNTIF(D13:I13,"✓") -> 0
A14: 9 | B14: เด็กชายพชร | C14: ธรรมหลวง | J14: =COUNTIF(D14:I14,"✓") -> 0
A15: 10 | B15: เด็กชายศิวกรณ์ | C15: ถึงวงศ์ | J15: =COUNTIF(D15:I15,"✓") -> 0
A16: 11 | B16: เด็กหญิงนิตยาภรณ์ | C16: กาสิงห์ | J16: =COUNTIF(D16:I16,"✓") -> 0
A17: 12 | B17: เด็กชายภาณุวิชญ์ | C17: โยชนะ | J17: =COUNTIF(D17:I17,"✓") -> 0
A18: 13 | B18: เด็กหญิงธรรณชนก | C18: ขอบอรัญ | J18: =COUNTIF(D18:I18,"✓") -> 0
... A23: 18 | B23: เด็กหญิงพิชญาพร | C23: อุดร | J23: =COUNTIF(D23:I23,"✓") -> 0
A24: 19 | J24: =COUNTIF(D24:I24,"✓") -> 0
A25: 20 | J25: =COUNTIF(D25:I25,"✓") -> 0
A26: 21 | J26: =COUNTIF(D26:I26,"✓") -> 0
A27: 22 | J27: =COUNTIF(D27:I27,"✓") -> 0
A28: 23 | J28: =COUNTIF(D28:I28,"✓") -> 0
A29: รวมจำนวนนักเรียนที่เล่นแต่ละมุม | D29: =COUNTIF(D6:D28,"✓") -> 0 | E29: =COUNTIF(E6:E28,"✓") -> 0 | F29: =COUNTIF(F6:F28,"✓") -> 0 | G29: =COUNTIF(G6:G28,"✓") -> 0 | H29: =COUNTIF(H6:H28,"✓") -> 0 | I29: =COUNTIF(I6:I28,"✓") -> 0 | J29: =SUM(J6:J28) -> 0
A31: ลงชื่อ .................................................. ผู้บันทึก ( นางสาววรพรรณ เจนการกิจ )

Sheet สัปดาห์ที่ 4
A1: แบบบันทึกการเล่นตามมุมประสบการณ์ของเด็กปฐมวัยรายสัปดาห์
A2: โรงเรียนเทศบาลบ้านเพ ๑ สังกัดกองการศึกษา เทศบาลตำบลบ้านเพ ชั้น อ.๑/๓
A3: สัปดาห์ที่ 4 | D3: วันที่ .............. ถึง .............. เดือน .............. พ.ศ. ..............
D4: มุมเสริมประสบการณ์แหล่งเรียนรู้ นอกห้องเรียน | J4: สรุปมุม ที่เล่น | K4: หมายเหตุ
A5: ที่ | B5: ชื่อ | C5: นามสกุล | D5: คัดแยกขยะ (mRS) | E5: ขยะอินทรีย์ | F5: แปลงปลูกผัก | G5: ห้องแหล่ง เรียนรู้ | H5: ห้อง คอมพิวเตอร์ | I5: เครื่องหมาย จราจร | J5: จำนวน มุม
A6: 1 | B6: เด็กชายชวคริต | J6: =COUNTIF(D6:I6,"✓") -> 0
A7: 2 | B7: เด็กชายตะวัน | C7: เจริญผล | J7: =COUNTIF(D7:I7,"✓") -> 0
A8: 3 | B8: เด็กชายภิมรภัทร | C8: คำนึงคิด | J8: =COUNTIF(D8:I8,"✓") -> 0
A9: 4 | B9: เด็กชายธิรพงศ์ | C9: อู่อ่อน | J9: =COUNTIF(D9:I9,"✓") -> 0
A10: 5 | B10: เด็กชายสรวิชญ์ | C10: เตชสงค์ | J10: =COUNTIF(D10:I10,"✓") -> 0
A11: 6 | B11: เด็กหญิงธัญญามาศ | C11: วิมลศรี | J11: =COUNTIF(D11:I11,"✓") -> 0
A12: 7 | B12: เด็กชายวสิน | C12: เม็ด | J12: =COUNTIF(D12:I12,"✓") -> 0
A13: 8 | B13: เด็กหญิงลีนา | C13: ออง | J13: =COUNTIF(D13:I13,"✓") -> 0
A14: 9 | B14: เด็กชายพชร | C14: ธรรมหลวง | J14: =COUNTIF(D14:I14,"✓") -> 0
A15: 10 | B15: เด็กชายศิวกรณ์ | C15: ถึงวงศ์ | J15: =COUNTIF(D15:I15,"✓") -> 0
A16: 11 | B16: เด็กหญิงนิตยาภรณ์ | C16: กาสิงห์ | J16: =COUNTIF(D16:I16,"✓") -> 0
A17: 12 | B17: เด็กชายภาณุวิชญ์ | C17: โยชนะ | J17: =COUNTIF(D17:I17,"✓") -> 0
A18: 13 | B18: เด็กหญิงธรรณชนก | C18: ขอบอรัญ | J18: =COUNTIF(D18:I18,"✓") -> 0
... A23: 18 | B23: เด็กหญิงพิชญาพร | C23: อุดร | J23: =COUNTIF(D23:I23,"✓") -> 0
A24: 19 | J24: =COUNTIF(D24:I24,"✓") -> 0
A25: 20 | J25: =COUNTIF(D25:I25,"✓") -> 0
A26: 21 | J26: =COUNTIF(D26:I26,"✓") -> 0
A27: 22 | J27: =COUNTIF(D27:I27,"✓") -> 0
A28: 23 | J28: =COUNTIF(D28:I28,"✓") -> 0
A29: รวมจำนวนนักเรียนที่เล่นแต่ละมุม | D29: =COUNTIF(D6:D28,"✓") -> 0 | E29: =COUNTIF(E6:E28,"✓") -> 0 | F29: =COUNTIF(F6:F28,"✓") -> 0 | G29: =COUNTIF(G6:G28,"✓") -> 0 | H29: =COUNTIF(H6:H28,"✓") -> 0 | I29: =COUNTIF(I6:I28,"✓") -> 0 | J29: =SUM(J6:J28) -> 0
A31: ลงชื่อ .................................................. ผู้บันทึก ( นางสาววรพรรณ เจนการกิจ )

Sheet สัปดาห์ที่ 5
A1: แบบบันทึกการเล่นตามมุมประสบการณ์ของเด็กปฐมวัยรายสัปดาห์
A2: โรงเรียนเทศบาลบ้านเพ ๑ สังกัดกองการศึกษา เทศบาลตำบลบ้านเพ ชั้น อ.๑/๓
A3: สัปดาห์ที่ 5 | D3: วันที่ .............. ถึง .............. เดือน .............. พ.ศ. ..............
D4: มุมเสริมประสบการณ์แหล่งเรียนรู้ นอกห้องเรียน | J4: สรุปมุม ที่เล่น | K4: หมายเหตุ
A5: ที่ | B5: ชื่อ | C5: นามสกุล | D5: คัดแยกขยะ (mRS) | E5: ขยะอินทรีย์ | F5: แปลงปลูกผัก | G5: ห้องแหล่ง เรียนรู้ | H5: ห้อง คอมพิวเตอร์ | I5: เครื่องหมาย จราจร | J5: จำนวน มุม
A6: 1 | B6: เด็กชายชวคริต | J6: =COUNTIF(D6:I6,"✓") -> 0
A7: 2 | B7: เด็กชายตะวัน | C7: เจริญผล | J7: =COUNTIF(D7:I7,"✓") -> 0
A8: 3 | B8: เด็กชายภิมรภัทร | C8: คำนึงคิด | J8: =COUNTIF(D8:I8,"✓") -> 0
A9: 4 | B9: เด็กชายธิรพงศ์ | C9: อู่อ่อน | J9: =COUNTIF(D9:I9,"✓") -> 0
A10: 5 | B10: เด็กชายสรวิชญ์ | C10: เตชสงค์ | J10: =COUNTIF(D10:I10,"✓") -> 0
A11: 6 | B11: เด็กหญิงธัญญามาศ | C11: วิมลศรี | J11: =COUNTIF(D11:I11,"✓") -> 0
A12: 7 | B12: เด็กชายวสิน | C12: เม็ด | J12: =COUNTIF(D12:I12,"✓") -> 0
A13: 8 | B13: เด็กหญิงลีนา | C13: ออง | J13: =COUNTIF(D13:I13,"✓") -> 0
A14: 9 | B14: เด็กชายพชร | C14: ธรรมหลวง | J14: =COUNTIF(D14:I14,"✓") -> 0
A15: 10 | B15: เด็กชายศิวกรณ์ | C15: ถึงวงศ์ | J15: =COUNTIF(D15:I15,"✓") -> 0
A16: 11 | B16: เด็กหญิงนิตยาภรณ์ | C16: กาสิงห์ | J16: =COUNTIF(D16:I16,"✓") -> 0
A17: 12 | B17: เด็กชายภาณุวิชญ์ | C17: โยชนะ | J17: =COUNTIF(D17:I17,"✓") -> 0
A18: 13 | B18: เด็กหญิงธรรณชนก | C18: ขอบอรัญ | J18: =COUNTIF(D18:I18,"✓") -> 0
... A23: 18 | B23: เด็กหญิงพิชญาพร | C23: อุดร | J23: =COUNTIF(D23:I23,"✓") -> 0
A24: 19 | J24: =COUNTIF(D24:I24,"✓") -> 0
A25: 20 | J25: =COUNTIF(D25:I25,"✓") -> 0
A26: 21 | J26: =COUNTIF(D26:I26,"✓") -> 0
A27: 22 | J27: =COUNTIF(D27:I27,"✓") -> 0
A28: 23 | J28: =COUNTIF(D28:I28,"✓") -> 0
A29: รวมจำนวนนักเรียนที่เล่นแต่ละมุม | D29: =COUNTIF(D6:D28,"✓") -> 0 | E29: =COUNTIF(E6:E28,"✓") -> 0 | F29: =COUNTIF(F6:F28,"✓") -> 0 | G29: =COUNTIF(G6:G28,"✓") -> 0 | H29: =COUNTIF(H6:H28,"✓") -> 0 | I29: =COUNTIF(I6:I28,"✓") -> 0 | J29: =SUM(J6:J28) -> 0
A31: ลงชื่อ .................................................. ผู้บันทึก ( นางสาววรพรรณ เจนการกิจ )

Sheet สัปดาห์ที่ 6
A1: แบบบันทึกการเล่นตามมุมประสบการณ์ของเด็กปฐมวัยรายสัปดาห์
A2: โรงเรียนเทศบาลบ้านเพ ๑ สังกัดกองการศึกษา เทศบาลตำบลบ้านเพ ชั้น อ.๑/๓
A3: สัปดาห์ที่ 6 | D3: วันที่ .............. ถึง .............. เดือน .............. พ.ศ. ..............
D4: มุมเสริมประสบการณ์แหล่งเรียนรู้ นอกห้องเรียน | J4: สรุปมุม ที่เล่น | K4: หมายเหตุ
A5: ที่ | B5: ชื่อ | C5: นามสกุล | D5: คัดแยกขยะ (mRS) | E5: ขยะอินทรีย์ | F5: แปลงปลูกผัก | G5: ห้องแหล่ง เรียนรู้ | H5: ห้อง คอมพิวเตอร์ | I5: เครื่องหมาย จราจร | J5: จำนวน มุม
A6: 1 | B6: เด็กชายชวคริต | J6: =COUNTIF(D6:I6,"✓") -> 0
A7: 2 | B7: เด็กชายตะวัน | C7: เจริญผล | J7: =COUNTIF(D7:I7,"✓") -> 0
A8: 3 | B8: เด็กชายภิมรภัทร | C8: คำนึงคิด | J8: =COUNTIF(D8:I8,"✓") -> 0
A9: 4 | B9: เด็กชายธิรพงศ์ | C9: อู่อ่อน | J9: =COUNTIF(D9:I9,"✓") -> 0
A10: 5 | B10: เด็กชายสรวิชญ์ | C10: เตชสงค์ | J10: =COUNTIF(D10:I10,"✓") -> 0
A11: 6 | B11: เด็กหญิงธัญญามาศ | C11: วิมลศรี | J11: =COUNTIF(D11:I11,"✓") -> 0
A12: 7 | B12: เด็กชายวสิน | C12: เม็ด | J12: =COUNTIF(D12:I12,"✓") -> 0
A13: 8 | B13: เด็กหญิงลีนา | C13: ออง | J13: =COUNTIF(D13:I13,"✓") -> 0
A14: 9 | B14: เด็กชายพชร | C14: ธรรมหลวง | J14: =COUNTIF(D14:I14,"✓") -> 0
A15: 10 | B15: เด็กชายศิวกรณ์ | C15: ถึงวงศ์ | J15: =COUNTIF(D15:I15,"✓") -> 0
A16: 11 | B16: เด็กหญิงนิตยาภรณ์ | C16: กาสิงห์ | J16: =COUNTIF(D16:I16,"✓") -> 0
A17: 12 | B17: เด็กชายภาณุวิชญ์ | C17: โยชนะ | J17: =COUNTIF(D17:I17,"✓") -> 0
A18: 13 | B18: เด็กหญิงธรรณชนก | C18: ขอบอรัญ | J18: =COUNTIF(D18:I18,"✓") -> 0
... A23: 18 | B23: เด็กหญิงพิชญาพร | C23: อุดร | J23: =COUNTIF(D23:I23,"✓") -> 0
A24: 19 | J24: =COUNTIF(D24:I24,"✓") -> 0
A25: 20 | J25: =COUNTIF(D25:I25,"✓") -> 0
A26: 21 | J26: =COUNTIF(D26:I26,"✓") -> 0
A27: 22 | J27: =COUNTIF(D27:I27,"✓") -> 0
A28: 23 | J28: =COUNTIF(D28:I28,"✓") -> 0
A29: รวมจำนวนนักเรียนที่เล่นแต่ละมุม | D29: =COUNTIF(D6:D28,"✓") -> 0 | E29: =COUNTIF(E6:E28,"✓") -> 0 | F29: =COUNTIF(F6:F28,"✓") -> 0 | G29: =COUNTIF(G6:G28,"✓") -> 0 | H29: =COUNTIF(H6:H28,"✓") -> 0 | I29: =COUNTIF(I6:I28,"✓") -> 0 | J29: =SUM(J6:J28) -> 0
A31: ลงชื่อ .................................................. ผู้บันทึก ( นางสาววรพรรณ เจนการกิจ )

Sheet สัปดาห์ที่ 7
A1: แบบบันทึกการเล่นตามมุมประสบการณ์ของเด็กปฐมวัยรายสัปดาห์
A2: โรงเรียนเทศบาลบ้านเพ ๑ สังกัดกองการศึกษา เทศบาลตำบลบ้านเพ ชั้น อ.๑/๓
A3: สัปดาห์ที่ 7 | D3: วันที่ .............. ถึง .............. เดือน .............. พ.ศ. ..............
D4: มุมเสริมประสบการณ์แหล่งเรียนรู้ นอกห้องเรียน | J4: สรุปมุม ที่เล่น | K4: หมายเหตุ
A5: ที่ | B5: ชื่อ | C5: นามสกุล | D5: คัดแยกขยะ (mRS) | E5: ขยะอินทรีย์ | F5: แปลงปลูกผัก | G5: ห้องแหล่ง เรียนรู้ | H5: ห้อง คอมพิวเตอร์ | I5: เครื่องหมาย จราจร | J5: จำนวน มุม
A6: 1 | B6: เด็กชายชวคริต | J6: =COUNTIF(D6:I6,"✓") -> 0
A7: 2 | B7: เด็กชายตะวัน | C7: เจริญผล | J7: =COUNTIF(D7:I7,"✓") -> 0
A8: 3 | B8: เด็กชายภิมรภัทร | C8: คำนึงคิด | J8: =COUNTIF(D8:I8,"✓") -> 0
A9: 4 | B9: เด็กชายธิรพงศ์ | C9: อู่อ่อน | J9: =COUNTIF(D9:I9,"✓") -> 0
A10: 5 | B10: เด็กชายสรวิชญ์ | C10: เตชสงค์ | J10: =COUNTIF(D10:I10,"✓") -> 0
A11: 6 | B11: เด็กหญิงธัญญามาศ | C11: วิมลศรี | J11: =COUNTIF(D11:I11,"✓") -> 0
A12: 7 | B12: เด็กชายวสิน | C12: เม็ด | J12: =COUNTIF(D12:I12,"✓") -> 0
A13: 8 | B13: เด็กหญิงลีนา | C13: ออง | J13: =COUNTIF(D13:I13,"✓") -> 0
A14: 9 | B14: เด็กชายพชร | C14: ธรรมหลวง | J14: =COUNTIF(D14:I14,"✓") -> 0
A15: 10 | B15: เด็กชายศิวกรณ์ | C15: ถึงวงศ์ | J15: =COUNTIF(D15:I15,"✓") -> 0
A16: 11 | B16: เด็กหญิงนิตยาภรณ์ | C16: กาสิงห์ | J16: =COUNTIF(D16:I16,"✓") -> 0
A17: 12 | B17: เด็กชายภาณุวิชญ์ | C17: โยชนะ | J17: =COUNTIF(D17:I17,"✓") -> 0
A18: 13 | B18: เด็กหญิงธรรณชนก | C18: ขอบอรัญ | J18: =COUNTIF(D18:I18,"✓") -> 0
... A23: 18 | B23: เด็กหญิงพิชญาพร | C23: อุดร | J23: =COUNTIF(D23:I23,"✓") -> 0
A24: 19 | J24: =COUNTIF(D24:I24,"✓") -> 0
A25: 20 | J25: =COUNTIF(D25:I25,"✓") -> 0
A26: 21 | J26: =COUNTIF(D26:I26,"✓") -> 0
A27: 22 | J27: =COUNTIF(D27:I27,"✓") -> 0
A28: 23 | J28: =COUNTIF(D28:I28,"✓") -> 0
A29: รวมจำนวนนักเรียนที่เล่นแต่ละมุม | D29: =COUNTIF(D6:D28,"✓") -> 0 | E29: =COUNTIF(E6:E28,"✓") -> 0 | F29: =COUNTIF(F6:F28,"✓") -> 0 | G29: =COUNTIF(G6:G28,"✓") -> 0 | H29: =COUNTIF(H6:H28,"✓") -> 0 | I29: =COUNTIF(I6:I28,"✓") -> 0 | J29: =SUM(J6:J28) -> 0
A31: ลงชื่อ .................................................. ผู้บันทึก ( นางสาววรพรรณ เจนการกิจ )

Sheet สัปดาห์ที่ 8
A1: แบบบันทึกการเล่นตามมุมประสบการณ์ของเด็กปฐมวัยรายสัปดาห์
A2: โรงเรียนเทศบาลบ้านเพ ๑ สังกัดกองการศึกษา เทศบาลตำบลบ้านเพ ชั้น อ.๑/๓
A3: สัปดาห์ที่ 8 | D3: วันที่ .............. ถึง .............. เดือน .............. พ.ศ. ..............
D4: มุมเสริมประสบการณ์แหล่งเรียนรู้ นอกห้องเรียน | J4: สรุปมุม ที่เล่น | K4: หมายเหตุ
A5: ที่ | B5: ชื่อ | C5: นามสกุล | D5: คัดแยกขยะ (mRS) | E5: ขยะอินทรีย์ | F5: แปลงปลูกผัก | G5: ห้องแหล่ง เรียนรู้ | H5: ห้อง คอมพิวเตอร์ | I5: เครื่องหมาย จราจร | J5: จำนวน มุม
A6: 1 | B6: เด็กชายชวคริต | J6: =COUNTIF(D6:I6,"✓") -> 0
A7: 2 | B7: เด็กชายตะวัน | C7: เจริญผล | J7: =COUNTIF(D7:I7,"✓") -> 0
A8: 3 | B8: เด็กชายภิมรภัทร | C8: คำนึงคิด | J8: =COUNTIF(D8:I8,"✓") -> 0
A9: 4 | B9: เด็กชายธิรพงศ์ | C9: อู่อ่อน | J9: =COUNTIF(D9:I9,"✓") -> 0
A10: 5 | B10: เด็กชายสรวิชญ์ | C10: เตชสงค์ | J10: =COUNTIF(D10:I10,"✓") -> 0
A11: 6 | B11: เด็กหญิงธัญญามาศ | C11: วิมลศรี | J11: =COUNTIF(D11:I11,"✓") -> 0
A12: 7 | B12: เด็กชายวสิน | C12: เม็ด | J12: =COUNTIF(D12:I12,"✓") -> 0
A13: 8 | B13: เด็กหญิงลีนา | C13: ออง | J13: =COUNTIF(D13:I13,"✓") -> 0
A14: 9 | B14: เด็กชายพชร | C14: ธรรมหลวง | J14: =COUNTIF(D14:I14,"✓") -> 0
A15: 10 | B15: เด็กชายศิวกรณ์ | C15: ถึงวงศ์ | J15: =COUNTIF(D15:I15,"✓") -> 0
A16: 11 | B16: เด็กหญิงนิตยาภรณ์ | C16: กาสิงห์ | J16: =COUNTIF(D16:I16,"✓") -> 0
A17: 12 | B17: เด็กชายภาณุวิชญ์ | C17: โยชนะ | J17: =COUNTIF(D17:I17,"✓") -> 0
A18: 13 | B18: เด็กหญิงธรรณชนก | C18: ขอบอรัญ | J18: =COUNTIF(D18:I18,"✓") -> 0
... A23: 18 | B23: เด็กหญิงพิชญาพร | C23: อุดร | J23: =COUNTIF(D23:I23,"✓") -> 0
A24: 19 | J24: =COUNTIF(D24:I24,"✓") -> 0
A25: 20 | J25: =COUNTIF(D25:I25,"✓") -> 0
A26: 21 | J26: =COUNTIF(D26:I26,"✓") -> 0
A27: 22 | J27: =COUNTIF(D27:I27,"✓") -> 0
A28: 23 | J28: =COUNTIF(D28:I28,"✓") -> 0
A29: รวมจำนวนนักเรียนที่เล่นแต่ละมุม | D29: =COUNTIF(D6:D28,"✓") -> 0 | E29: =COUNTIF(E6:E28,"✓") -> 0 | F29: =COUNTIF(F6:F28,"✓") -> 0 | G29: =COUNTIF(G6:G28,"✓") -> 0 | H29: =COUNTIF(H6:H28,"✓") -> 0 | I29: =COUNTIF(I6:I28,"✓") -> 0 | J29: =SUM(J6:J28) -> 0
A31: ลงชื่อ .................................................. ผู้บันทึก ( นางสาววรพรรณ เจนการกิจ )

Sheet สัปดาห์ที่ 9
A1: แบบบันทึกการเล่นตามมุมประสบการณ์ของเด็กปฐมวัยรายสัปดาห์
A2: โรงเรียนเทศบาลบ้านเพ ๑ สังกัดกองการศึกษา เทศบาลตำบลบ้านเพ ชั้น อ.๑/๓
A3: สัปดาห์ที่ 9 | D3: วันที่ .............. ถึง .............. เดือน .............. พ.ศ. ..............
D4: มุมเสริมประสบการณ์แหล่งเรียนรู้ นอกห้องเรียน | J4: สรุปมุม ที่เล่น | K4: หมายเหตุ
A5: ที่ | B5: ชื่อ | C5: นามสกุล | D5: คัดแยกขยะ (mRS) | E5: ขยะอินทรีย์ | F5: แปลงปลูกผัก | G5: ห้องแหล่ง เรียนรู้ | H5: ห้อง คอมพิวเตอร์ | I5: เครื่องหมาย จราจร | J5: จำนวน มุม
A6: 1 | B6: เด็กชายชวคริต | J6: =COUNTIF(D6:I6,"✓") -> 0
A7: 2 | B7: เด็กชายตะวัน | C7: เจริญผล | J7: =COUNTIF(D7:I7,"✓") -> 0
A8: 3 | B8: เด็กชายภิมรภัทร | C8: คำนึงคิด | J8: =COUNTIF(D8:I8,"✓") -> 0
A9: 4 | B9: เด็กชายธิรพงศ์ | C9: อู่อ่อน | J9: =COUNTIF(D9:I9,"✓") -> 0
A10: 5 | B10: เด็กชายสรวิชญ์ | C10: เตชสงค์ | J10: =COUNTIF(D10:I10,"✓") -> 0
A11: 6 | B11: เด็กหญิงธัญญามาศ | C11: วิมลศรี | J11: =COUNTIF(D11:I11,"✓") -> 0
A12: 7 | B12: เด็กชายวสิน | C12: เม็ด | J12: =COUNTIF(D12:I12,"✓") -> 0
A13: 8 | B13: เด็กหญิงลีนา | C13: ออง | J13: =COUNTIF(D13:I13,"✓") -> 0
A14: 9 | B14: เด็กชายพชร | C14: ธรรมหลวง | J14: =COUNTIF(D14:I14,"✓") -> 0
A15: 10 | B15: เด็กชายศิวกรณ์ | C15: ถึงวงศ์ | J15: =COUNTIF(D15:I15,"✓") -> 0
A16: 11 | B16: เด็กหญิงนิตยาภรณ์ | C16: กาสิงห์ | J16: =COUNTIF(D16:I16,"✓") -> 0
A17: 12 | B17: เด็กชายภาณุวิชญ์ | C17: โยชนะ | J17: =COUNTIF(D17:I17,"✓") -> 0
A18: 13 | B18: เด็กหญิงธรรณชนก | C18: ขอบอรัญ | J18: =COUNTIF(D18:I18,"✓") -> 0
... A23: 18 | B23: เด็กหญิงพิชญาพร | C23: อุดร | J23: =COUNTIF(D23:I23,"✓") -> 0
A24: 19 | J24: =COUNTIF(D24:I24,"✓") -> 0
A25: 20 | J25: =COUNTIF(D25:I25,"✓") -> 0
A26: 21 | J26: =COUNTIF(D26:I26,"✓") -> 0
A27: 22 | J27: =COUNTIF(D27:I27,"✓") -> 0
A28: 23 | J28: =COUNTIF(D28:I28,"✓") -> 0
A29: รวมจำนวนนักเรียนที่เล่นแต่ละมุม | D29: =COUNTIF(D6:D28,"✓") -> 0 | E29: =COUNTIF(E6:E28,"✓") -> 0 | F29: =COUNTIF(F6:F28,"✓") -> 0 | G29: =COUNTIF(G6:G28,"✓") -> 0 | H29: =COUNTIF(H6:H28,"✓") -> 0 | I29: =COUNTIF(I6:I28,"✓") -> 0 | J29: =SUM(J6:J28) -> 0
A31: ลงชื่อ .................................................. ผู้บันทึก ( นางสาววรพรรณ เจนการกิจ )

Sheet สัปดาห์ที่ 10
A1: แบบบันทึกการเล่นตามมุมประสบการณ์ของเด็กปฐมวัยรายสัปดาห์
A2: โรงเรียนเทศบาลบ้านเพ ๑ สังกัดกองการศึกษา เทศบาลตำบลบ้านเพ ชั้น อ.๑/๓
A3: สัปดาห์ที่ 10 | D3: วันที่ .............. ถึง .............. เดือน .............. พ.ศ. ..............
D4: มุมเสริมประสบการณ์แหล่งเรียนรู้ นอกห้องเรียน | J4: สรุปมุม ที่เล่น | K4: หมายเหตุ
A5: ที่ | B5: ชื่อ | C5: นามสกุล | D5: คัดแยกขยะ (mRS) | E5: ขยะอินทรีย์ | F5: แปลงปลูกผัก | G5: ห้องแหล่ง เรียนรู้ | H5: ห้อง คอมพิวเตอร์ | I5: เครื่องหมาย จราจร | J5: จำนวน มุม
A6: 1 | B6: เด็กชายชวคริต | J6: =COUNTIF(D6:I6,"✓") -> 0
A7: 2 | B7: เด็กชายตะวัน | C7: เจริญผล | J7: =COUNTIF(D7:I7,"✓") -> 0
A8: 3 | B8: เด็กชายภิมรภัทร | C8: คำนึงคิด | J8: =COUNTIF(D8:I8,"✓") -> 0
A9: 4 | B9: เด็กชายธิรพงศ์ | C9: อู่อ่อน | J9: =COUNTIF(D9:I9,"✓") -> 0
A10: 5 | B10: เด็กชายสรวิชญ์ | C10: เตชสงค์ | J10: =COUNTIF(D10:I10,"✓") -> 0
A11: 6 | B11: เด็กหญิงธัญญามาศ | C11: วิมลศรี | J11: =COUNTIF(D11:I11,"✓") -> 0
A12: 7 | B12: เด็กชายวสิน | C12: เม็ด | J12: =COUNTIF(D12:I12,"✓") -> 0
A13: 8 | B13: เด็กหญิงลีนา | C13: ออง | J13: =COUNTIF(D13:I13,"✓") -> 0
A14: 9 | B14: เด็กชายพชร | C14: ธรรมหลวง | J14: =COUNTIF(D14:I14,"✓") -> 0
A15: 10 | B15: เด็กชายศิวกรณ์ | C15: ถึงวงศ์ | J15: =COUNTIF(D15:I15,"✓") -> 0
A16: 11 | B16: เด็กหญิงนิตยาภรณ์ | C16: กาสิงห์ | J16: =COUNTIF(D16:I16,"✓") -> 0
A17: 12 | B17: เด็กชายภาณุวิชญ์ | C17: โยชนะ | J17: =COUNTIF(D17:I17,"✓") -> 0
A18: 13 | B18: เด็กหญิงธรรณชนก | C18: ขอบอรัญ | J18: =COUNTIF(D18:I18,"✓") -> 0
... A23: 18 | B23: เด็กหญิงพิชญาพร | C23: อุดร | J23: =COUNTIF(D23:I23,"✓") -> 0
A24: 19 | J24: =COUNTIF(D24:I24,"✓") -> 0
A25: 20 | J25: =COUNTIF(D25:I25,"✓") -> 0
A26: 21 | J26: =COUNTIF(D26:I26,"✓") -> 0
A27: 22 | J27: =COUNTIF(D27:I27,"✓") -> 0
A28: 23 | J28: =COUNTIF(D28:I28,"✓") -> 0
A29: รวมจำนวนนักเรียนที่เล่นแต่ละมุม | D29: =COUNTIF(D6:D28,"✓") -> 0 | E29: =COUNTIF(E6:E28,"✓") -> 0 | F29: =COUNTIF(F6:F28,"✓") -> 0 | G29: =COUNTIF(G6:G28,"✓") -> 0 | H29: =COUNTIF(H6:H28,"✓") -> 0 | I29: =COUNTIF(I6:I28,"✓") -> 0 | J29: =SUM(J6:J28) -> 0
A31: ลงชื่อ .................................................. ผู้บันทึก ( นางสาววรพรรณ เจนการกิจ )

Sheet สัปดาห์ที่ 11
A1: แบบบันทึกการเล่นตามมุมประสบการณ์ของเด็กปฐมวัยรายสัปดาห์
A2: โรงเรียนเทศบาลบ้านเพ ๑ สังกัดกองการศึกษา เทศบาลตำบลบ้านเพ ชั้น อ.๑/๓
A3: สัปดาห์ที่ 11 | D3: วันที่ .............. ถึง .............. เดือน .............. พ.ศ. ..............
D4: มุมเสริมประสบการณ์แหล่งเรียนรู้ นอกห้องเรียน | J4: สรุปมุม ที่เล่น | K4: หมายเหตุ
A5: ที่ | B5: ชื่อ | C5: นามสกุล | D5: คัดแยกขยะ (mRS) | E5: ขยะอินทรีย์ | F5: แปลงปลูกผัก | G5: ห้องแหล่ง เรียนรู้ | H5: ห้อง คอมพิวเตอร์ | I5: เครื่องหมาย จราจร | J5: จำนวน มุม
A6: 1 | B6: เด็กชายชวคริต | J6: =COUNTIF(D6:I6,"✓") -> 0
A7: 2 | B7: เด็กชายตะวัน | C7: เจริญผล | J7: =COUNTIF(D7:I7,"✓") -> 0
A8: 3 | B8: เด็กชายภิมรภัทร | C8: คำนึงคิด | J8: =COUNTIF(D8:I8,"✓") -> 0
A9: 4 | B9: เด็กชายธิรพงศ์ | C9: อู่อ่อน | J9: =COUNTIF(D9:I9,"✓") -> 0
A10: 5 | B10: เด็กชายสรวิชญ์ | C10: เตชสงค์ | J10: =COUNTIF(D10:I10,"✓") -> 0
A11: 6 | B11: เด็กหญิงธัญญามาศ | C11: วิมลศรี | J11: =COUNTIF(D11:I11,"✓") -> 0
A12: 7 | B12: เด็กชายวสิน | C12: เม็ด | J12: =COUNTIF(D12:I12,"✓") -> 0
A13: 8 | B13: เด็กหญิงลีนา | C13: ออง | J13: =COUNTIF(D13:I13,"✓") -> 0
A14: 9 | B14: เด็กชายพชร | C14: ธรรมหลวง | J14: =COUNTIF(D14:I14,"✓") -> 0
A15: 10 | B15: เด็กชายศิวกรณ์ | C15: ถึงวงศ์ | J15: =COUNTIF(D15:I15,"✓") -> 0
A16: 11 | B16: เด็กหญิงนิตยาภรณ์ | C16: กาสิงห์ | J16: =COUNTIF(D16:I16,"✓") -> 0
A17: 12 | B17: เด็กชายภาณุวิชญ์ | C17: โยชนะ | J17: =COUNTIF(D17:I17,"✓") -> 0
A18: 13 | B18: เด็กหญิงธรรณชนก | C18: ขอบอรัญ | J18: =COUNTIF(D18:I18,"✓") -> 0
... A23: 18 | B23: เด็กหญิงพิชญาพร | C23: อุดร | J23: =COUNTIF(D23:I23,"✓") -> 0
A24: 19 | J24: =COUNTIF(D24:I24,"✓") -> 0
A25: 20 | J25: =COUNTIF(D25:I25,"✓") -> 0
A26: 21 | J26: =COUNTIF(D26:I26,"✓") -> 0
A27: 22 | J27: =COUNTIF(D27:I27,"✓") -> 0
A28: 23 | J28: =COUNTIF(D28:I28,"✓") -> 0
A29: รวมจำนวนนักเรียนที่เล่นแต่ละมุม | D29: =COUNTIF(D6:D28,"✓") -> 0 | E29: =COUNTIF(E6:E28,"✓") -> 0 | F29: =COUNTIF(F6:F28,"✓") -> 0 | G29: =COUNTIF(G6:G28,"✓") -> 0 | H29: =COUNTIF(H6:H28,"✓") -> 0 | I29: =COUNTIF(I6:I28,"✓") -> 0 | J29: =SUM(J6:J28) -> 0
A31: ลงชื่อ .................................................. ผู้บันทึก ( นางสาววรพรรณ เจนการกิจ )

Sheet สัปดาห์ที่ 12
A1: แบบบันทึกการเล่นตามมุมประสบการณ์ของเด็กปฐมวัยรายสัปดาห์
A2: โรงเรียนเทศบาลบ้านเพ ๑ สังกัดกองการศึกษา เทศบาลตำบลบ้านเพ ชั้น อ.๑/๓
A3: สัปดาห์ที่ 12 | D3: วันที่ .............. ถึง .............. เดือน .............. พ.ศ. ..............
D4: มุมเสริมประสบการณ์แหล่งเรียนรู้ นอกห้องเรียน | J4: สรุปมุม ที่เล่น | K4: หมายเหตุ
A5: ที่ | B5: ชื่อ | C5: นามสกุล | D5: คัดแยกขยะ (mRS) | E5: ขยะอินทรีย์ | F5: แปลงปลูกผัก | G5: ห้องแหล่ง เรียนรู้ | H5: ห้อง คอมพิวเตอร์ | I5: เครื่องหมาย จราจร | J5: จำนวน มุม
A6: 1 | B6: เด็กชายชวคริต | J6: =COUNTIF(D6:I6,"✓") -> 0
A7: 2 | B7: เด็กชายตะวัน | C7: เจริญผล | J7: =COUNTIF(D7:I7,"✓") -> 0
A8: 3 | B8: เด็กชายภิมรภัทร | C8: คำนึงคิด | J8: =COUNTIF(D8:I8,"✓") -> 0
A9: 4 | B9: เด็กชายธิรพงศ์ | C9: อู่อ่อน | J9: =COUNTIF(D9:I9,"✓") -> 0
A10: 5 | B10: เด็กชายสรวิชญ์ | C10: เตชสงค์ | J10: =COUNTIF(D10:I10,"✓") -> 0
A11: 6 | B11: เด็กหญิงธัญญามาศ | C11: วิมลศรี | J11: =COUNTIF(D11:I11,"✓") -> 0
A12: 7 | B12: เด็กชายวสิน | C12: เม็ด | J12: =COUNTIF(D12:I12,"✓") -> 0
A13: 8 | B13: เด็กหญิงลีนา | C13: ออง | J13: =COUNTIF(D13:I13,"✓") -> 0
A14: 9 | B14: เด็กชายพชร | C14: ธรรมหลวง | J14: =COUNTIF(D14:I14,"✓") -> 0
A15: 10 | B15: เด็กชายศิวกรณ์ | C15: ถึงวงศ์ | J15: =COUNTIF(D15:I15,"✓") -> 0
A16: 11 | B16: เด็กหญิงนิตยาภรณ์ | C16: กาสิงห์ | J16: =COUNTIF(D16:I16,"✓") -> 0
A17: 12 | B17: เด็กชายภาณุวิชญ์ | C17: โยชนะ | J17: =COUNTIF(D17:I17,"✓") -> 0
A18: 13 | B18: เด็กหญิงธรรณชนก | C18: ขอบอรัญ | J18: =COUNTIF(D18:I18,"✓") -> 0
... A23: 18 | B23: เด็กหญิงพิชญาพร | C23: อุดร | J23: =COUNTIF(D23:I23,"✓") -> 0
A24: 19 | J24: =COUNTIF(D24:I24,"✓") -> 0
A25: 20 | J25: =COUNTIF(D25:I25,"✓") -> 0
A26: 21 | J26: =COUNTIF(D26:I26,"✓") -> 0
A27: 22 | J27: =COUNTIF(D27:I27,"✓") -> 0
A28: 23 | J28: =COUNTIF(D28:I28,"✓") -> 0
A29: รวมจำนวนนักเรียนที่เล่นแต่ละมุม | D29: =COUNTIF(D6:D28,"✓") -> 0 | E29: =COUNTIF(E6:E28,"✓") -> 0 | F29: =COUNTIF(F6:F28,"✓") -> 0 | G29: =COUNTIF(G6:G28,"✓") -> 0 | H29: =COUNTIF(H6:H28,"✓") -> 0 | I29: =COUNTIF(I6:I28,"✓") -> 0 | J29: =SUM(J6:J28) -> 0
A31: ลงชื่อ .................................................. ผู้บันทึก ( นางสาววรพรรณ เจนการกิจ )

Sheet สัปดาห์ที่ 13
A1: แบบบันทึกการเล่นตามมุมประสบการณ์ของเด็กปฐมวัยรายสัปดาห์
A2: โรงเรียนเทศบาลบ้านเพ ๑ สังกัดกองการศึกษา เทศบาลตำบลบ้านเพ ชั้น อ.๑/๓
A3: สัปดาห์ที่ 13 | D3: วันที่ .............. ถึง .............. เดือน .............. พ.ศ. ..............
D4: มุมเสริมประสบการณ์แหล่งเรียนรู้ นอกห้องเรียน | J4: สรุปมุม ที่เล่น | K4: หมายเหตุ
A5: ที่ | B5: ชื่อ | C5: นามสกุล | D5: คัดแยกขยะ (mRS) | E5: ขยะอินทรีย์ | F5: แปลงปลูกผัก | G5: ห้องแหล่ง เรียนรู้ | H5: ห้อง คอมพิวเตอร์ | I5: เครื่องหมาย จราจร | J5: จำนวน มุม
A6: 1 | B6: เด็กชายชวคริต | J6: =COUNTIF(D6:I6,"✓") -> 0
A7: 2 | B7: เด็กชายตะวัน | C7: เจริญผล | J7: =COUNTIF(D7:I7,"✓") -> 0
A8: 3 | B8: เด็กชายภิมรภัทร | C8: คำนึงคิด | J8: =COUNTIF(D8:I8,"✓") -> 0
A9: 4 | B9: เด็กชายธิรพงศ์ | C9: อู่อ่อน | J9: =COUNTIF(D9:I9,"✓") -> 0
A10: 5 | B10: เด็กชายสรวิชญ์ | C10: เตชสงค์ | J10: =COUNTIF(D10:I10,"✓") -> 0
A11: 6 | B11: เด็กหญิงธัญญามาศ | C11: วิมลศรี | J11: =COUNTIF(D11:I11,"✓") -> 0
A12: 7 | B12: เด็กชายวสิน | C12: เม็ด | J12: =COUNTIF(D12:I12,"✓") -> 0
A13: 8 | B13: เด็กหญิงลีนา | C13: ออง | J13: =COUNTIF(D13:I13,"✓") -> 0
A14: 9 | B14: เด็กชายพชร | C14: ธรรมหลวง | J14: =COUNTIF(D14:I14,"✓") -> 0
A15: 10 | B15: เด็กชายศิวกรณ์ | C15: ถึงวงศ์ | J15: =COUNTIF(D15:I15,"✓") -> 0
A16: 11 | B16: เด็กหญิงนิตยาภรณ์ | C16: กาสิงห์ | J16: =COUNTIF(D16:I16,"✓") -> 0
A17: 12 | B17: เด็กชายภาณุวิชญ์ | C17: โยชนะ | J17: =COUNTIF(D17:I17,"✓") -> 0
A18: 13 | B18: เด็กหญิงธรรณชนก | C18: ขอบอรัญ | J18: =COUNTIF(D18:I18,"✓") -> 0
... A23: 18 | B23: เด็กหญิงพิชญาพร | C23: อุดร | J23: =COUNTIF(D23:I23,"✓") -> 0
A24: 19 | J24: =COUNTIF(D24:I24,"✓") -> 0
A25: 20 | J25: =COUNTIF(D25:I25,"✓") -> 0
A26: 21 | J26: =COUNTIF(D26:I26,"✓") -> 0
A27: 22 | J27: =COUNTIF(D27:I27,"✓") -> 0
A28: 23 | J28: =COUNTIF(D28:I28,"✓") -> 0
A29: รวมจำนวนนักเรียนที่เล่นแต่ละมุม | D29: =COUNTIF(D6:D28,"✓") -> 0 | E29: =COUNTIF(E6:E28,"✓") -> 0 | F29: =COUNTIF(F6:F28,"✓") -> 0 | G29: =COUNTIF(G6:G28,"✓") -> 0 | H29: =COUNTIF(H6:H28,"✓") -> 0 | I29: =COUNTIF(I6:I28,"✓") -> 0 | J29: =SUM(J6:J28) -> 0
A31: ลงชื่อ .................................................. ผู้บันทึก ( นางสาววรพรรณ เจนการกิจ )

Sheet สัปดาห์ที่ 14
A1: แบบบันทึกการเล่นตามมุมประสบการณ์ของเด็กปฐมวัยรายสัปดาห์
A2: โรงเรียนเทศบาลบ้านเพ ๑ สังกัดกองการศึกษา เทศบาลตำบลบ้านเพ ชั้น อ.๑/๓
A3: สัปดาห์ที่ 14 | D3: วันที่ .............. ถึง .............. เดือน .............. พ.ศ. ..............
D4: มุมเสริมประสบการณ์แหล่งเรียนรู้ นอกห้องเรียน | J4: สรุปมุม ที่เล่น | K4: หมายเหตุ
A5: ที่ | B5: ชื่อ | C5: นามสกุล | D5: คัดแยกขยะ (mRS) | E5: ขยะอินทรีย์ | F5: แปลงปลูกผัก | G5: ห้องแหล่ง เรียนรู้ | H5: ห้อง คอมพิวเตอร์ | I5: เครื่องหมาย จราจร | J5: จำนวน มุม
A6: 1 | B6: เด็กชายชวคริต | J6: =COUNTIF(D6:I6,"✓") -> 0
A7: 2 | B7: เด็กชายตะวัน | C7: เจริญผล | J7: =COUNTIF(D7:I7,"✓") -> 0
A8: 3 | B8: เด็กชายภิมรภัทร | C8: คำนึงคิด | J8: =COUNTIF(D8:I8,"✓") -> 0
A9: 4 | B9: เด็กชายธิรพงศ์ | C9: อู่อ่อน | J9: =COUNTIF(D9:I9,"✓") -> 0
A10: 5 | B10: เด็กชายสรวิชญ์ | C10: เตชสงค์ | J10: =COUNTIF(D10:I10,"✓") -> 0
A11: 6 | B11: เด็กหญิงธัญญามาศ | C11: วิมลศรี | J11: =COUNTIF(D11:I11,"✓") -> 0
A12: 7 | B12: เด็กชายวสิน | C12: เม็ด | J12: =COUNTIF(D12:I12,"✓") -> 0
A13: 8 | B13: เด็กหญิงลีนา | C13: ออง | J13: =COUNTIF(D13:I13,"✓") -> 0
A14: 9 | B14: เด็กชายพชร | C14: ธรรมหลวง | J14: =COUNTIF(D14:I14,"✓") -> 0
A15: 10 | B15: เด็กชายศิวกรณ์ | C15: ถึงวงศ์ | J15: =COUNTIF(D15:I15,"✓") -> 0
A16: 11 | B16: เด็กหญิงนิตยาภรณ์ | C16: กาสิงห์ | J16: =COUNTIF(D16:I16,"✓") -> 0
A17: 12 | B17: เด็กชายภาณุวิชญ์ | C17: โยชนะ | J17: =COUNTIF(D17:I17,"✓") -> 0
A18: 13 | B18: เด็กหญิงธรรณชนก | C18: ขอบอรัญ | J18: =COUNTIF(D18:I18,"✓") -> 0
... A23: 18 | B23: เด็กหญิงพิชญาพร | C23: อุดร | J23: =COUNTIF(D23:I23,"✓") -> 0
A24: 19 | J24: =COUNTIF(D24:I24,"✓") -> 0
A25: 20 | J25: =COUNTIF(D25:I25,"✓") -> 0
A26: 21 | J26: =COUNTIF(D26:I26,"✓") -> 0
A27: 22 | J27: =COUNTIF(D27:I27,"✓") -> 0
A28: 23 | J28: =COUNTIF(D28:I28,"✓") -> 0
A29: รวมจำนวนนักเรียนที่เล่นแต่ละมุม | D29: =COUNTIF(D6:D28,"✓") -> 0 | E29: =COUNTIF(E6:E28,"✓") -> 0 | F29: =COUNTIF(F6:F28,"✓") -> 0 | G29: =COUNTIF(G6:G28,"✓") -> 0 | H29: =COUNTIF(H6:H28,"✓") -> 0 | I29: =COUNTIF(I6:I28,"✓") -> 0 | J29: =SUM(J6:J28) -> 0
A31: ลงชื่อ .................................................. ผู้บันทึก ( นางสาววรพรรณ เจนการกิจ )

Sheet สัปดาห์ที่ 15
A1: แบบบันทึกการเล่นตามมุมประสบการณ์ของเด็กปฐมวัยรายสัปดาห์
A2: โรงเรียนเทศบาลบ้านเพ ๑ สังกัดกองการศึกษา เทศบาลตำบลบ้านเพ ชั้น อ.๑/๓
A3: สัปดาห์ที่ 15 | D3: วันที่ .............. ถึง .............. เดือน .............. พ.ศ. ..............
D4: มุมเสริมประสบการณ์แหล่งเรียนรู้ นอกห้องเรียน | J4: สรุปมุม ที่เล่น | K4: หมายเหตุ
A5: ที่ | B5: ชื่อ | C5: นามสกุล | D5: คัดแยกขยะ (mRS) | E5: ขยะอินทรีย์ | F5: แปลงปลูกผัก | G5: ห้องแหล่ง เรียนรู้ | H5: ห้อง คอมพิวเตอร์ | I5: เครื่องหมาย จราจร | J5: จำนวน มุม
A6: 1 | B6: เด็กชายชวคริต | J6: =COUNTIF(D6:I6,"✓") -> 0
A7: 2 | B7: เด็กชายตะวัน | C7: เจริญผล | J7: =COUNTIF(D7:I7,"✓") -> 0
A8: 3 | B8: เด็กชายภิมรภัทร | C8: คำนึงคิด | J8: =COUNTIF(D8:I8,"✓") -> 0
A9: 4 | B9: เด็กชายธิรพงศ์ | C9: อู่อ่อน | J9: =COUNTIF(D9:I9,"✓") -> 0
A10: 5 | B10: เด็กชายสรวิชญ์ | C10: เตชสงค์ | J10: =COUNTIF(D10:I10,"✓") -> 0
A11: 6 | B11: เด็กหญิงธัญญามาศ | C11: วิมลศรี | J11: =COUNTIF(D11:I11,"✓") -> 0
A12: 7 | B12: เด็กชายวสิน | C12: เม็ด | J12: =COUNTIF(D12:I12,"✓") -> 0
A13: 8 | B13: เด็กหญิงลีนา | C13: ออง | J13: =COUNTIF(D13:I13,"✓") -> 0
A14: 9 | B14: เด็กชายพชร | C14: ธรรมหลวง | J14: =COUNTIF(D14:I14,"✓") -> 0
A15: 10 | B15: เด็กชายศิวกรณ์ | C15: ถึงวงศ์ | J15: =COUNTIF(D15:I15,"✓") -> 0
A16: 11 | B16: เด็กหญิงนิตยาภรณ์ | C16: กาสิงห์ | J16: =COUNTIF(D16:I16,"✓") -> 0
A17: 12 | B17: เด็กชายภาณุวิชญ์ | C17: โยชนะ | J17: =COUNTIF(D17:I17,"✓") -> 0
A18: 13 | B18: เด็กหญิงธรรณชนก | C18: ขอบอรัญ | J18: =COUNTIF(D18:I18,"✓") -> 0
... A23: 18 | B23: เด็กหญิงพิชญาพร | C23: อุดร | J23: =COUNTIF(D23:I23,"✓") -> 0
A24: 19 | J24: =COUNTIF(D24:I24,"✓") -> 0
A25: 20 | J25: =COUNTIF(D25:I25,"✓") -> 0
A26: 21 | J26: =COUNTIF(D26:I26,"✓") -> 0
A27: 22 | J27: =COUNTIF(D27:I27,"✓") -> 0
A28: 23 | J28: =COUNTIF(D28:I28,"✓") -> 0
A29: รวมจำนวนนักเรียนที่เล่นแต่ละมุม | D29: =COUNTIF(D6:D28,"✓") -> 0 | E29: =COUNTIF(E6:E28,"✓") -> 0 | F29: =COUNTIF(F6:F28,"✓") -> 0 | G29: =COUNTIF(G6:G28,"✓") -> 0 | H29: =COUNTIF(H6:H28,"✓") -> 0 | I29: =COUNTIF(I6:I28,"✓") -> 0 | J29: =SUM(J6:J28) -> 0
A31: ลงชื่อ .................................................. ผู้บันทึก ( นางสาววรพรรณ เจนการกิจ )

Sheet สัปดาห์ที่ 16
A1: แบบบันทึกการเล่นตามมุมประสบการณ์ของเด็กปฐมวัยรายสัปดาห์
A2: โรงเรียนเทศบาลบ้านเพ ๑ สังกัดกองการศึกษา เทศบาลตำบลบ้านเพ ชั้น อ.๑/๓
A3: สัปดาห์ที่ 16 | D3: วันที่ .............. ถึง .............. เดือน .............. พ.ศ. ..............
D4: มุมเสริมประสบการณ์แหล่งเรียนรู้ นอกห้องเรียน | J4: สรุปมุม ที่เล่น | K4: หมายเหตุ
A5: ที่ | B5: ชื่อ | C5: นามสกุล | D5: คัดแยกขยะ (mRS) | E5: ขยะอินทรีย์ | F5: แปลงปลูกผัก | G5: ห้องแหล่ง เรียนรู้ | H5: ห้อง คอมพิวเตอร์ | I5: เครื่องหมาย จราจร | J5: จำนวน มุม
A6: 1 | B6: เด็กชายชวคริต | J6: =COUNTIF(D6:I6,"✓") -> 0
A7: 2 | B7: เด็กชายตะวัน | C7: เจริญผล | J7: =COUNTIF(D7:I7,"✓") -> 0
A8: 3 | B8: เด็กชายภิมรภัทร | C8: คำนึงคิด | J8: =COUNTIF(D8:I8,"✓") -> 0
A9: 4 | B9: เด็กชายธิรพงศ์ | C9: อู่อ่อน | J9: =COUNTIF(D9:I9,"✓") -> 0
A10: 5 | B10: เด็กชายสรวิชญ์ | C10: เตชสงค์ | J10: =COUNTIF(D10:I10,"✓") -> 0
A11: 6 | B11: เด็กหญิงธัญญามาศ | C11: วิมลศรี | J11: =COUNTIF(D11:I11,"✓") -> 0
A12: 7 | B12: เด็กชายวสิน | C12: เม็ด | J12: =COUNTIF(D12:I12,"✓") -> 0
A13: 8 | B13: เด็กหญิงลีนา | C13: ออง | J13: =COUNTIF(D13:I13,"✓") -> 0
A14: 9 | B14: เด็กชายพชร | C14: ธรรมหลวง | J14: =COUNTIF(D14:I14,"✓") -> 0
A15: 10 | B15: เด็กชายศิวกรณ์ | C15: ถึงวงศ์ | J15: =COUNTIF(D15:I15,"✓") -> 0
A16: 11 | B16: เด็กหญิงนิตยาภรณ์ | C16: กาสิงห์ | J16: =COUNTIF(D16:I16,"✓") -> 0
A17: 12 | B17: เด็กชายภาณุวิชญ์ | C17: โยชนะ | J17: =COUNTIF(D17:I17,"✓") -> 0
A18: 13 | B18: เด็กหญิงธรรณชนก | C18: ขอบอรัญ | J18: =COUNTIF(D18:I18,"✓") -> 0
... A23: 18 | B23: เด็กหญิงพิชญาพร | C23: อุดร | J23: =COUNTIF(D23:I23,"✓") -> 0
A24: 19 | J24: =COUNTIF(D24:I24,"✓") -> 0
A25: 20 | J25: =COUNTIF(D25:I25,"✓") -> 0
A26: 21 | J26: =COUNTIF(D26:I26,"✓") -> 0
A27: 22 | J27: =COUNTIF(D27:I27,"✓") -> 0
A28: 23 | J28: =COUNTIF(D28:I28,"✓") -> 0
A29: รวมจำนวนนักเรียนที่เล่นแต่ละมุม | D29: =COUNTIF(D6:D28,"✓") -> 0 | E29: =COUNTIF(E6:E28,"✓") -> 0 | F29: =COUNTIF(F6:F28,"✓") -> 0 | G29: =COUNTIF(G6:G28,"✓") -> 0 | H29: =COUNTIF(H6:H28,"✓") -> 0 | I29: =COUNTIF(I6:I28,"✓") -> 0 | J29: =SUM(J6:J28) -> 0
A31: ลงชื่อ .................................................. ผู้บันทึก ( นางสาววรพรรณ เจนการกิจ )

Sheet สัปดาห์ที่ 17
A1: แบบบันทึกการเล่นตามมุมประสบการณ์ของเด็กปฐมวัยรายสัปดาห์
A2: โรงเรียนเทศบาลบ้านเพ ๑ สังกัดกองการศึกษา เทศบาลตำบลบ้านเพ ชั้น อ.๑/๓
A3: สัปดาห์ที่ 17 | D3: วันที่ .............. ถึง .............. เดือน .............. พ.ศ. ..............
D4: มุมเสริมประสบการณ์แหล่งเรียนรู้ นอกห้องเรียน | J4: สรุปมุม ที่เล่น | K4: หมายเหตุ
A5: ที่ | B5: ชื่อ | C5: นามสกุล | D5: คัดแยกขยะ (mRS) | E5: ขยะอินทรีย์ | F5: แปลงปลูกผัก | G5: ห้องแหล่ง เรียนรู้ | H5: ห้อง คอมพิวเตอร์ | I5: เครื่องหมาย จราจร | J5: จำนวน มุม
A6: 1 | B6: เด็กชายชวคริต | J6: =COUNTIF(D6:I6,"✓") -> 0
A7: 2 | B7: เด็กชายตะวัน | C7: เจริญผล | J7: =COUNTIF(D7:I7,"✓") -> 0
A8: 3 | B8: เด็กชายภิมรภัทร | C8: คำนึงคิด | J8: =COUNTIF(D8:I8,"✓") -> 0
A9: 4 | B9: เด็กชายธิรพงศ์ | C9: อู่อ่อน | J9: =COUNTIF(D9:I9,"✓") -> 0
A10: 5 | B10: เด็กชายสรวิชญ์ | C10: เตชสงค์ | J10: =COUNTIF(D10:I10,"✓") -> 0
A11: 6 | B11: เด็กหญิงธัญญามาศ | C11: วิมลศรี | J11: =COUNTIF(D11:I11,"✓") -> 0
A12: 7 | B12: เด็กชายวสิน | C12: เม็ด | J12: =COUNTIF(D12:I12,"✓") -> 0
A13: 8 | B13: เด็กหญิงลีนา | C13: ออง | J13: =COUNTIF(D13:I13,"✓") -> 0
A14: 9 | B14: เด็กชายพชร | C14: ธรรมหลวง | J14: =COUNTIF(D14:I14,"✓") -> 0
A15: 10 | B15: เด็กชายศิวกรณ์ | C15: ถึงวงศ์ | J15: =COUNTIF(D15:I15,"✓") -> 0
A16: 11 | B16: เด็กหญิงนิตยาภรณ์ | C16: กาสิงห์ | J16: =COUNTIF(D16:I16,"✓") -> 0
A17: 12 | B17: เด็กชายภาณุวิชญ์ | C17: โยชนะ | J17: =COUNTIF(D17:I17,"✓") -> 0
A18: 13 | B18: เด็กหญิงธรรณชนก | C18: ขอบอรัญ | J18: =COUNTIF(D18:I18,"✓") -> 0
... A23: 18 | B23: เด็กหญิงพิชญาพร | C23: อุดร | J23: =COUNTIF(D23:I23,"✓") -> 0
A24: 19 | J24: =COUNTIF(D24:I24,"✓") -> 0
A25: 20 | J25: =COUNTIF(D25:I25,"✓") -> 0
A26: 21 | J26: =COUNTIF(D26:I26,"✓") -> 0
A27: 22 | J27: =COUNTIF(D27:I27,"✓") -> 0
A28: 23 | J28: =COUNTIF(D28:I28,"✓") -> 0
A29: รวมจำนวนนักเรียนที่เล่นแต่ละมุม | D29: =COUNTIF(D6:D28,"✓") -> 0 | E29: =COUNTIF(E6:E28,"✓") -> 0 | F29: =COUNTIF(F6:F28,"✓") -> 0 | G29: =COUNTIF(G6:G28,"✓") -> 0 | H29: =COUNTIF(H6:H28,"✓") -> 0 | I29: =COUNTIF(I6:I28,"✓") -> 0 | J29: =SUM(J6:J28) -> 0
A31: ลงชื่อ .................................................. ผู้บันทึก ( นางสาววรพรรณ เจนการกิจ )

Sheet สัปดาห์ที่ 18
A1: แบบบันทึกการเล่นตามมุมประสบการณ์ของเด็กปฐมวัยรายสัปดาห์
A2: โรงเรียนเทศบาลบ้านเพ ๑ สังกัดกองการศึกษา เทศบาลตำบลบ้านเพ ชั้น อ.๑/๓
A3: สัปดาห์ที่ 18 | D3: วันที่ .............. ถึง .............. เดือน .............. พ.ศ. ..............
D4: มุมเสริมประสบการณ์แหล่งเรียนรู้ นอกห้องเรียน | J4: สรุปมุม ที่เล่น | K4: หมายเหตุ
A5: ที่ | B5: ชื่อ | C5: นามสกุล | D5: คัดแยกขยะ (mRS) | E5: ขยะอินทรีย์ | F5: แปลงปลูกผัก | G5: ห้องแหล่ง เรียนรู้ | H5: ห้อง คอมพิวเตอร์ | I5: เครื่องหมาย จราจร | J5: จำนวน มุม
A6: 1 | B6: เด็กชายชวคริต | J6: =COUNTIF(D6:I6,"✓") -> 0
A7: 2 | B7: เด็กชายตะวัน | C7: เจริญผล | J7: =COUNTIF(D7:I7,"✓") -> 0
A8: 3 | B8: เด็กชายภิมรภัทร | C8: คำนึงคิด | J8: =COUNTIF(D8:I8,"✓") -> 0
A9: 4 | B9: เด็กชายธิรพงศ์ | C9: อู่อ่อน | J9: =COUNTIF(D9:I9,"✓") -> 0
A10: 5 | B10: เด็กชายสรวิชญ์ | C10: เตชสงค์ | J10: =COUNTIF(D10:I10,"✓") -> 0
A11: 6 | B11: เด็กหญิงธัญญามาศ | C11: วิมลศรี | J11: =COUNTIF(D11:I11,"✓") -> 0
A12: 7 | B12: เด็กชายวสิน | C12: เม็ด | J12: =COUNTIF(D12:I12,"✓") -> 0
A13: 8 | B13: เด็กหญิงลีนา | C13: ออง | J13: =COUNTIF(D13:I13,"✓") -> 0
A14: 9 | B14: เด็กชายพชร | C14: ธรรมหลวง | J14: =COUNTIF(D14:I14,"✓") -> 0
A15: 10 | B15: เด็กชายศิวกรณ์ | C15: ถึงวงศ์ | J15: =COUNTIF(D15:I15,"✓") -> 0
A16: 11 | B16: เด็กหญิงนิตยาภรณ์ | C16: กาสิงห์ | J16: =COUNTIF(D16:I16,"✓") -> 0
A17: 12 | B17: เด็กชายภาณุวิชญ์ | C17: โยชนะ | J17: =COUNTIF(D17:I17,"✓") -> 0
A18: 13 | B18: เด็กหญิงธรรณชนก | C18: ขอบอรัญ | J18: =COUNTIF(D18:I18,"✓") -> 0
... A23: 18 | B23: เด็กหญิงพิชญาพร | C23: อุดร | J23: =COUNTIF(D23:I23,"✓") -> 0
A24: 19 | J24: =COUNTIF(D24:I24,"✓") -> 0
A25: 20 | J25: =COUNTIF(D25:I25,"✓") -> 0
A26: 21 | J26: =COUNTIF(D26:I26,"✓") -> 0
A27: 22 | J27: =COUNTIF(D27:I27,"✓") -> 0
A28: 23 | J28: =COUNTIF(D28:I28,"✓") -> 0
A29: รวมจำนวนนักเรียนที่เล่นแต่ละมุม | D29: =COUNTIF(D6:D28,"✓") -> 0 | E29: =COUNTIF(E6:E28,"✓") -> 0 | F29: =COUNTIF(F6:F28,"✓") -> 0 | G29: =COUNTIF(G6:G28,"✓") -> 0 | H29: =COUNTIF(H6:H28,"✓") -> 0 | I29: =COUNTIF(I6:I28,"✓") -> 0 | J29: =SUM(J6:J28) -> 0
A31: ลงชื่อ .................................................. ผู้บันทึก ( นางสาววรพรรณ เจนการกิจ )

Sheet สัปดาห์ที่ 19
A1: แบบบันทึกการเล่นตามมุมประสบการณ์ของเด็กปฐมวัยรายสัปดาห์
A2: โรงเรียนเทศบาลบ้านเพ ๑ สังกัดกองการศึกษา เทศบาลตำบลบ้านเพ ชั้น อ.๑/๓
A3: สัปดาห์ที่ 19 | D3: วันที่ .............. ถึง .............. เดือน .............. พ.ศ. ..............
D4: มุมเสริมประสบการณ์แหล่งเรียนรู้ นอกห้องเรียน | J4: สรุปมุม ที่เล่น | K4: หมายเหตุ
A5: ที่ | B5: ชื่อ | C5: นามสกุล | D5: คัดแยกขยะ (mRS) | E5: ขยะอินทรีย์ | F5: แปลงปลูกผัก | G5: ห้องแหล่ง เรียนรู้ | H5: ห้อง คอมพิวเตอร์ | I5: เครื่องหมาย จราจร | J5: จำนวน มุม
A6: 1 | B6: เด็กชายชวคริต | J6: =COUNTIF(D6:I6,"✓") -> 0
A7: 2 | B7: เด็กชายตะวัน | C7: เจริญผล | J7: =COUNTIF(D7:I7,"✓") -> 0
A8: 3 | B8: เด็กชายภิมรภัทร | C8: คำนึงคิด | J8: =COUNTIF(D8:I8,"✓") -> 0
A9: 4 | B9: เด็กชายธิรพงศ์ | C9: อู่อ่อน | J9: =COUNTIF(D9:I9,"✓") -> 0
A10: 5 | B10: เด็กชายสรวิชญ์ | C10: เตชสงค์ | J10: =COUNTIF(D10:I10,"✓") -> 0
A11: 6 | B11: เด็กหญิงธัญญามาศ | C11: วิมลศรี | J11: =COUNTIF(D11:I11,"✓") -> 0
A12: 7 | B12: เด็กชายวสิน | C12: เม็ด | J12: =COUNTIF(D12:I12,"✓") -> 0
A13: 8 | B13: เด็กหญิงลีนา | C13: ออง | J13: =COUNTIF(D13:I13,"✓") -> 0
A14: 9 | B14: เด็กชายพชร | C14: ธรรมหลวง | J14: =COUNTIF(D14:I14,"✓") -> 0
A15: 10 | B15: เด็กชายศิวกรณ์ | C15: ถึงวงศ์ | J15: =COUNTIF(D15:I15,"✓") -> 0
A16: 11 | B16: เด็กหญิงนิตยาภรณ์ | C16: กาสิงห์ | J16: =COUNTIF(D16:I16,"✓") -> 0
A17: 12 | B17: เด็กชายภาณุวิชญ์ | C17: โยชนะ | J17: =COUNTIF(D17:I17,"✓") -> 0
A18: 13 | B18: เด็กหญิงธรรณชนก | C18: ขอบอรัญ | J18: =COUNTIF(D18:I18,"✓") -> 0
... A23: 18 | B23: เด็กหญิงพิชญาพร | C23: อุดร | J23: =COUNTIF(D23:I23,"✓") -> 0
A24: 19 | J24: =COUNTIF(D24:I24,"✓") -> 0
A25: 20 | J25: =COUNTIF(D25:I25,"✓") -> 0
A26: 21 | J26: =COUNTIF(D26:I26,"✓") -> 0
A27: 22 | J27: =COUNTIF(D27:I27,"✓") -> 0
A28: 23 | J28: =COUNTIF(D28:I28,"✓") -> 0
A29: รวมจำนวนนักเรียนที่เล่นแต่ละมุม | D29: =COUNTIF(D6:D28,"✓") -> 0 | E29: =COUNTIF(E6:E28,"✓") -> 0 | F29: =COUNTIF(F6:F28,"✓") -> 0 | G29: =COUNTIF(G6:G28,"✓") -> 0 | H29: =COUNTIF(H6:H28,"✓") -> 0 | I29: =COUNTIF(I6:I28,"✓") -> 0 | J29: =SUM(J6:J28) -> 0
A31: ลงชื่อ .................................................. ผู้บันทึก ( นางสาววรพรรณ เจนการกิจ )

Sheet สัปดาห์ที่ 20
A1: แบบบันทึกการเล่นตามมุมประสบการณ์ของเด็กปฐมวัยรายสัปดาห์
A2: โรงเรียนเทศบาลบ้านเพ ๑ สังกัดกองการศึกษา เทศบาลตำบลบ้านเพ ชั้น อ.๑/๓
A3: สัปดาห์ที่ 20 | D3: วันที่ .............. ถึง .............. เดือน .............. พ.ศ. ..............
D4: มุมเสริมประสบการณ์แหล่งเรียนรู้ นอกห้องเรียน | J4: สรุปมุม ที่เล่น | K4: หมายเหตุ
A5: ที่ | B5: ชื่อ | C5: นามสกุล | D5: คัดแยกขยะ (mRS) | E5: ขยะอินทรีย์ | F5: แปลงปลูกผัก | G5: ห้องแหล่ง เรียนรู้ | H5: ห้อง คอมพิวเตอร์ | I5: เครื่องหมาย จราจร | J5: จำนวน มุม
A6: 1 | B6: เด็กชายชวคริต | J6: =COUNTIF(D6:I6,"✓") -> 0
A7: 2 | B7: เด็กชายตะวัน | C7: เจริญผล | J7: =COUNTIF(D7:I7,"✓") -> 0
A8: 3 | B8: เด็กชายภิมรภัทร | C8: คำนึงคิด | J8: =COUNTIF(D8:I8,"✓") -> 0
A9: 4 | B9: เด็กชายธิรพงศ์ | C9: อู่อ่อน | J9: =COUNTIF(D9:I9,"✓") -> 0
A10: 5 | B10: เด็กชายสรวิชญ์ | C10: เตชสงค์ | J10: =COUNTIF(D10:I10,"✓") -> 0
A11: 6 | B11: เด็กหญิงธัญญามาศ | C11: วิมลศรี | J11: =COUNTIF(D11:I11,"✓") -> 0
A12: 7 | B12: เด็กชายวสิน | C12: เม็ด | J12: =COUNTIF(D12:I12,"✓") -> 0
A13: 8 | B13: เด็กหญิงลีนา | C13: ออง | J13: =COUNTIF(D13:I13,"✓") -> 0
A14: 9 | B14: เด็กชายพชร | C14: ธรรมหลวง | J14: =COUNTIF(D14:I14,"✓") -> 0
A15: 10 | B15: เด็กชายศิวกรณ์ | C15: ถึงวงศ์ | J15: =COUNTIF(D15:I15,"✓") -> 0
A16: 11 | B16: เด็กหญิงนิตยาภรณ์ | C16: กาสิงห์ | J16: =COUNTIF(D16:I16,"✓") -> 0
A17: 12 | B17: เด็กชายภาณุวิชญ์ | C17: โยชนะ | J17: =COUNTIF(D17:I17,"✓") -> 0
A18: 13 | B18: เด็กหญิงธรรณชนก | C18: ขอบอรัญ | J18: =COUNTIF(D18:I18,"✓") -> 0
... A23: 18 | B23: เด็กหญิงพิชญาพร | C23: อุดร | J23: =COUNTIF(D23:I23,"✓") -> 0
A24: 19 | J24: =COUNTIF(D24:I24,"✓") -> 0
A25: 20 | J25: =COUNTIF(D25:I25,"✓") -> 0
A26: 21 | J26: =COUNTIF(D26:I26,"✓") -> 0
A27: 22 | J27: =COUNTIF(D27:I27,"✓") -> 0
A28: 23 | J28: =COUNTIF(D28:I28,"✓") -> 0
A29: รวมจำนวนนักเรียนที่เล่นแต่ละมุม | D29: =COUNTIF(D6:D28,"✓") -> 0 | E29: =COUNTIF(E6:E28,"✓") -> 0 | F29: =COUNTIF(F6:F28,"✓") -> 0 | G29: =COUNTIF(G6:G28,"✓") -> 0 | H29: =COUNTIF(H6:H28,"✓") -> 0 | I29: =COUNTIF(I6:I28,"✓") -> 0 | J29: =SUM(J6:J28) -> 0
A31: ลงชื่อ .................................................. ผู้บันทึก ( นางสาววรพรรณ เจนการกิจ )

Sheet สรุปรายภาคเรียน
A1: สรุปผลการเล่นตามมุมประสบการณ์ รายภาคเรียน ชั้น อ.๑/๓
A2: โรงเรียนเทศบาลบ้านเพ ๑ ปีการศึกษา ๒๕๖๘ ครูประจำชั้น: นางสาววรพรรณ เจนการกิจ
A3: ที่ | B3: ชื่อ | C3: นามสกุล | D3: รวม คัดแยกขยะ (mRS) | E3: รวม ขยะอินทรีย์ | F3: รวม แปลงปลูกผัก | G3: รวม ห้องแหล่ง เรียนรู้ | H3: รวม ห้อง คอมพิวเตอร์ | I3: รวม เครื่องหมาย จราจร | J3: รวมทั้งหมด
A4: 1 | B4: เด็กชายชวคริต | D4: =SUMPRODUCT(('สัปดาห์ที่ 1'!D6="✓")*1+('สัปดาห์ที่ 2'!D6="✓")*1+('สัปดาห์ที่ 3'!D6="✓")*1+('สัปดาห์ที่ 4'!D6="✓")*1+('สัปดาห์ที่ 5'!D6="✓")*1+('สัปดาห์ที่ 6'!D6="✓")*1+('สัปดาห์ที่ 7'!D6="✓")*1+('สัปดาห์ที่ 8'!D6="✓")*1+('สัปดาห์ที่ 9'!D6="✓")*1+('สัปดาห์ที่ 10'!D6="✓")*1+('สัปดาห์ที่ 11'!D6="✓")*1+('สัปดาห์ที่ 12'!D6="✓")*1+('สัปดาห์ที่ 13'!D6="✓")*1+('สัปดาห์ที่ 14'!D6="✓")*1+('สัปดาห์ที่ 15'!D6="✓")*1+('สัปดาห์ที่ 16'!D6="✓")*1+('สัปดาห์ที่ 17'!D6="✓")*1+('สัปดาห์ที่ 18'!D6="✓")*1+('สัปดาห์ที่ 19'!D6="✓")*1+('สัปดาห์ที่ 20'!D6="✓")*1) -> 0 | E4: =SUMPRODUCT(('สัปดาห์ที่ 1'!E6="✓")*1+('สัปดาห์ที่ 2'!E6="✓")*1+('สัปดาห์ที่ 3'!E6="✓")*1+('สัปดาห์ที่ 4'!E6="✓")*1+('สัปดาห์ที่ 5'!E6="✓")*1+('สัปดาห์ที่ 6'!E6="✓")*1+('สัปดาห์ที่ 7'!E6="✓")*1+('สัปดาห์ที่ 8'!E6="✓")*1+('สัปดาห์ที่ 9'!E6="✓")*1+('สัปดาห์ที่ 10'!E6="✓")*1+('สัปดาห์ที่ 11'!E6="✓")*1+('สัปดาห์ที่ 12'!E6="✓")*1+('สัปดาห์ที่ 13'!E6="✓")*1+('สัปดาห์ที่ 14'!E6="✓")*1+('สัปดาห์ที่ 15'!E6="✓")*1+('สัปดาห์ที่ 16'!E6="✓")*1+('สัปดาห์ที่ 17'!E6="✓")*1+('สัปดาห์ที่ 18'!E6="✓")*1+('สัปดาห์ที่ 19'!E6="✓")*1+('สัปดาห์ที่ 20'!E6="✓")*1) -> 0 | F4: =SUMPRODUCT(('สัปดาห์ที่ 1'!F6="✓")*1+('สัปดาห์ที่ 2'!F6="✓")*1+('สัปดาห์ที่ 3'!F6="✓")*1+('สัปดาห์ที่ 4'!F6="✓")*1+('สัปดาห์ที่ 5'!F6="✓")*1+('สัปดาห์ที่ 6'!F6="✓")*1+('สัปดาห์ที่ 7'!F6="✓")*1+('สัปดาห์ที่ 8'!F6="✓")*1+('สัปดาห์ที่ 9'!F6="✓")*1+('สัปดาห์ที่ 10'!F6="✓")*1+('สัปดาห์ที่ 11'!F6="✓")*1+('สัปดาห์ที่ 12'!F6="✓")*1+('สัปดาห์ที่ 13'!F6="✓")*1+('สัปดาห์ที่ 14'!F6="✓")*1+('สัปดาห์ที่ 15'!F6="✓")*1+('สัปดาห์ที่ 16'!F6="✓")*1+('สัปดาห์ที่ 17'!F6="✓")*1+('สัปดาห์ที่ 18'!F6="✓")*1+('สัปดาห์ที่ 19'!F6="✓")*1+('สัปดาห์ที่ 20'!F6="✓")*1) -> 0 | G4: =SUMPRODUCT(('สัปดาห์ที่ 1'!G6="✓")*1+('สัปดาห์ที่ 2'!G6="✓")*1+('สัปดาห์ที่ 3'!G6="✓")*1+('สัปดาห์ที่ 4'!G6="✓")*1+('สัปดาห์ที่ 5'!G6="✓")*1+('สัปดาห์ที่ 6'!G6="✓")*1+('สัปดาห์ที่ 7'!G6="✓")*1+('สัปดาห์ที่ 8'!G6="✓")*1+('สัปดาห์ที่ 9'!G6="✓")*1+('สัปดาห์ที่ 10'!G6="✓")*1+('สัปดาห์ที่ 11'!G6="✓")*1+('สัปดาห์ที่ 12'!G6="✓")*1+('สัปดาห์ที่ 13'!G6="✓")*1+('สัปดาห์ที่ 14'!G6="✓")*1+('สัปดาห์ที่ 15'!G6="✓")*1+('สัปดาห์ที่ 16'!G6="✓")*1+('สัปดาห์ที่ 17'!G6="✓")*1+('สัปดาห์ที่ 18'!G6="✓")*1+('สัปดาห์ที่ 19'!G6="✓")*1+('สัปดาห์ที่ 20'!G6="✓")*1) -> 0 | H4: =SUMPRODUCT(('สัปดาห์ที่ 1'!H6="✓")*1+('สัปดาห์ที่ 2'!H6="✓")*1+('สัปดาห์ที่ 3'!H6="✓")*1+('สัปดาห์ที่ 4'!H6="✓")*1+('สัปดาห์ที่ 5'!H6="✓")*1+('สัปดาห์ที่ 6'!H6="✓")*1+('สัปดาห์ที่ 7'!H6="✓")*1+('สัปดาห์ที่ 8'!H6="✓")*1+('สัปดาห์ที่ 9'!H6="✓")*1+('สัปดาห์ที่ 10'!H6="✓")*1+('สัปดาห์ที่ 11'!H6="✓")*1+('สัปดาห์ที่ 12'!H6="✓")*1+('สัปดาห์ที่ 13'!H6="✓")*1+('สัปดาห์ที่ 14'!H6="✓")*1+('สัปดาห์ที่ 15'!H6="✓")*1+('สัปดาห์ที่ 16'!H6="✓")*1+('สัปดาห์ที่ 17'!H6="✓")*1+('สัปดาห์ที่ 18'!H6="✓")*1+('สัปดาห์ที่ 19'!H6="✓")*1+('สัปดาห์ที่ 20'!H6="✓")*1) -> 0 | I4: =SUMPRODUCT(('สัปดาห์ที่ 1'!I6="✓")*1+('สัปดาห์ที่ 2'!I6="✓")*1+('สัปดาห์ที่ 3'!I6="✓")*1+('สัปดาห์ที่ 4'!I6="✓")*1+('สัปดาห์ที่ 5'!I6="✓")*1+('สัปดาห์ที่ 6'!I6="✓")*1+('สัปดาห์ที่ 7'!I6="✓")*1+('สัปดาห์ที่ 8'!I6="✓")*1+('สัปดาห์ที่ 9'!I6="✓")*1+('สัปดาห์ที่ 10'!I6="✓")*1+('สัปดาห์ที่ 11'!I6="✓")*1+('สัปดาห์ที่ 12'!I6="✓")*1+('สัปดาห์ที่ 13'!I6="✓")*1+('สัปดาห์ที่ 14'!I6="✓")*1+('สัปดาห์ที่ 15'!I6="✓")*1+('สัปดาห์ที่ 16'!I6="✓")*1+('สัปดาห์ที่ 17'!I6="✓")*1+('สัปดาห์ที่ 18'!I6="✓")*1+('สัปดาห์ที่ 19'!I6="✓")*1+('สัปดาห์ที่ 20'!I6="✓")*1) -> 0 | J4: =SUM(D4:I4) -> 0
A5: 2 | B5: เด็กชายตะวัน | C5: เจริญผล | D5: =SUMPRODUCT(('สัปดาห์ที่ 1'!D7="✓")*1+('สัปดาห์ที่ 2'!D7="✓")*1+('สัปดาห์ที่ 3'!D7="✓")*1+('สัปดาห์ที่ 4'!D7="✓")*1+('สัปดาห์ที่ 5'!D7="✓")*1+('สัปดาห์ที่ 6'!D7="✓")*1+('สัปดาห์ที่ 7'!D7="✓")*1+('สัปดาห์ที่ 8'!D7="✓")*1+('สัปดาห์ที่ 9'!D7="✓")*1+('สัปดาห์ที่ 10'!D7="✓")*1+('สัปดาห์ที่ 11'!D7="✓")*1+('สัปดาห์ที่ 12'!D7="✓")*1+('สัปดาห์ที่ 13'!D7="✓")*1+('สัปดาห์ที่ 14'!D7="✓")*1+('สัปดาห์ที่ 15'!D7="✓")*1+('สัปดาห์ที่ 16'!D7="✓")*1+('สัปดาห์ที่ 17'!D7="✓")*1+('สัปดาห์ที่ 18'!D7="✓")*1+('สัปดาห์ที่ 19'!D7="✓")*1+('สัปดาห์ที่ 20'!D7="✓")*1) -> 0 | E5: =SUMPRODUCT(('สัปดาห์ที่ 1'!E7="✓")*1+('สัปดาห์ที่ 2'!E7="✓")*1+('สัปดาห์ที่ 3'!E7="✓")*1+('สัปดาห์ที่ 4'!E7="✓")*1+('สัปดาห์ที่ 5'!E7="✓")*1+('สัปดาห์ที่ 6'!E7="✓")*1+('สัปดาห์ที่ 7'!E7="✓")*1+('สัปดาห์ที่ 8'!E7="✓")*1+('สัปดาห์ที่ 9'!E7="✓")*1+('สัปดาห์ที่ 10'!E7="✓")*1+('สัปดาห์ที่ 11'!E7="✓")*1+('สัปดาห์ที่ 12'!E7="✓")*1+('สัปดาห์ที่ 13'!E7="✓")*1+('สัปดาห์ที่ 14'!E7="✓")*1+('สัปดาห์ที่ 15'!E7="✓")*1+('สัปดาห์ที่ 16'!E7="✓")*1+('สัปดาห์ที่ 17'!E7="✓")*1+('สัปดาห์ที่ 18'!E7="✓")*1+('สัปดาห์ที่ 19'!E7="✓")*1+('สัปดาห์ที่ 20'!E7="✓")*1) -> 0 | F5: =SUMPRODUCT(('สัปดาห์ที่ 1'!F7="✓")*1+('สัปดาห์ที่ 2'!F7="✓")*1+('สัปดาห์ที่ 3'!F7="✓")*1+('สัปดาห์ที่ 4'!F7="✓")*1+('สัปดาห์ที่ 5'!F7="✓")*1+('สัปดาห์ที่ 6'!F7="✓")*1+('สัปดาห์ที่ 7'!F7="✓")*1+('สัปดาห์ที่ 8'!F7="✓")*1+('สัปดาห์ที่ 9'!F7="✓")*1+('สัปดาห์ที่ 10'!F7="✓")*1+('สัปดาห์ที่ 11'!F7="✓")*1+('สัปดาห์ที่ 12'!F7="✓")*1+('สัปดาห์ที่ 13'!F7="✓")*1+('สัปดาห์ที่ 14'!F7="✓")*1+('สัปดาห์ที่ 15'!F7="✓")*1+('สัปดาห์ที่ 16'!F7="✓")*1+('สัปดาห์ที่ 17'!F7="✓")*1+('สัปดาห์ที่ 18'!F7="✓")*1+('สัปดาห์ที่ 19'!F7="✓")*1+('สัปดาห์ที่ 20'!F7="✓")*1) -> 0 | G5: =SUMPRODUCT(('สัปดาห์ที่ 1'!G7="✓")*1+('สัปดาห์ที่ 2'!G7="✓")*1+('สัปดาห์ที่ 3'!G7="✓")*1+('สัปดาห์ที่ 4'!G7="✓")*1+('สัปดาห์ที่ 5'!G7="✓")*1+('สัปดาห์ที่ 6'!G7="✓")*1+('สัปดาห์ที่ 7'!G7="✓")*1+('สัปดาห์ที่ 8'!G7="✓")*1+('สัปดาห์ที่ 9'!G7="✓")*1+('สัปดาห์ที่ 10'!G7="✓")*1+('สัปดาห์ที่ 11'!G7="✓")*1+('สัปดาห์ที่ 12'!G7="✓")*1+('สัปดาห์ที่ 13'!G7="✓")*1+('สัปดาห์ที่ 14'!G7="✓")*1+('สัปดาห์ที่ 15'!G7="✓")*1+('สัปดาห์ที่ 16'!G7="✓")*1+('สัปดาห์ที่ 17'!G7="✓")*1+('สัปดาห์ที่ 18'!G7="✓")*1+('สัปดาห์ที่ 19'!G7="✓")*1+('สัปดาห์ที่ 20'!G7="✓")*1) -> 0 | H5: =SUMPRODUCT(('สัปดาห์ที่ 1'!H7="✓")*1+('สัปดาห์ที่ 2'!H7="✓")*1+('สัปดาห์ที่ 3'!H7="✓")*1+('สัปดาห์ที่ 4'!H7="✓")*1+('สัปดาห์ที่ 5'!H7="✓")*1+('สัปดาห์ที่ 6'!H7="✓")*1+('สัปดาห์ที่ 7'!H7="✓")*1+('สัปดาห์ที่ 8'!H7="✓")*1+('สัปดาห์ที่ 9'!H7="✓")*1+('สัปดาห์ที่ 10'!H7="✓")*1+('สัปดาห์ที่ 11'!H7="✓")*1+('สัปดาห์ที่ 12'!H7="✓")*1+('สัปดาห์ที่ 13'!H7="✓")*1+('สัปดาห์ที่ 14'!H7="✓")*1+('สัปดาห์ที่ 15'!H7="✓")*1+('สัปดาห์ที่ 16'!H7="✓")*1+('สัปดาห์ที่ 17'!H7="✓")*1+('สัปดาห์ที่ 18'!H7="✓")*1+('สัปดาห์ที่ 19'!H7="✓")*1+('สัปดาห์ที่ 20'!H7="✓")*1) -> 0 | I5: =SUMPRODUCT(('สัปดาห์ที่ 1'!I7="✓")*1+('สัปดาห์ที่ 2'!I7="✓")*1+('สัปดาห์ที่ 3'!I7="✓")*1+('สัปดาห์ที่ 4'!I7="✓")*1+('สัปดาห์ที่ 5'!I7="✓")*1+('สัปดาห์ที่ 6'!I7="✓")*1+('สัปดาห์ที่ 7'!I7="✓")*1+('สัปดาห์ที่ 8'!I7="✓")*1+('สัปดาห์ที่ 9'!I7="✓")*1+('สัปดาห์ที่ 10'!I7="✓")*1+('สัปดาห์ที่ 11'!I7="✓")*1+('สัปดาห์ที่ 12'!I7="✓")*1+('สัปดาห์ที่ 13'!I7="✓")*1+('สัปดาห์ที่ 14'!I7="✓")*1+('สัปดาห์ที่ 15'!I7="✓")*1+('สัปดาห์ที่ 16'!I7="✓")*1+('สัปดาห์ที่ 17'!I7="✓")*1+('สัปดาห์ที่ 18'!I7="✓")*1+('สัปดาห์ที่ 19'!I7="✓")*1+('สัปดาห์ที่ 20'!I7="✓")*1) -> 0 | J5: =SUM(D5:I5) -> 0
A6: 3 | B6: เด็กชายภิมรภัทร | C6: คำนึงคิด | D6: =SUMPRODUCT(('สัปดาห์ที่ 1'!D8="✓")*1+('สัปดาห์ที่ 2'!D8="✓")*1+('สัปดาห์ที่ 3'!D8="✓")*1+('สัปดาห์ที่ 4'!D8="✓")*1+('สัปดาห์ที่ 5'!D8="✓")*1+('สัปดาห์ที่ 6'!D8="✓")*1+('สัปดาห์ที่ 7'!D8="✓")*1+('สัปดาห์ที่ 8'!D8="✓")*1+('สัปดาห์ที่ 9'!D8="✓")*1+('สัปดาห์ที่ 10'!D8="✓")*1+('สัปดาห์ที่ 11'!D8="✓")*1+('สัปดาห์ที่ 12'!D8="✓")*1+('สัปดาห์ที่ 13'!D8="✓")*1+('สัปดาห์ที่ 14'!D8="✓")*1+('สัปดาห์ที่ 15'!D8="✓")*1+('สัปดาห์ที่ 16'!D8="✓")*1+('สัปดาห์ที่ 17'!D8="✓")*1+('สัปดาห์ที่ 18'!D8="✓")*1+('สัปดาห์ที่ 19'!D8="✓")*1+('สัปดาห์ที่ 20'!D8="✓")*1) -> 0 | E6: =SUMPRODUCT(('สัปดาห์ที่ 1'!E8="✓")*1+('สัปดาห์ที่ 2'!E8="✓")*1+('สัปดาห์ที่ 3'!E8="✓")*1+('สัปดาห์ที่ 4'!E8="✓")*1+('สัปดาห์ที่ 5'!E8="✓")*1+('สัปดาห์ที่ 6'!E8="✓")*1+('สัปดาห์ที่ 7'!E8="✓")*1+('สัปดาห์ที่ 8'!E8="✓")*1+('สัปดาห์ที่ 9'!E8="✓")*1+('สัปดาห์ที่ 10'!E8="✓")*1+('สัปดาห์ที่ 11'!E8="✓")*1+('สัปดาห์ที่ 12'!E8="✓")*1+('สัปดาห์ที่ 13'!E8="✓")*1+('สัปดาห์ที่ 14'!E8="✓")*1+('สัปดาห์ที่ 15'!E8="✓")*1+('สัปดาห์ที่ 16'!E8="✓")*1+('สัปดาห์ที่ 17'!E8="✓")*1+('สัปดาห์ที่ 18'!E8="✓")*1+('สัปดาห์ที่ 19'!E8="✓")*1+('สัปดาห์ที่ 20'!E8="✓")*1) -> 0 | F6: =SUMPRODUCT(('สัปดาห์ที่ 1'!F8="✓")*1+('สัปดาห์ที่ 2'!F8="✓")*1+('สัปดาห์ที่ 3'!F8="✓")*1+('สัปดาห์ที่ 4'!F8="✓")*1+('สัปดาห์ที่ 5'!F8="✓")*1+('สัปดาห์ที่ 6'!F8="✓")*1+('สัปดาห์ที่ 7'!F8="✓")*1+('สัปดาห์ที่ 8'!F8="✓")*1+('สัปดาห์ที่ 9'!F8="✓")*1+('สัปดาห์ที่ 10'!F8="✓")*1+('สัปดาห์ที่ 11'!F8="✓")*1+('สัปดาห์ที่ 12'!F8="✓")*1+('สัปดาห์ที่ 13'!F8="✓")*1+('สัปดาห์ที่ 14'!F8="✓")*1+('สัปดาห์ที่ 15'!F8="✓")*1+('สัปดาห์ที่ 16'!F8="✓")*1+('สัปดาห์ที่ 17'!F8="✓")*1+('สัปดาห์ที่ 18'!F8="✓")*1+('สัปดาห์ที่ 19'!F8="✓")*1+('สัปดาห์ที่ 20'!F8="✓")*1) -> 0 | G6: =SUMPRODUCT(('สัปดาห์ที่ 1'!G8="✓")*1+('สัปดาห์ที่ 2'!G8="✓")*1+('สัปดาห์ที่ 3'!G8="✓")*1+('สัปดาห์ที่ 4'!G8="✓")*1+('สัปดาห์ที่ 5'!G8="✓")*1+('สัปดาห์ที่ 6'!G8="✓")*1+('สัปดาห์ที่ 7'!G8="✓")*1+('สัปดาห์ที่ 8'!G8="✓")*1+('สัปดาห์ที่ 9'!G8="✓")*1+('สัปดาห์ที่ 10'!G8="✓")*1+('สัปดาห์ที่ 11'!G8="✓")*1+('สัปดาห์ที่ 12'!G8="✓")*1+('สัปดาห์ที่ 13'!G8="✓")*1+('สัปดาห์ที่ 14'!G8="✓")*1+('สัปดาห์ที่ 15'!G8="✓")*1+('สัปดาห์ที่ 16'!G8="✓")*1+('สัปดาห์ที่ 17'!G8="✓")*1+('สัปดาห์ที่ 18'!G8="✓")*1+('สัปดาห์ที่ 19'!G8="✓")*1+('สัปดาห์ที่ 20'!G8="✓")*1) -> 0 | H6: =SUMPRODUCT(('สัปดาห์ที่ 1'!H8="✓")*1+('สัปดาห์ที่ 2'!H8="✓")*1+('สัปดาห์ที่ 3'!H8="✓")*1+('สัปดาห์ที่ 4'!H8="✓")*1+('สัปดาห์ที่ 5'!H8="✓")*1+('สัปดาห์ที่ 6'!H8="✓")*1+('สัปดาห์ที่ 7'!H8="✓")*1+('สัปดาห์ที่ 8'!H8="✓")*1+('สัปดาห์ที่ 9'!H8="✓")*1+('สัปดาห์ที่ 10'!H8="✓")*1+('สัปดาห์ที่ 11'!H8="✓")*1+('สัปดาห์ที่ 12'!H8="✓")*1+('สัปดาห์ที่ 13'!H8="✓")*1+('สัปดาห์ที่ 14'!H8="✓")*1+('สัปดาห์ที่ 15'!H8="✓")*1+('สัปดาห์ที่ 16'!H8="✓")*1+('สัปดาห์ที่ 17'!H8="✓")*1+('สัปดาห์ที่ 18'!H8="✓")*1+('สัปดาห์ที่ 19'!H8="✓")*1+('สัปดาห์ที่ 20'!H8="✓")*1) -> 0 | I6: =SUMPRODUCT(('สัปดาห์ที่ 1'!I8="✓")*1+('สัปดาห์ที่ 2'!I8="✓")*1+('สัปดาห์ที่ 3'!I8="✓")*1+('สัปดาห์ที่ 4'!I8="✓")*1+('สัปดาห์ที่ 5'!I8="✓")*1+('สัปดาห์ที่ 6'!I8="✓")*1+('สัปดาห์ที่ 7'!I8="✓")*1+('สัปดาห์ที่ 8'!I8="✓")*1+('สัปดาห์ที่ 9'!I8="✓")*1+('สัปดาห์ที่ 10'!I8="✓")*1+('สัปดาห์ที่ 11'!I8="✓")*1+('สัปดาห์ที่ 12'!I8="✓")*1+('สัปดาห์ที่ 13'!I8="✓")*1+('สัปดาห์ที่ 14'!I8="✓")*1+('สัปดาห์ที่ 15'!I8="✓")*1+('สัปดาห์ที่ 16'!I8="✓")*1+('สัปดาห์ที่ 17'!I8="✓")*1+('สัปดาห์ที่ 18'!I8="✓")*1+('สัปดาห์ที่ 19'!I8="✓")*1+('สัปดาห์ที่ 20'!I8="✓")*1) -> 0 | J6: =SUM(D6:I6) -> 0
A7: 4 | B7: เด็กชายธิรพงศ์ | C7: อู่อ่อน | D7: =SUMPRODUCT(('สัปดาห์ที่ 1'!D9="✓")*1+('สัปดาห์ที่ 2'!D9="✓")*1+('สัปดาห์ที่ 3'!D9="✓")*1+('สัปดาห์ที่ 4'!D9="✓")*1+('สัปดาห์ที่ 5'!D9="✓")*1+('สัปดาห์ที่ 6'!D9="✓")*1+('สัปดาห์ที่ 7'!D9="✓")*1+('สัปดาห์ที่ 8'!D9="✓")*1+('สัปดาห์ที่ 9'!D9="✓")*1+('สัปดาห์ที่ 10'!D9="✓")*1+('สัปดาห์ที่ 11'!D9="✓")*1+('สัปดาห์ที่ 12'!D9="✓")*1+('สัปดาห์ที่ 13'!D9="✓")*1+('สัปดาห์ที่ 14'!D9="✓")*1+('สัปดาห์ที่ 15'!D9="✓")*1+('สัปดาห์ที่ 16'!D9="✓")*1+('สัปดาห์ที่ 17'!D9="✓")*1+('สัปดาห์ที่ 18'!D9="✓")*1+('สัปดาห์ที่ 19'!D9="✓")*1+('สัปดาห์ที่ 20'!D9="✓")*1) -> 0 | E7: =SUMPRODUCT(('สัปดาห์ที่ 1'!E9="✓")*1+('สัปดาห์ที่ 2'!E9="✓")*1+('สัปดาห์ที่ 3'!E9="✓")*1+('สัปดาห์ที่ 4'!E9="✓")*1+('สัปดาห์ที่ 5'!E9="✓")*1+('สัปดาห์ที่ 6'!E9="✓")*1+('สัปดาห์ที่ 7'!E9="✓")*1+('สัปดาห์ที่ 8'!E9="✓")*1+('สัปดาห์ที่ 9'!E9="✓")*1+('สัปดาห์ที่ 10'!E9="✓")*1+('สัปดาห์ที่ 11'!E9="✓")*1+('สัปดาห์ที่ 12'!E9="✓")*1+('สัปดาห์ที่ 13'!E9="✓")*1+('สัปดาห์ที่ 14'!E9="✓")*1+('สัปดาห์ที่ 15'!E9="✓")*1+('สัปดาห์ที่ 16'!E9="✓")*1+('สัปดาห์ที่ 17'!E9="✓")*1+('สัปดาห์ที่ 18'!E9="✓")*1+('สัปดาห์ที่ 19'!E9="✓")*1+('สัปดาห์ที่ 20'!E9="✓")*1) -> 0 | F7: =SUMPRODUCT(('สัปดาห์ที่ 1'!F9="✓")*1+('สัปดาห์ที่ 2'!F9="✓")*1+('สัปดาห์ที่ 3'!F9="✓")*1+('สัปดาห์ที่ 4'!F9="✓")*1+('สัปดาห์ที่ 5'!F9="✓")*1+('สัปดาห์ที่ 6'!F9="✓")*1+('สัปดาห์ที่ 7'!F9="✓")*1+('สัปดาห์ที่ 8'!F9="✓")*1+('สัปดาห์ที่ 9'!F9="✓")*1+('สัปดาห์ที่ 10'!F9="✓")*1+('สัปดาห์ที่ 11'!F9="✓")*1+('สัปดาห์ที่ 12'!F9="✓")*1+('สัปดาห์ที่ 13'!F9="✓")*1+('สัปดาห์ที่ 14'!F9="✓")*1+('สัปดาห์ที่ 15'!F9="✓")*1+('สัปดาห์ที่ 16'!F9="✓")*1+('สัปดาห์ที่ 17'!F9="✓")*1+('สัปดาห์ที่ 18'!F9="✓")*1+('สัปดาห์ที่ 19'!F9="✓")*1+('สัปดาห์ที่ 20'!F9="✓")*1) -> 0 | G7: =SUMPRODUCT(('สัปดาห์ที่ 1'!G9="✓")*1+('สัปดาห์ที่ 2'!G9="✓")*1+('สัปดาห์ที่ 3'!G9="✓")*1+('สัปดาห์ที่ 4'!G9="✓")*1+('สัปดาห์ที่ 5'!G9="✓")*1+('สัปดาห์ที่ 6'!G9="✓")*1+('สัปดาห์ที่ 7'!G9="✓")*1+('สัปดาห์ที่ 8'!G9="✓")*1+('สัปดาห์ที่ 9'!G9="✓")*1+('สัปดาห์ที่ 10'!G9="✓")*1+('สัปดาห์ที่ 11'!G9="✓")*1+('สัปดาห์ที่ 12'!G9="✓")*1+('สัปดาห์ที่ 13'!G9="✓")*1+('สัปดาห์ที่ 14'!G9="✓")*1+('สัปดาห์ที่ 15'!G9="✓")*1+('สัปดาห์ที่ 16'!G9="✓")*1+('สัปดาห์ที่ 17'!G9="✓")*1+('สัปดาห์ที่ 18'!G9="✓")*1+('สัปดาห์ที่ 19'!G9="✓")*1+('สัปดาห์ที่ 20'!G9="✓")*1) -> 0 | H7: =SUMPRODUCT(('สัปดาห์ที่ 1'!H9="✓")*1+('สัปดาห์ที่ 2'!H9="✓")*1+('สัปดาห์ที่ 3'!H9="✓")*1+('สัปดาห์ที่ 4'!H9="✓")*1+('สัปดาห์ที่ 5'!H9="✓")*1+('สัปดาห์ที่ 6'!H9="✓")*1+('สัปดาห์ที่ 7'!H9="✓")*1+('สัปดาห์ที่ 8'!H9="✓")*1+('สัปดาห์ที่ 9'!H9="✓")*1+('สัปดาห์ที่ 10'!H9="✓")*1+('สัปดาห์ที่ 11'!H9="✓")*1+('สัปดาห์ที่ 12'!H9="✓")*1+('สัปดาห์ที่ 13'!H9="✓")*1+('สัปดาห์ที่ 14'!H9="✓")*1+('สัปดาห์ที่ 15'!H9="✓")*1+('สัปดาห์ที่ 16'!H9="✓")*1+('สัปดาห์ที่ 17'!H9="✓")*1+('สัปดาห์ที่ 18'!H9="✓")*1+('สัปดาห์ที่ 19'!H9="✓")*1+('สัปดาห์ที่ 20'!H9="✓")*1) -> 0 | I7: =SUMPRODUCT(('สัปดาห์ที่ 1'!I9="✓")*1+('สัปดาห์ที่ 2'!I9="✓")*1+('สัปดาห์ที่ 3'!I9="✓")*1+('สัปดาห์ที่ 4'!I9="✓")*1+('สัปดาห์ที่ 5'!I9="✓")*1+('สัปดาห์ที่ 6'!I9="✓")*1+('สัปดาห์ที่ 7'!I9="✓")*1+('สัปดาห์ที่ 8'!I9="✓")*1+('สัปดาห์ที่ 9'!I9="✓")*1+('สัปดาห์ที่ 10'!I9="✓")*1+('สัปดาห์ที่ 11'!I9="✓")*1+('สัปดาห์ที่ 12'!I9="✓")*1+('สัปดาห์ที่ 13'!I9="✓")*1+('สัปดาห์ที่ 14'!I9="✓")*1+('สัปดาห์ที่ 15'!I9="✓")*1+('สัปดาห์ที่ 16'!I9="✓")*1+('สัปดาห์ที่ 17'!I9="✓")*1+('สัปดาห์ที่ 18'!I9="✓")*1+('สัปดาห์ที่ 19'!I9="✓")*1+('สัปดาห์ที่ 20'!I9="✓")*1) -> 0 | J7: =SUM(D7:I7) -> 0
