Workbook

Sheet สัปดาห์ที่ 1
A1: แบบบันทึกการเล่นตามมุมประสบการณ์ภายนอกห้องเรียนของเด็กปฐมวัยรายสัปดาห์
A2: โรงเรียนเทศบาลบ้านเพ ๑ สังกัดกองการศึกษา เทศบาลตำบลบ้านเพ ชั้น อ.๑/๓
A3: สัปดาห์ที่ 1 | D3: วันที่ .............. ถึง .............. เดือน .............. พ.ศ. ..............
D4: มุมเสริมประสบการณ์ภายในห้องเรียน | J4: มุมเสริมประสบการณ์แหล่งเรียนรู้ นอกห้องเรียน | M4: สรุป มุมที่เล่น
A5: ที่ | B5: ชื่อ | C5: นามสกุล | D5: มุมบล็อก | E5: มุมนิทาน | F5: มุมแต่งตัว | G5: มุมสร้างสรรค์ | H5: มุมบทบาทสมมติ | I5: มุมสื่อ | J5: มุมทราย/น้ำ | K5: มุมธรรมชาติ | L5: มุมออกกำลังกาย | M5: จำนวน มุม
A6: 1 | B6: เด็กชายนันทิพัฒน์ | C6: ฤทธิ์นอก | M6: =COUNTIF(D6:L6,"✓") -> 0
A7: 2 | B7: เด็กหญิงปาณิสรา | C7: บางขุนทด | M7: =COUNTIF(D7:L7,"✓") -> 0
A8: 3 | B8: เด็กหญิงกรายทิพย์ | C8: พันธ์สวัสดิ์ | M8: =COUNTIF(D8:L8,"✓") -> 0
A9: 4 | B9: เด็กหญิงจารุวรรณ | C9: เหมือนประโคน | M9: =COUNTIF(D9:L9,"✓") -> 0
A10: 5 | B10: เด็กชายนิติพัฒน์ | C10: พูดเพราะ | M10: =COUNTIF(D10:L10,"✓") -> 0
A11: 6 | B11: เด็กชายธนวัฒน์ | C11: บางทุ่มแบน | M11: =COUNTIF(D11:L11,"✓") -> 0
A12: 7 | B12: เด็กชายปิยวัฒน์ | C12: กิ่งเกตุ | M12: =COUNTIF(D12:L12,"✓") -> 0
A13: 8 | B13: เด็กหญิงรัญจิดา | C13: แสนเจริญ | M13: =COUNTIF(D13:L13,"✓") -> 0
A14: 9 | B14: เด็กหญิงพรนัชชา | C14: เปลื้องกลาง | M14: =COUNTIF(D14:L14,"✓") -> 0
A15: 10 | B15: เด็กหญิงจันเอย | C15: ทน | M15: =COUNTIF(D15:L15,"✓") -> 0
A16: 11 | B16: เด็กชายศริตวรรธน์ | C16: การดี | M16: =COUNTIF(D16:L16,"✓") -> 0
A17: 12 | B17: เด็กหญิงมนัสนันท์ | C17: เหลืองอร่าม | M17: =COUNTIF(D17:L17,"✓") -> 0
... A20: 15 | B20: เด็กชายต้นกล้า | C20: ลิทธิศักดิ์ | M20: =COUNTIF(D20:L20,"✓") -> 0
A21: รวมจำนวนนักเรียนที่เล่นแต่ละมุม | D21: =COUNTIF(D6:D20,"✓") -> 0 | E21: =COUNTIF(E6:E20,"✓") -> 0 | F21: =COUNTIF(F6:F20,"✓") -> 0 | G21: =COUNTIF(G6:G20,"✓") -> 0 | H21: =COUNTIF(H6:H20,"✓") -> 0 | I21: =COUNTIF(I6:I20,"✓") -> 0 | J21: =COUNTIF(J6:J20,"✓") -> 0 | K21: =COUNTIF(K6:K20,"✓") -> 0 | L21: =COUNTIF(L6:L20,"✓") -> 0 | M21: =SUM(M6:M20) -> 0
A23: ลงชื่อ .................................................. ผู้บันทึก ( นางสาวชลดา กู่เฟี้ยม )

Sheet สัปดาห์ที่ 2
A1: แบบบันทึกการเล่นตามมุมประสบการณ์ของเด็กปฐมวัยรายสัปดาห์
A2: โรงเรียนเทศบาลบ้านเพ ๑ สังกัดกองการศึกษา เทศบาลตำบลบ้านเพ ชั้น อ.๑/๓
A3: สัปดาห์ที่ 2 | D3: วันที่ .............. ถึง .............. เดือน .............. พ.ศ. ..............
D4: มุมเสริมประสบการณ์ภายในห้องเรียน | J4: มุมเสริมประสบการณ์แหล่งเรียนรู้ นอกห้องเรียน | M4: สรุป มุมที่เล่น
A5: ที่ | B5: ชื่อ | C5: นามสกุล | D5: มุมบล็อก | E5: มุมนิทาน | F5: มุมแต่งตัว | G5: มุมสร้างสรรค์ | H5: มุมบทบาทสมมติ | I5: มุมสื่อ | J5: มุมทราย/น้ำ | K5: มุมธรรมชาติ | L5: มุมออกกำลังกาย | M5: จำนวน มุม
A6: 1 | B6: เด็กชายนันทิพัฒน์ | C6: ฤทธิ์นอก | M6: =COUNTIF(D6:L6,"✓") -> 0
A7: 2 | B7: เด็กหญิงปาณิสรา | C7: บางขุนทด | M7: =COUNTIF(D7:L7,"✓") -> 0
A8: 3 | B8: เด็กหญิงกรายทิพย์ | C8: พันธ์สวัสดิ์ | M8: =COUNTIF(D8:L8,"✓") -> 0
A9: 4 | B9: เด็กหญิงจารุวรรณ | C9: เหมือนประโคน | M9: =COUNTIF(D9:L9,"✓") -> 0
A10: 5 | B10: เด็กชายนิติพัฒน์ | C10: พูดเพราะ | M10: =COUNTIF(D10:L10,"✓") -> 0
A11: 6 | B11: เด็กชายธนวัฒน์ | C11: บางทุ่มแบน | M11: =COUNTIF(D11:L11,"✓") -> 0
A12: 7 | B12: เด็กชายปิยวัฒน์ | C12: กิ่งเกตุ | M12: =COUNTIF(D12:L12,"✓") -> 0
A13: 8 | B13: เด็กหญิงรัญจิดา | C13: แสนเจริญ | M13: =COUNTIF(D13:L13,"✓") -> 0
A14: 9 | B14: เด็กหญิงพรนัชชา | C14: เปลื้องกลาง | M14: =COUNTIF(D14:L14,"✓") -> 0
A15: 10 | B15: เด็กหญิงจันเอย | C15: ทน | M15: =COUNTIF(D15:L15,"✓") -> 0
A16: 11 | B16: เด็กชายศริตวรรธน์ | C16: การดี | M16: =COUNTIF(D16:L16,"✓") -> 0
A17: 12 | B17: เด็กหญิงมนัสนันท์ | C17: เหลืองอร่าม | M17: =COUNTIF(D17:L17,"✓") -> 0
... A20: 15 | B20: เด็กชายต้นกล้า | C20: ลิทธิศักดิ์ | M20: =COUNTIF(D20:L20,"✓") -> 0
A21: รวมจำนวนนักเรียนที่เล่นแต่ละมุม | D21: =COUNTIF(D6:D20,"✓") -> 0 | E21: =COUNTIF(E6:E20,"✓") -> 0 | F21: =COUNTIF(F6:F20,"✓") -> 0 | G21: =COUNTIF(G6:G20,"✓") -> 0 | H21: =COUNTIF(H6:H20,"✓") -> 0 | I21: =COUNTIF(I6:I20,"✓") -> 0 | J21: =COUNTIF(J6:J20,"✓") -> 0 | K21: =COUNTIF(K6:K20,"✓") -> 0 | L21: =COUNTIF(L6:L20,"✓") -> 0 | M21: =SUM(M6:M20) -> 0
A23: ลงชื่อ .................................................. ผู้บันทึก ( นางสาวชลดา กู่เฟี้ยม )

Sheet สัปดาห์ที่ 3
A1: แบบบันทึกการเล่นตามมุมประสบการณ์ของเด็กปฐมวัยรายสัปดาห์
A2: โรงเรียนเทศบาลบ้านเพ ๑ สังกัดกองการศึกษา เทศบาลตำบลบ้านเพ ชั้น อ.๑/๓
A3: สัปดาห์ที่ 3 | D3: วันที่ .............. ถึง .............. เดือน .............. พ.ศ. ..............
D4: มุมเสริมประสบการณ์ภายในห้องเรียน | J4: มุมเสริมประสบการณ์แหล่งเรียนรู้ นอกห้องเรียน | M4: สรุป มุมที่เล่น
A5: ที่ | B5: ชื่อ | C5: นามสกุล | D5: มุมบล็อก | E5: มุมนิทาน | F5: มุมแต่งตัว | G5: มุมสร้างสรรค์ | H5: มุมบทบาทสมมติ | I5: มุมสื่อ | J5: มุมทราย/น้ำ | K5: มุมธรรมชาติ | L5: มุมออกกำลังกาย | M5: จำนวน มุม
A6: 1 | B6: เด็กชายนันทิพัฒน์ | C6: ฤทธิ์นอก | M6: =COUNTIF(D6:L6,"✓") -> 0
A7: 2 | B7: เด็กหญิงปาณิสรา | C7: บางขุนทด | M7: =COUNTIF(D7:L7,"✓") -> 0
A8: 3 | B8: เด็กหญิงกรายทิพย์ | C8: พันธ์สวัสดิ์ | M8: =COUNTIF(D8:L8,"✓") -> 0
A9: 4 | B9: เด็กหญิงจารุวรรณ | C9: เหมือนประโคน | M9: =COUNTIF(D9:L9,"✓") -> 0
A10: 5 | B10: เด็กชายนิติพัฒน์ | C10: พูดเพราะ | M10: =COUNTIF(D10:L10,"✓") -> 0
A11: 6 | B11: เด็กชายธนวัฒน์ | C11: บางทุ่มแบน | M11: =COUNTIF(D11:L11,"✓") -> 0
A12: 7 | B12: เด็กชายปิยวัฒน์ | C12: กิ่งเกตุ | M12: =COUNTIF(D12:L12,"✓") -> 0
A13: 8 | B13: เด็กหญิงรัญจิดา | C13: แสนเจริญ | M13: =COUNTIF(D13:L13,"✓") -> 0
A14: 9 | B14: เด็กหญิงพรนัชชา | C14: เปลื้องกลาง | M14: =COUNTIF(D14:L14,"✓") -> 0
A15: 10 | B15: เด็กหญิงจันเอย | C15: ทน | M15: =COUNTIF(D15:L15,"✓") -> 0
A16: 11 | B16: เด็กชายศริตวรรธน์ | C16: การดี | M16: =COUNTIF(D16:L16,"✓") -> 0
A17: 12 | B17: เด็กหญิงมนัสนันท์ | C17: เหลืองอร่าม | M17: =COUNTIF(D17:L17,"✓") -> 0
... A20: 15 | B20: เด็กชายต้นกล้า | C20: ลิทธิศักดิ์ | M20: =COUNTIF(D20:L20,"✓") -> 0
A21: รวมจำนวนนักเรียนที่เล่นแต่ละมุม | D21: =COUNTIF(D6:D20,"✓") -> 0 | E21: =COUNTIF(E6:E20,"✓") -> 0 | F21: =COUNTIF(F6:F20,"✓") -> 0 | G21: =COUNTIF(G6:G20,"✓") -> 0 | H21: =COUNTIF(H6:H20,"✓") -> 0 | I21: =COUNTIF(I6:I20,"✓") -> 0 | J21: =COUNTIF(J6:J20,"✓") -> 0 | K21: =COUNTIF(K6:K20,"✓") -> 0 | L21: =COUNTIF(L6:L20,"✓") -> 0 | M21: =SUM(M6:M20) -> 0
A23: ลงชื่อ .................................................. ผู้บันทึก ( นางสาวชลดา กู่เฟี้ยม )

Sheet สัปดาห์ที่ 4
A1: แบบบันทึกการเล่นตามมุมประสบการณ์ของเด็กปฐมวัยรายสัปดาห์
A2: โรงเรียนเทศบาลบ้านเพ ๑ สังกัดกองการศึกษา เทศบาลตำบลบ้านเพ ชั้น อ.๑/๓
A3: สัปดาห์ที่ 4 | D3: วันที่ .............. ถึง .............. เดือน .............. พ.ศ. ..............
D4: มุมเสริมประสบการณ์ภายในห้องเรียน | J4: มุมเสริมประสบการณ์แหล่งเรียนรู้ นอกห้องเรียน | M4: สรุป มุมที่เล่น
A5: ที่ | B5: ชื่อ | C5: นามสกุล | D5: มุมบล็อก | E5: มุมนิทาน | F5: มุมแต่งตัว | G5: มุมสร้างสรรค์ | H5: มุมบทบาทสมมติ | I5: มุมสื่อ | J5: มุมทราย/น้ำ | K5: มุมธรรมชาติ | L5: มุมออกกำลังกาย | M5: จำนวน มุม
A6: 1 | B6: เด็กชายนันทิพัฒน์ | C6: ฤทธิ์นอก | M6: =COUNTIF(D6:L6,"✓") -> 0
A7: 2 | B7: เด็กหญิงปาณิสรา | C7: บางขุนทด | M7: =COUNTIF(D7:L7,"✓") -> 0
A8: 3 | B8: เด็กหญิงกรายทิพย์ | C8: พันธ์สวัสดิ์ | M8: =COUNTIF(D8:L8,"✓") -> 0
A9: 4 | B9: เด็กหญิงจารุวรรณ | C9: เหมือนประโคน | M9: =COUNTIF(D9:L9,"✓") -> 0
A10: 5 | B10: เด็กชายนิติพัฒน์ | C10: พูดเพราะ | M10: =COUNTIF(D10:L10,"✓") -> 0
A11: 6 | B11: เด็กชายธนวัฒน์ | C11: บางทุ่มแบน | M11: =COUNTIF(D11:L11,"✓") -> 0
A12: 7 | B12: เด็กชายปิยวัฒน์ | C12: กิ่งเกตุ | M12: =COUNTIF(D12:L12,"✓") -> 0
A13: 8 | B13: เด็กหญิงรัญจิดา | C13: แสนเจริญ | M13: =COUNTIF(D13:L13,"✓") -> 0
A14: 9 | B14: เด็กหญิงพรนัชชา | C14: เปลื้องกลาง | M14: =COUNTIF(D14:L14,"✓") -> 0
A15: 10 | B15: เด็กหญิงจันเอย | C15: ทน | M15: =COUNTIF(D15:L15,"✓") -> 0
A16: 11 | B16: เด็กชายศริตวรรธน์ | C16: การดี | M16: =COUNTIF(D16:L16,"✓") -> 0
A17: 12 | B17: เด็กหญิงมนัสนันท์ | C17: เหลืองอร่าม | M17: =COUNTIF(D17:L17,"✓") -> 0
... A20: 15 | B20: เด็กชายต้นกล้า | C20: ลิทธิศักดิ์ | M20: =COUNTIF(D20:L20,"✓") -> 0
A21: รวมจำนวนนักเรียนที่เล่นแต่ละมุม | D21: =COUNTIF(D6:D20,"✓") -> 0 | E21: =COUNTIF(E6:E20,"✓") -> 0 | F21: =COUNTIF(F6:F20,"✓") -> 0 | G21: =COUNTIF(G6:G20,"✓") -> 0 | H21: =COUNTIF(H6:H20,"✓") -> 0 | I21: =COUNTIF(I6:I20,"✓") -> 0 | J21: =COUNTIF(J6:J20,"✓") -> 0 | K21: =COUNTIF(K6:K20,"✓") -> 0 | L21: =COUNTIF(L6:L20,"✓") -> 0 | M21: =SUM(M6:M20) -> 0
A23: ลงชื่อ .................................................. ผู้บันทึก ( นางสาวชลดา กู่เฟี้ยม )

Sheet สัปดาห์ที่ 5
A1: แบบบันทึกการเล่นตามมุมประสบการณ์ของเด็กปฐมวัยรายสัปดาห์
A2: โรงเรียนเทศบาลบ้านเพ ๑ สังกัดกองการศึกษา เทศบาลตำบลบ้านเพ ชั้น อ.๑/๓
A3: สัปดาห์ที่ 5 | D3: วันที่ .............. ถึง .............. เดือน .............. พ.ศ. ..............
D4: มุมเสริมประสบการณ์ภายในห้องเรียน | J4: มุมเสริมประสบการณ์แหล่งเรียนรู้ นอกห้องเรียน | M4: สรุป มุมที่เล่น
A5: ที่ | B5: ชื่อ | C5: นามสกุล | D5: มุมบล็อก | E5: มุมนิทาน | F5: มุมแต่งตัว | G5: มุมสร้างสรรค์ | H5: มุมบทบาทสมมติ | I5: มุมสื่อ | J5: มุมทราย/น้ำ | K5: มุมธรรมชาติ | L5: มุมออกกำลังกาย | M5: จำนวน มุม
A6: 1 | B6: เด็กชายนันทิพัฒน์ | C6: ฤทธิ์นอก | M6: =COUNTIF(D6:L6,"✓") -> 0
A7: 2 | B7: เด็กหญิงปาณิสรา | C7: บางขุนทด | M7: =COUNTIF(D7:L7,"✓") -> 0
A8: 3 | B8: เด็กหญิงกรายทิพย์ | C8: พันธ์สวัสดิ์ | M8: =COUNTIF(D8:L8,"✓") -> 0
A9: 4 | B9: เด็กหญิงจารุวรรณ | C9: เหมือนประโคน | M9: =COUNTIF(D9:L9,"✓") -> 0
A10: 5 | B10: เด็กชายนิติพัฒน์ | C10: พูดเพราะ | M10: =COUNTIF(D10:L10,"✓") -> 0
A11: 6 | B11: เด็กชายธนวัฒน์ | C11: บางทุ่มแบน | M11: =COUNTIF(D11:L11,"✓") -> 0
A12: 7 | B12: เด็กชายปิยวัฒน์ | C12: กิ่งเกตุ | M12: =COUNTIF(D12:L12,"✓") -> 0
A13: 8 | B13: เด็กหญิงรัญจิดา | C13: แสนเจริญ | M13: =COUNTIF(D13:L13,"✓") -> 0
A14: 9 | B14: เด็กหญิงพรนัชชา | C14: เปลื้องกลาง | M14: =COUNTIF(D14:L14,"✓") -> 0
A15: 10 | B15: เด็กหญิงจันเอย | C15: ทน | M15: =COUNTIF(D15:L15,"✓") -> 0
A16: 11 | B16: เด็กชายศริตวรรธน์ | C16: การดี | M16: =COUNTIF(D16:L16,"✓") -> 0
A17: 12 | B17: เด็กหญิงมนัสนันท์ | C17: เหลืองอร่าม | M17: =COUNTIF(D17:L17,"✓") -> 0
... A20: 15 | B20: เด็กชายต้นกล้า | C20: ลิทธิศักดิ์ | M20: =COUNTIF(D20:L20,"✓") -> 0
A21: รวมจำนวนนักเรียนที่เล่นแต่ละมุม | D21: =COUNTIF(D6:D20,"✓") -> 0 | E21: =COUNTIF(E6:E20,"✓") -> 0 | F21: =COUNTIF(F6:F20,"✓") -> 0 | G21: =COUNTIF(G6:G20,"✓") -> 0 | H21: =COUNTIF(H6:H20,"✓") -> 0 | I21: =COUNTIF(I6:I20,"✓") -> 0 | J21: =COUNTIF(J6:J20,"✓") -> 0 | K21: =COUNTIF(K6:K20,"✓") -> 0 | L21: =COUNTIF(L6:L20,"✓") -> 0 | M21: =SUM(M6:M20) -> 0
A23: ลงชื่อ .................................................. ผู้บันทึก ( นางสาวชลดา กู่เฟี้ยม )

Sheet สัปดาห์ที่ 6
A1: แบบบันทึกการเล่นตามมุมประสบการณ์ของเด็กปฐมวัยรายสัปดาห์
A2: โรงเรียนเทศบาลบ้านเพ ๑ สังกัดกองการศึกษา เทศบาลตำบลบ้านเพ ชั้น อ.๑/๓
A3: สัปดาห์ที่ 6 | D3: วันที่ .............. ถึง .............. เดือน .............. พ.ศ. ..............
D4: มุมเสริมประสบการณ์ภายในห้องเรียน | J4: มุมเสริมประสบการณ์แหล่งเรียนรู้ นอกห้องเรียน | M4: สรุป มุมที่เล่น
A5: ที่ | B5: ชื่อ | C5: นามสกุล | D5: มุมบล็อก | E5: มุมนิทาน | F5: มุมแต่งตัว | G5: มุมสร้างสรรค์ | H5: มุมบทบาทสมมติ | I5: มุมสื่อ | J5: มุมทราย/น้ำ | K5: มุมธรรมชาติ | L5: มุมออกกำลังกาย | M5: จำนวน มุม
A6: 1 | B6: เด็กชายนันทิพัฒน์ | C6: ฤทธิ์นอก | M6: =COUNTIF(D6:L6,"✓") -> 0
A7: 2 | B7: เด็กหญิงปาณิสรา | C7: บางขุนทด | M7: =COUNTIF(D7:L7,"✓") -> 0
A8: 3 | B8: เด็กหญิงกรายทิพย์ | C8: พันธ์สวัสดิ์ | M8: =COUNTIF(D8:L8,"✓") -> 0
A9: 4 | B9: เด็กหญิงจารุวรรณ | C9: เหมือนประโคน | M9: =COUNTIF(D9:L9,"✓") -> 0
A10: 5 | B10: เด็กชายนิติพัฒน์ | C10: พูดเพราะ | M10: =COUNTIF(D10:L10,"✓") -> 0
A11: 6 | B11: เด็กชายธนวัฒน์ | C11: บางทุ่มแบน | M11: =COUNTIF(D11:L11,"✓") -> 0
A12: 7 | B12: เด็กชายปิยวัฒน์ | C12: กิ่งเกตุ | M12: =COUNTIF(D12:L12,"✓") -> 0
A13: 8 | B13: เด็กหญิงรัญจิดา | C13: แสนเจริญ | M13: =COUNTIF(D13:L13,"✓") -> 0
A14: 9 | B14: เด็กหญิงพรนัชชา | C14: เปลื้องกลาง | M14: =COUNTIF(D14:L14,"✓") -> 0
A15: 10 | B15: เด็กหญิงจันเอย | C15: ทน | M15: =COUNTIF(D15:L15,"✓") -> 0
A16: 11 | B16: เด็กชายศริตวรรธน์ | C16: การดี | M16: =COUNTIF(D16:L16,"✓") -> 0
A17: 12 | B17: เด็กหญิงมนัสนันท์ | C17: เหลืองอร่าม | M17: =COUNTIF(D17:L17,"✓") -> 0
... A20: 15 | B20: เด็กชายต้นกล้า | C20: ลิทธิศักดิ์ | M20: =COUNTIF(D20:L20,"✓") -> 0
A21: รวมจำนวนนักเรียนที่เล่นแต่ละมุม | D21: =COUNTIF(D6:D20,"✓") -> 0 | E21: =COUNTIF(E6:E20,"✓") -> 0 | F21: =COUNTIF(F6:F20,"✓") -> 0 | G21: =COUNTIF(G6:G20,"✓") -> 0 | H21: =COUNTIF(H6:H20,"✓") -> 0 | I21: =COUNTIF(I6:I20,"✓") -> 0 | J21: =COUNTIF(J6:J20,"✓") -> 0 | K21: =COUNTIF(K6:K20,"✓") -> 0 | L21: =COUNTIF(L6:L20,"✓") -> 0 | M21: =SUM(M6:M20) -> 0
A23: ลงชื่อ .................................................. ผู้บันทึก ( นางสาวชลดา กู่เฟี้ยม )

Sheet สัปดาห์ที่ 7
A1: แบบบันทึกการเล่นตามมุมประสบการณ์ของเด็กปฐมวัยรายสัปดาห์
A2: โรงเรียนเทศบาลบ้านเพ ๑ สังกัดกองการศึกษา เทศบาลตำบลบ้านเพ ชั้น อ.๑/๓
A3: สัปดาห์ที่ 7 | D3: วันที่ .............. ถึง .............. เดือน .............. พ.ศ. ..............
D4: มุมเสริมประสบการณ์ภายในห้องเรียน | J4: มุมเสริมประสบการณ์แหล่งเรียนรู้ นอกห้องเรียน | M4: สรุป มุมที่เล่น
A5: ที่ | B5: ชื่อ | C5: นามสกุล | D5: มุมบล็อก | E5: มุมนิทาน | F5: มุมแต่งตัว | G5: มุมสร้างสรรค์ | H5: มุมบทบาทสมมติ | I5: มุมสื่อ | J5: มุมทราย/น้ำ | K5: มุมธรรมชาติ | L5: มุมออกกำลังกาย | M5: จำนวน มุม
A6: 1 | B6: เด็กชายนันทิพัฒน์ | C6: ฤทธิ์นอก | M6: =COUNTIF(D6:L6,"✓") -> 0
A7: 2 | B7: เด็กหญิงปาณิสรา | C7: บางขุนทด | M7: =COUNTIF(D7:L7,"✓") -> 0
A8: 3 | B8: เด็กหญิงกรายทิพย์ | C8: พันธ์สวัสดิ์ | M8: =COUNTIF(D8:L8,"✓") -> 0
A9: 4 | B9: เด็กหญิงจารุวรรณ | C9: เหมือนประโคน | M9: =COUNTIF(D9:L9,"✓") -> 0
A10: 5 | B10: เด็กชายนิติพัฒน์ | C10: พูดเพราะ | M10: =COUNTIF(D10:L10,"✓") -> 0
A11: 6 | B11: เด็กชายธนวัฒน์ | C11: บางทุ่มแบน | M11: =COUNTIF(D11:L11,"✓") -> 0
A12: 7 | B12: เด็กชายปิยวัฒน์ | C12: กิ่งเกตุ | M12: =COUNTIF(D12:L12,"✓") -> 0
A13: 8 | B13: เด็กหญิงรัญจิดา | C13: แสนเจริญ | M13: =COUNTIF(D13:L13,"✓") -> 0
A14: 9 | B14: เด็กหญิงพรนัชชา | C14: เปลื้องกลาง | M14: =COUNTIF(D14:L14,"✓") -> 0
A15: 10 | B15: เด็กหญิงจันเอย | C15: ทน | M15: =COUNTIF(D15:L15,"✓") -> 0
A16: 11 | B16: เด็กชายศริตวรรธน์ | C16: การดี | M16: =COUNTIF(D16:L16,"✓") -> 0
A17: 12 | B17: เด็กหญิงมนัสนันท์ | C17: เหลืองอร่าม | M17: =COUNTIF(D17:L17,"✓") -> 0
... A20: 15 | B20: เด็กชายต้นกล้า | C20: ลิทธิศักดิ์ | M20: =COUNTIF(D20:L20,"✓") -> 0
A21: รวมจำนวนนักเรียนที่เล่นแต่ละมุม | D21: =COUNTIF(D6:D20,"✓") -> 0 | E21: =COUNTIF(E6:E20,"✓") -> 0 | F21: =COUNTIF(F6:F20,"✓") -> 0 | G21: =COUNTIF(G6:G20,"✓") -> 0 | H21: =COUNTIF(H6:H20,"✓") -> 0 | I21: =COUNTIF(I6:I20,"✓") -> 0 | J21: =COUNTIF(J6:J20,"✓") -> 0 | K21: =COUNTIF(K6:K20,"✓") -> 0 | L21: =COUNTIF(L6:L20,"✓") -> 0 | M21: =SUM(M6:M20) -> 0
A23: ลงชื่อ .................................................. ผู้บันทึก ( นางสาวชลดา กู่เฟี้ยม )

Sheet สัปดาห์ที่ 8
A1: แบบบันทึกการเล่นตามมุมประสบการณ์ของเด็กปฐมวัยรายสัปดาห์
A2: โรงเรียนเทศบาลบ้านเพ ๑ สังกัดกองการศึกษา เทศบาลตำบลบ้านเพ ชั้น อ.๑/๓
A3: สัปดาห์ที่ 8 | D3: วันที่ .............. ถึง .............. เดือน .............. พ.ศ. ..............
D4: มุมเสริมประสบการณ์ภายในห้องเรียน | J4: มุมเสริมประสบการณ์แหล่งเรียนรู้ นอกห้องเรียน | M4: สรุป มุมที่เล่น
A5: ที่ | B5: ชื่อ | C5: นามสกุล | D5: มุมบล็อก | E5: มุมนิทาน | F5: มุมแต่งตัว | G5: มุมสร้างสรรค์ | H5: มุมบทบาทสมมติ | I5: มุมสื่อ | J5: มุมทราย/น้ำ | K5: มุมธรรมชาติ | L5: มุมออกกำลังกาย | M5: จำนวน มุม
A6: 1 | B6: เด็กชายนันทิพัฒน์ | C6: ฤทธิ์นอก | M6: =COUNTIF(D6:L6,"✓") -> 0
A7: 2 | B7: เด็กหญิงปาณิสรา | C7: บางขุนทด | M7: =COUNTIF(D7:L7,"✓") -> 0
A8: 3 | B8: เด็กหญิงกรายทิพย์ | C8: พันธ์สวัสดิ์ | M8: =COUNTIF(D8:L8,"✓") -> 0
A9: 4 | B9: เด็กหญิงจารุวรรณ | C9: เหมือนประโคน | M9: =COUNTIF(D9:L9,"✓") -> 0
A10: 5 | B10: เด็กชายนิติพัฒน์ | C10: พูดเพราะ | M10: =COUNTIF(D10:L10,"✓") -> 0
A11: 6 | B11: เด็กชายธนวัฒน์ | C11: บางทุ่มแบน | M11: =COUNTIF(D11:L11,"✓") -> 0
A12: 7 | B12: เด็กชายปิยวัฒน์ | C12: กิ่งเกตุ | M12: =COUNTIF(D12:L12,"✓") -> 0
A13: 8 | B13: เด็กหญิงรัญจิดา | C13: แสนเจริญ | M13: =COUNTIF(D13:L13,"✓") -> 0
A14: 9 | B14: เด็กหญิงพรนัชชา | C14: เปลื้องกลาง | M14: =COUNTIF(D14:L14,"✓") -> 0
A15: 10 | B15: เด็กหญิงจันเอย | C15: ทน | M15: =COUNTIF(D15:L15,"✓") -> 0
A16: 11 | B16: เด็กชายศริตวรรธน์ | C16: การดี | M16: =COUNTIF(D16:L16,"✓") -> 0
A17: 12 | B17: เด็กหญิงมนัสนันท์ | C17: เหลืองอร่าม | M17: =COUNTIF(D17:L17,"✓") -> 0
... A20: 15 | B20: เด็กชายต้นกล้า | C20: ลิทธิศักดิ์ | M20: =COUNTIF(D20:L20,"✓") -> 0
A21: รวมจำนวนนักเรียนที่เล่นแต่ละมุม | D21: =COUNTIF(D6:D20,"✓") -> 0 | E21: =COUNTIF(E6:E20,"✓") -> 0 | F21: =COUNTIF(F6:F20,"✓") -> 0 | G21: =COUNTIF(G6:G20,"✓") -> 0 | H21: =COUNTIF(H6:H20,"✓") -> 0 | I21: =COUNTIF(I6:I20,"✓") -> 0 | J21: =COUNTIF(J6:J20,"✓") -> 0 | K21: =COUNTIF(K6:K20,"✓") -> 0 | L21: =COUNTIF(L6:L20,"✓") -> 0 | M21: =SUM(M6:M20) -> 0
A23: ลงชื่อ .................................................. ผู้บันทึก ( นางสาวชลดา กู่เฟี้ยม )

Sheet สัปดาห์ที่ 9
A1: แบบบันทึกการเล่นตามมุมประสบการณ์ของเด็กปฐมวัยรายสัปดาห์
A2: โรงเรียนเทศบาลบ้านเพ ๑ สังกัดกองการศึกษา เทศบาลตำบลบ้านเพ ชั้น อ.๑/๓
A3: สัปดาห์ที่ 9 | D3: วันที่ .............. ถึง .............. เดือน .............. พ.ศ. ..............
D4: มุมเสริมประสบการณ์ภายในห้องเรียน | J4: มุมเสริมประสบการณ์แหล่งเรียนรู้ นอกห้องเรียน | M4: สรุป มุมที่เล่น
A5: ที่ | B5: ชื่อ | C5: นามสกุล | D5: มุมบล็อก | E5: มุมนิทาน | F5: มุมแต่งตัว | G5: มุมสร้างสรรค์ | H5: มุมบทบาทสมมติ | I5: มุมสื่อ | J5: มุมทราย/น้ำ | K5: มุมธรรมชาติ | L5: มุมออกกำลังกาย | M5: จำนวน มุม
A6: 1 | B6: เด็กชายนันทิพัฒน์ | C6: ฤทธิ์นอก | M6: =COUNTIF(D6:L6,"✓") -> 0
A7: 2 | B7: เด็กหญิงปาณิสรา | C7: บางขุนทด | M7: =COUNTIF(D7:L7,"✓") -> 0
A8: 3 | B8: เด็กหญิงกรายทิพย์ | C8: พันธ์สวัสดิ์ | M8: =COUNTIF(D8:L8,"✓") -> 0
A9: 4 | B9: เด็กหญิงจารุวรรณ | C9: เหมือนประโคน | M9: =COUNTIF(D9:L9,"✓") -> 0
A10: 5 | B10: เด็กชายนิติพัฒน์ | C10: พูดเพราะ | M10: =COUNTIF(D10:L10,"✓") -> 0
A11: 6 | B11: เด็กชายธนวัฒน์ | C11: บางทุ่มแบน | M11: =COUNTIF(D11:L11,"✓") -> 0
A12: 7 | B12: เด็กชายปิยวัฒน์ | C12: กิ่งเกตุ | M12: =COUNTIF(D12:L12,"✓") -> 0
A13: 8 | B13: เด็กหญิงรัญจิดา | C13: แสนเจริญ | M13: =COUNTIF(D13:L13,"✓") -> 0
A14: 9 | B14: เด็กหญิงพรนัชชา | C14: เปลื้องกลาง | M14: =COUNTIF(D14:L14,"✓") -> 0
A15: 10 | B15: เด็กหญิงจันเอย | C15: ทน | M15: =COUNTIF(D15:L15,"✓") -> 0
A16: 11 | B16: เด็กชายศริตวรรธน์ | C16: การดี | M16: =COUNTIF(D16:L16,"✓") -> 0
A17: 12 | B17: เด็กหญิงมนัสนันท์ | C17: เหลืองอร่าม | M17: =COUNTIF(D17:L17,"✓") -> 0
... A20: 15 | B20: เด็กชายต้นกล้า | C20: ลิทธิศักดิ์ | M20: =COUNTIF(D20:L20,"✓") -> 0
A21: รวมจำนวนนักเรียนที่เล่นแต่ละมุม | D21: =COUNTIF(D6:D20,"✓") -> 0 | E21: =COUNTIF(E6:E20,"✓") -> 0 | F21: =COUNTIF(F6:F20,"✓") -> 0 | G21: =COUNTIF(G6:G20,"✓") -> 0 | H21: =COUNTIF(H6:H20,"✓") -> 0 | I21: =COUNTIF(I6:I20,"✓") -> 0 | J21: =COUNTIF(J6:J20,"✓") -> 0 | K21: =COUNTIF(K6:K20,"✓") -> 0 | L21: =COUNTIF(L6:L20,"✓") -> 0 | M21: =SUM(M6:M20) -> 0
A23: ลงชื่อ .................................................. ผู้บันทึก ( นางสาวชลดา กู่เฟี้ยม )

Sheet สัปดาห์ที่ 10
A1: แบบบันทึกการเล่นตามมุมประสบการณ์ของเด็กปฐมวัยรายสัปดาห์
A2: โรงเรียนเทศบาลบ้านเพ ๑ สังกัดกองการศึกษา เทศบาลตำบลบ้านเพ ชั้น อ.๑/๓
A3: สัปดาห์ที่ 10 | D3: วันที่ .............. ถึง .............. เดือน .............. พ.ศ. ..............
D4: มุมเสริมประสบการณ์ภายในห้องเรียน | J4: มุมเสริมประสบการณ์แหล่งเรียนรู้ นอกห้องเรียน | M4: สรุป มุมที่เล่น
A5: ที่ | B5: ชื่อ | C5: นามสกุล | D5: มุมบล็อก | E5: มุมนิทาน | F5: มุมแต่งตัว | G5: มุมสร้างสรรค์ | H5: มุมบทบาทสมมติ | I5: มุมสื่อ | J5: มุมทราย/น้ำ | K5: มุมธรรมชาติ | L5: มุมออกกำลังกาย | M5: จำนวน มุม
A6: 1 | B6: เด็กชายนันทิพัฒน์ | C6: ฤทธิ์นอก | M6: =COUNTIF(D6:L6,"✓") -> 0
A7: 2 | B7: เด็กหญิงปาณิสรา | C7: บางขุนทด | M7: =COUNTIF(D7:L7,"✓") -> 0
A8: 3 | B8: เด็กหญิงกรายทิพย์ | C8: พันธ์สวัสดิ์ | M8: =COUNTIF(D8:L8,"✓") -> 0
A9: 4 | B9: เด็กหญิงจารุวรรณ | C9: เหมือนประโคน | M9: =COUNTIF(D9:L9,"✓") -> 0
A10: 5 | B10: เด็กชายนิติพัฒน์ | C10: พูดเพราะ | M10: =COUNTIF(D10:L10,"✓") -> 0
A11: 6 | B11: เด็กชายธนวัฒน์ | C11: บางทุ่มแบน | M11: =COUNTIF(D11:L11,"✓") -> 0
A12: 7 | B12: เด็กชายปิยวัฒน์ | C12: กิ่งเกตุ | M12: =COUNTIF(D12:L12,"✓") -> 0
A13: 8 | B13: เด็กหญิงรัญจิดา | C13: แสนเจริญ | M13: =COUNTIF(D13:L13,"✓") -> 0
A14: 9 | B14: เด็กหญิงพรนัชชา | C14: เปลื้องกลาง | M14: =COUNTIF(D14:L14,"✓") -> 0
A15: 10 | B15: เด็กหญิงจันเอย | C15: ทน | M15: =COUNTIF(D15:L15,"✓") -> 0
A16: 11 | B16: เด็กชายศริตวรรธน์ | C16: การดี | M16: =COUNTIF(D16:L16,"✓") -> 0
A17: 12 | B17: เด็กหญิงมนัสนันท์ | C17: เหลืองอร่าม | M17: =COUNTIF(D17:L17,"✓") -> 0
... A20: 15 | B20: เด็กชายต้นกล้า | C20: ลิทธิศักดิ์ | M20: =COUNTIF(D20:L20,"✓") -> 0
A21: รวมจำนวนนักเรียนที่เล่นแต่ละมุม | D21: =COUNTIF(D6:D20,"✓") -> 0 | E21: =COUNTIF(E6:E20,"✓") -> 0 | F21: =COUNTIF(F6:F20,"✓") -> 0 | G21: =COUNTIF(G6:G20,"✓") -> 0 | H21: =COUNTIF(H6:H20,"✓") -> 0 | I21: =COUNTIF(I6:I20,"✓") -> 0 | J21: =COUNTIF(J6:J20,"✓") -> 0 | K21: =COUNTIF(K6:K20,"✓") -> 0 | L21: =COUNTIF(L6:L20,"✓") -> 0 | M21: =SUM(M6:M20) -> 0
A23: ลงชื่อ .................................................. ผู้บันทึก ( นางสาวชลดา กู่เฟี้ยม )

Sheet สัปดาห์ที่ 11
A1: แบบบันทึกการเล่นตามมุมประสบการณ์ของเด็กปฐมวัยรายสัปดาห์
A2: โรงเรียนเทศบาลบ้านเพ ๑ สังกัดกองการศึกษา เทศบาลตำบลบ้านเพ ชั้น อ.๑/๓
A3: สัปดาห์ที่ 11 | D3: วันที่ .............. ถึง .............. เดือน .............. พ.ศ. ..............
D4: มุมเสริมประสบการณ์ภายในห้องเรียน | J4: มุมเสริมประสบการณ์แหล่งเรียนรู้ นอกห้องเรียน | M4: สรุป มุมที่เล่น
A5: ที่ | B5: ชื่อ | C5: นามสกุล | D5: มุมบล็อก | E5: มุมนิทาน | F5: มุมแต่งตัว | G5: มุมสร้างสรรค์ | H5: มุมบทบาทสมมติ | I5: มุมสื่อ | J5: มุมทราย/น้ำ | K5: มุมธรรมชาติ | L5: มุมออกกำลังกาย | M5: จำนวน มุม
A6: 1 | B6: เด็กชายนันทิพัฒน์ | C6: ฤทธิ์นอก | M6: =COUNTIF(D6:L6,"✓") -> 0
A7: 2 | B7: เด็กหญิงปาณิสรา | C7: บางขุนทด | M7: =COUNTIF(D7:L7,"✓") -> 0
A8: 3 | B8: เด็กหญิงกรายทิพย์ | C8: พันธ์สวัสดิ์ | M8: =COUNTIF(D8:L8,"✓") -> 0
A9: 4 | B9: เด็กหญิงจารุวรรณ | C9: เหมือนประโคน | M9: =COUNTIF(D9:L9,"✓") -> 0
A10: 5 | B10: เด็กชายนิติพัฒน์ | C10: พูดเพราะ | M10: =COUNTIF(D10:L10,"✓") -> 0
A11: 6 | B11: เด็กชายธนวัฒน์ | C11: บางทุ่มแบน | M11: =COUNTIF(D11:L11,"✓") -> 0
A12: 7 | B12: เด็กชายปิยวัฒน์ | C12: กิ่งเกตุ | M12: =COUNTIF(D12:L12,"✓") -> 0
A13: 8 | B13: เด็กหญิงรัญจิดา | C13: แสนเจริญ | M13: =COUNTIF(D13:L13,"✓") -> 0
A14: 9 | B14: เด็กหญิงพรนัชชา | C14: เปลื้องกลาง | M14: =COUNTIF(D14:L14,"✓") -> 0
A15: 10 | B15: เด็กหญิงจันเอย | C15: ทน | M15: =COUNTIF(D15:L15,"✓") -> 0
A16: 11 | B16: เด็กชายศริตวรรธน์ | C16: การดี | M16: =COUNTIF(D16:L16,"✓") -> 0
A17: 12 | B17: เด็กหญิงมนัสนันท์ | C17: เหลืองอร่าม | M17: =COUNTIF(D17:L17,"✓") -> 0
... A20: 15 | B20: เด็กชายต้นกล้า | C20: ลิทธิศักดิ์ | M20: =COUNTIF(D20:L20,"✓") -> 0
A21: รวมจำนวนนักเรียนที่เล่นแต่ละมุม | D21: =COUNTIF(D6:D20,"✓") -> 0 | E21: =COUNTIF(E6:E20,"✓") -> 0 | F21: =COUNTIF(F6:F20,"✓") -> 0 | G21: =COUNTIF(G6:G20,"✓") -> 0 | H21: =COUNTIF(H6:H20,"✓") -> 0 | I21: =COUNTIF(I6:I20,"✓") -> 0 | J21: =COUNTIF(J6:J20,"✓") -> 0 | K21: =COUNTIF(K6:K20,"✓") -> 0 | L21: =COUNTIF(L6:L20,"✓") -> 0 | M21: =SUM(M6:M20) -> 0
A23: ลงชื่อ .................................................. ผู้บันทึก ( นางสาวชลดา กู่เฟี้ยม )

Sheet สัปดาห์ที่ 12
A1: แบบบันทึกการเล่นตามมุมประสบการณ์ของเด็กปฐมวัยรายสัปดาห์
A2: โรงเรียนเทศบาลบ้านเพ ๑ สังกัดกองการศึกษา เทศบาลตำบลบ้านเพ ชั้น อ.๑/๓
A3: สัปดาห์ที่ 12 | D3: วันที่ .............. ถึง .............. เดือน .............. พ.ศ. ..............
D4: มุมเสริมประสบการณ์ภายในห้องเรียน | J4: มุมเสริมประสบการณ์แหล่งเรียนรู้ นอกห้องเรียน | M4: สรุป มุมที่เล่น
A5: ที่ | B5: ชื่อ | C5: นามสกุล | D5: มุมบล็อก | E5: มุมนิทาน | F5: มุมแต่งตัว | G5: มุมสร้างสรรค์ | H5: มุมบทบาทสมมติ | I5: มุมสื่อ | J5: มุมทราย/น้ำ | K5: มุมธรรมชาติ | L5: มุมออกกำลังกาย | M5: จำนวน มุม
A6: 1 | B6: เด็กชายนันทิพัฒน์ | C6: ฤทธิ์นอก | M6: =COUNTIF(D6:L6,"✓") -> 0
A7: 2 | B7: เด็กหญิงปาณิสรา | C7: บางขุนทด | M7: =COUNTIF(D7:L7,"✓") -> 0
A8: 3 | B8: เด็กหญิงกรายทิพย์ | C8: พันธ์สวัสดิ์ | M8: =COUNTIF(D8:L8,"✓") -> 0
A9: 4 | B9: เด็กหญิงจารุวรรณ | C9: เหมือนประโคน | M9: =COUNTIF(D9:L9,"✓") -> 0
A10: 5 | B10: เด็กชายนิติพัฒน์ | C10: พูดเพราะ | M10: =COUNTIF(D10:L10,"✓") -> 0
A11: 6 | B11: เด็กชายธนวัฒน์ | C11: บางทุ่มแบน | M11: =COUNTIF(D11:L11,"✓") -> 0
A12: 7 | B12: เด็กชายปิยวัฒน์ | C12: กิ่งเกตุ | M12: =COUNTIF(D12:L12,"✓") -> 0
A13: 8 | B13: เด็กหญิงรัญจิดา | C13: แสนเจริญ | M13: =COUNTIF(D13:L13,"✓") -> 0
A14: 9 | B14: เด็กหญิงพรนัชชา | C14: เปลื้องกลาง | M14: =COUNTIF(D14:L14,"✓") -> 0
A15: 10 | B15: เด็กหญิงจันเอย | C15: ทน | M15: =COUNTIF(D15:L15,"✓") -> 0
A16: 11 | B16: เด็กชายศริตวรรธน์ | C16: การดี | M16: =COUNTIF(D16:L16,"✓") -> 0
A17: 12 | B17: เด็กหญิงมนัสนันท์ | C17: เหลืองอร่าม | M17: =COUNTIF(D17:L17,"✓") -> 0
... A20: 15 | B20: เด็กชายต้นกล้า | C20: ลิทธิศักดิ์ | M20: =COUNTIF(D20:L20,"✓") -> 0
A21: รวมจำนวนนักเรียนที่เล่นแต่ละมุม | D21: =COUNTIF(D6:D20,"✓") -> 0 | E21: =COUNTIF(E6:E20,"✓") -> 0 | F21: =COUNTIF(F6:F20,"✓") -> 0 | G21: =COUNTIF(G6:G20,"✓") -> 0 | H21: =COUNTIF(H6:H20,"✓") -> 0 | I21: =COUNTIF(I6:I20,"✓") -> 0 | J21: =COUNTIF(J6:J20,"✓") -> 0 | K21: =COUNTIF(K6:K20,"✓") -> 0 | L21: =COUNTIF(L6:L20,"✓") -> 0 | M21: =SUM(M6:M20) -> 0
A23: ลงชื่อ .................................................. ผู้บันทึก ( นางสาวชลดา กู่เฟี้ยม )

Sheet สัปดาห์ที่ 13
A1: แบบบันทึกการเล่นตามมุมประสบการณ์ของเด็กปฐมวัยรายสัปดาห์
A2: โรงเรียนเทศบาลบ้านเพ ๑ สังกัดกองการศึกษา เทศบาลตำบลบ้านเพ ชั้น อ.๑/๓
A3: สัปดาห์ที่ 13 | D3: วันที่ .............. ถึง .............. เดือน .............. พ.ศ. ..............
D4: มุมเสริมประสบการณ์ภายในห้องเรียน | J4: มุมเสริมประสบการณ์แหล่งเรียนรู้ นอกห้องเรียน | M4: สรุป มุมที่เล่น
A5: ที่ | B5: ชื่อ | C5: นามสกุล | D5: มุมบล็อก | E5: มุมนิทาน | F5: มุมแต่งตัว | G5: มุมสร้างสรรค์ | H5: มุมบทบาทสมมติ | I5: มุมสื่อ | J5: มุมทราย/น้ำ | K5: มุมธรรมชาติ | L5: มุมออกกำลังกาย | M5: จำนวน มุม
A6: 1 | B6: เด็กชายนันทิพัฒน์ | C6: ฤทธิ์นอก | M6: =COUNTIF(D6:L6,"✓") -> 0
A7: 2 | B7: เด็กหญิงปาณิสรา | C7: บางขุนทด | M7: =COUNTIF(D7:L7,"✓") -> 0
A8: 3 | B8: เด็กหญิงกรายทิพย์ | C8: พันธ์สวัสดิ์ | M8: =COUNTIF(D8:L8,"✓") -> 0
A9: 4 | B9: เด็กหญิงจารุวรรณ | C9: เหมือนประโคน | M9: =COUNTIF(D9:L9,"✓") -> 0
A10: 5 | B10: เด็กชายนิติพัฒน์ | C10: พูดเพราะ | M10: =COUNTIF(D10:L10,"✓") -> 0
A11: 6 | B11: เด็กชายธนวัฒน์ | C11: บางทุ่มแบน | M11: =COUNTIF(D11:L11,"✓") -> 0
A12: 7 | B12: เด็กชายปิยวัฒน์ | C12: กิ่งเกตุ | M12: =COUNTIF(D12:L12,"✓") -> 0
A13: 8 | B13: เด็กหญิงรัญจิดา | C13: แสนเจริญ | M13: =COUNTIF(D13:L13,"✓") -> 0
A14: 9 | B14: เด็กหญิงพรนัชชา | C14: เปลื้องกลาง | M14: =COUNTIF(D14:L14,"✓") -> 0
A15: 10 | B15: เด็กหญิงจันเอย | C15: ทน | M15: =COUNTIF(D15:L15,"✓") -> 0
A16: 11 | B16: เด็กชายศริตวรรธน์ | C16: การดี | M16: =COUNTIF(D16:L16,"✓") -> 0
A17: 12 | B17: เด็กหญิงมนัสนันท์ | C17: เหลืองอร่าม | M17: =COUNTIF(D17:L17,"✓") -> 0
... A20: 15 | B20: เด็กชายต้นกล้า | C20: ลิทธิศักดิ์ | M20: =COUNTIF(D20:L20,"✓") -> 0
A21: รวมจำนวนนักเรียนที่เล่นแต่ละมุม | D21: =COUNTIF(D6:D20,"✓") -> 0 | E21: =COUNTIF(E6:E20,"✓") -> 0 | F21: =COUNTIF(F6:F20,"✓") -> 0 | G21: =COUNTIF(G6:G20,"✓") -> 0 | H21: =COUNTIF(H6:H20,"✓") -> 0 | I21: =COUNTIF(I6:I20,"✓") -> 0 | J21: =COUNTIF(J6:J20,"✓") -> 0 | K21: =COUNTIF(K6:K20,"✓") -> 0 | L21: =COUNTIF(L6:L20,"✓") -> 0 | M21: =SUM(M6:M20) -> 0
A23: ลงชื่อ .................................................. ผู้บันทึก ( นางสาวชลดา กู่เฟี้ยม )

Sheet สัปดาห์ที่ 14
A1: แบบบันทึกการเล่นตามมุมประสบการณ์ของเด็กปฐมวัยรายสัปดาห์
A2: โรงเรียนเทศบาลบ้านเพ ๑ สังกัดกองการศึกษา เทศบาลตำบลบ้านเพ ชั้น อ.๑/๓
A3: สัปดาห์ที่ 14 | D3: วันที่ .............. ถึง .............. เดือน .............. พ.ศ. ..............
D4: มุมเสริมประสบการณ์ภายในห้องเรียน | J4: มุมเสริมประสบการณ์แหล่งเรียนรู้ นอกห้องเรียน | M4: สรุป มุมที่เล่น
A5: ที่ | B5: ชื่อ | C5: นามสกุล | D5: มุมบล็อก | E5: มุมนิทาน | F5: มุมแต่งตัว | G5: มุมสร้างสรรค์ | H5: มุมบทบาทสมมติ | I5: มุมสื่อ | J5: มุมทราย/น้ำ | K5: มุมธรรมชาติ | L5: มุมออกกำลังกาย | M5: จำนวน มุม
A6: 1 | B6: เด็กชายนันทิพัฒน์ | C6: ฤทธิ์นอก | M6: =COUNTIF(D6:L6,"✓") -> 0
A7: 2 | B7: เด็กหญิงปาณิสรา | C7: บางขุนทด | M7: =COUNTIF(D7:L7,"✓") -> 0
A8: 3 | B8: เด็กหญิงกรายทิพย์ | C8: พันธ์สวัสดิ์ | M8: =COUNTIF(D8:L8,"✓") -> 0
A9: 4 | B9: เด็กหญิงจารุวรรณ | C9: เหมือนประโคน | M9: =COUNTIF(D9:L9,"✓") -> 0
A10: 5 | B10: เด็กชายนิติพัฒน์ | C10: พูดเพราะ | M10: =COUNTIF(D10:L10,"✓") -> 0
A11: 6 | B11: เด็กชายธนวัฒน์ | C11: บางทุ่มแบน | M11: =COUNTIF(D11:L11,"✓") -> 0
A12: 7 | B12: เด็กชายปิยวัฒน์ | C12: กิ่งเกตุ | M12: =COUNTIF(D12:L12,"✓") -> 0
A13: 8 | B13: เด็กหญิงรัญจิดา | C13: แสนเจริญ | M13: =COUNTIF(D13:L13,"✓") -> 0
A14: 9 | B14: เด็กหญิงพรนัชชา | C14: เปลื้องกลาง | M14: =COUNTIF(D14:L14,"✓") -> 0
A15: 10 | B15: เด็กหญิงจันเอย | C15: ทน | M15: =COUNTIF(D15:L15,"✓") -> 0
A16: 11 | B16: เด็กชายศริตวรรธน์ | C16: การดี | M16: =COUNTIF(D16:L16,"✓") -> 0
A17: 12 | B17: เด็กหญิงมนัสนันท์ | C17: เหลืองอร่าม | M17: =COUNTIF(D17:L17,"✓") -> 0
... A20: 15 | B20: เด็กชายต้นกล้า | C20: ลิทธิศักดิ์ | M20: =COUNTIF(D20:L20,"✓") -> 0
A21: รวมจำนวนนักเรียนที่เล่นแต่ละมุม | D21: =COUNTIF(D6:D20,"✓") -> 0 | E21: =COUNTIF(E6:E20,"✓") -> 0 | F21: =COUNTIF(F6:F20,"✓") -> 0 | G21: =COUNTIF(G6:G20,"✓") -> 0 | H21: =COUNTIF(H6:H20,"✓") -> 0 | I21: =COUNTIF(I6:I20,"✓") -> 0 | J21: =COUNTIF(J6:J20,"✓") -> 0 | K21: =COUNTIF(K6:K20,"✓") -> 0 | L21: =COUNTIF(L6:L20,"✓") -> 0 | M21: =SUM(M6:M20) -> 0
A23: ลงชื่อ .................................................. ผู้บันทึก ( นางสาวชลดา กู่เฟี้ยม )

Sheet สัปดาห์ที่ 15
A1: แบบบันทึกการเล่นตามมุมประสบการณ์ของเด็กปฐมวัยรายสัปดาห์
A2: โรงเรียนเทศบาลบ้านเพ ๑ สังกัดกองการศึกษา เทศบาลตำบลบ้านเพ ชั้น อ.๑/๓
A3: สัปดาห์ที่ 15 | D3: วันที่ .............. ถึง .............. เดือน .............. พ.ศ. ..............
D4: มุมเสริมประสบการณ์ภายในห้องเรียน | J4: มุมเสริมประสบการณ์แหล่งเรียนรู้ นอกห้องเรียน | M4: สรุป มุมที่เล่น
A5: ที่ | B5: ชื่อ | C5: นามสกุล | D5: มุมบล็อก | E5: มุมนิทาน | F5: มุมแต่งตัว | G5: มุมสร้างสรรค์ | H5: มุมบทบาทสมมติ | I5: มุมสื่อ | J5: มุมทราย/น้ำ | K5: มุมธรรมชาติ | L5: มุมออกกำลังกาย | M5: จำนวน มุม
A6: 1 | B6: เด็กชายนันทิพัฒน์ | C6: ฤทธิ์นอก | M6: =COUNTIF(D6:L6,"✓") -> 0
A7: 2 | B7: เด็กหญิงปาณิสรา | C7: บางขุนทด | M7: =COUNTIF(D7:L7,"✓") -> 0
A8: 3 | B8: เด็กหญิงกรายทิพย์ | C8: พันธ์สวัสดิ์ | M8: =COUNTIF(D8:L8,"✓") -> 0
A9: 4 | B9: เด็กหญิงจารุวรรณ | C9: เหมือนประโคน | M9: =COUNTIF(D9:L9,"✓") -> 0
A10: 5 | B10: เด็กชายนิติพัฒน์ | C10: พูดเพราะ | M10: =COUNTIF(D10:L10,"✓") -> 0
A11: 6 | B11: เด็กชายธนวัฒน์ | C11: บางทุ่มแบน | M11: =COUNTIF(D11:L11,"✓") -> 0
A12: 7 | B12: เด็กชายปิยวัฒน์ | C12: กิ่งเกตุ | M12: =COUNTIF(D12:L12,"✓") -> 0
A13: 8 | B13: เด็กหญิงรัญจิดา | C13: แสนเจริญ | M13: =COUNTIF(D13:L13,"✓") -> 0
A14: 9 | B14: เด็กหญิงพรนัชชา | C14: เปลื้องกลาง | M14: =COUNTIF(D14:L14,"✓") -> 0
A15: 10 | B15: เด็กหญิงจันเอย | C15: ทน | M15: =COUNTIF(D15:L15,"✓") -> 0
A16: 11 | B16: เด็กชายศริตวรรธน์ | C16: การดี | M16: =COUNTIF(D16:L16,"✓") -> 0
A17: 12 | B17: เด็กหญิงมนัสนันท์ | C17: เหลืองอร่าม | M17: =COUNTIF(D17:L17,"✓") -> 0
... A20: 15 | B20: เด็กชายต้นกล้า | C20: ลิทธิศักดิ์ | M20: =COUNTIF(D20:L20,"✓") -> 0
A21: รวมจำนวนนักเรียนที่เล่นแต่ละมุม | D21: =COUNTIF(D6:D20,"✓") -> 0 | E21: =COUNTIF(E6:E20,"✓") -> 0 | F21: =COUNTIF(F6:F20,"✓") -> 0 | G21: =COUNTIF(G6:G20,"✓") -> 0 | H21: =COUNTIF(H6:H20,"✓") -> 0 | I21: =COUNTIF(I6:I20,"✓") -> 0 | J21: =COUNTIF(J6:J20,"✓") -> 0 | K21: =COUNTIF(K6:K20,"✓") -> 0 | L21: =COUNTIF(L6:L20,"✓") -> 0 | M21: =SUM(M6:M20) -> 0
A23: ลงชื่อ .................................................. ผู้บันทึก ( นางสาวชลดา กู่เฟี้ยม )

Sheet สัปดาห์ที่ 16
A1: แบบบันทึกการเล่นตามมุมประสบการณ์ของเด็กปฐมวัยรายสัปดาห์
A2: โรงเรียนเทศบาลบ้านเพ ๑ สังกัดกองการศึกษา เทศบาลตำบลบ้านเพ ชั้น อ.๑/๓
A3: สัปดาห์ที่ 16 | D3: วันที่ .............. ถึง .............. เดือน .............. พ.ศ. ..............
D4: มุมเสริมประสบการณ์ภายในห้องเรียน | J4: มุมเสริมประสบการณ์แหล่งเรียนรู้ นอกห้องเรียน | M4: สรุป มุมที่เล่น
A5: ที่ | B5: ชื่อ | C5: นามสกุล | D5: มุมบล็อก | E5: มุมนิทาน | F5: มุมแต่งตัว | G5: มุมสร้างสรรค์ | H5: มุมบทบาทสมมติ | I5: มุมสื่อ | J5: มุมทราย/น้ำ | K5: มุมธรรมชาติ | L5: มุมออกกำลังกาย | M5: จำนวน มุม
A6: 1 | B6: เด็กชายนันทิพัฒน์ | C6: ฤทธิ์นอก | M6: =COUNTIF(D6:L6,"✓") -> 0
A7: 2 | B7: เด็กหญิงปาณิสรา | C7: บางขุนทด | M7: =COUNTIF(D7:L7,"✓") -> 0
A8: 3 | B8: เด็กหญิงกรายทิพย์ | C8: พันธ์สวัสดิ์ | M8: =COUNTIF(D8:L8,"✓") -> 0
A9: 4 | B9: เด็กหญิงจารุวรรณ | C9: เหมือนประโคน | M9: =COUNTIF(D9:L9,"✓") -> 0
A10: 5 | B10: เด็กชายนิติพัฒน์ | C10: พูดเพราะ | M10: =COUNTIF(D10:L10,"✓") -> 0
A11: 6 | B11: เด็กชายธนวัฒน์ | C11: บางทุ่มแบน | M11: =COUNTIF(D11:L11,"✓") -> 0
A12: 7 | B12: เด็กชายปิยวัฒน์ | C12: กิ่งเกตุ | M12: =COUNTIF(D12:L12,"✓") -> 0
A13: 8 | B13: เด็กหญิงรัญจิดา | C13: แสนเจริญ | M13: =COUNTIF(D13:L13,"✓") -> 0
A14: 9 | B14: เด็กหญิงพรนัชชา | C14: เปลื้องกลาง | M14: =COUNTIF(D14:L14,"✓") -> 0
A15: 10 | B15: เด็กหญิงจันเอย | C15: ทน | M15: =COUNTIF(D15:L15,"✓") -> 0
A16: 11 | B16: เด็กชายศริตวรรธน์ | C16: การดี | M16: =COUNTIF(D16:L16,"✓") -> 0
A17: 12 | B17: เด็กหญิงมนัสนันท์ | C17: เหลืองอร่าม | M17: =COUNTIF(D17:L17,"✓") -> 0
... A20: 15 | B20: เด็กชายต้นกล้า | C20: ลิทธิศักดิ์ | M20: =COUNTIF(D20:L20,"✓") -> 0
A21: รวมจำนวนนักเรียนที่เล่นแต่ละมุม | D21: =COUNTIF(D6:D20,"✓") -> 0 | E21: =COUNTIF(E6:E20,"✓") -> 0 | F21: =COUNTIF(F6:F20,"✓") -> 0 | G21: =COUNTIF(G6:G20,"✓") -> 0 | H21: =COUNTIF(H6:H20,"✓") -> 0 | I21: =COUNTIF(I6:I20,"✓") -> 0 | J21: =COUNTIF(J6:J20,"✓") -> 0 | K21: =COUNTIF(K6:K20,"✓") -> 0 | L21: =COUNTIF(L6:L20,"✓") -> 0 | M21: =SUM(M6:M20) -> 0
A23: ลงชื่อ .................................................. ผู้บันทึก ( นางสาวชลดา กู่เฟี้ยม )

Sheet สัปดาห์ที่ 17
A1: แบบบันทึกการเล่นตามมุมประสบการณ์ของเด็กปฐมวัยรายสัปดาห์
A2: โรงเรียนเทศบาลบ้านเพ ๑ สังกัดกองการศึกษา เทศบาลตำบลบ้านเพ ชั้น อ.๑/๓
A3: สัปดาห์ที่ 17 | D3: วันที่ .............. ถึง .............. เดือน .............. พ.ศ. ..............
D4: มุมเสริมประสบการณ์ภายในห้องเรียน | J4: มุมเสริมประสบการณ์แหล่งเรียนรู้ นอกห้องเรียน | M4: สรุป มุมที่เล่น
A5: ที่ | B5: ชื่อ | C5: นามสกุล | D5: มุมบล็อก | E5: มุมนิทาน | F5: มุมแต่งตัว | G5: มุมสร้างสรรค์ | H5: มุมบทบาทสมมติ | I5: มุมสื่อ | J5: มุมทราย/น้ำ | K5: มุมธรรมชาติ | L5: มุมออกกำลังกาย | M5: จำนวน มุม
A6: 1 | B6: เด็กชายนันทิพัฒน์ | C6: ฤทธิ์นอก | M6: =COUNTIF(D6:L6,"✓") -> 0
A7: 2 | B7: เด็กหญิงปาณิสรา | C7: บางขุนทด | M7: =COUNTIF(D7:L7,"✓") -> 0
A8: 3 | B8: เด็กหญิงกรายทิพย์ | C8: พันธ์สวัสดิ์ | M8: =COUNTIF(D8:L8,"✓") -> 0
A9: 4 | B9: เด็กหญิงจารุวรรณ | C9: เหมือนประโคน | M9: =COUNTIF(D9:L9,"✓") -> 0
A10: 5 | B10: เด็กชายนิติพัฒน์ | C10: พูดเพราะ | M10: =COUNTIF(D10:L10,"✓") -> 0
A11: 6 | B11: เด็กชายธนวัฒน์ | C11: บางทุ่มแบน | M11: =COUNTIF(D11:L11,"✓") -> 0
A12: 7 | B12: เด็กชายปิยวัฒน์ | C12: กิ่งเกตุ | M12: =COUNTIF(D12:L12,"✓") -> 0
A13: 8 | B13: เด็กหญิงรัญจิดา | C13: แสนเจริญ | M13: =COUNTIF(D13:L13,"✓") -> 0
A14: 9 | B14: เด็กหญิงพรนัชชา | C14: เปลื้องกลาง | M14: =COUNTIF(D14:L14,"✓") -> 0
A15: 10 | B15: เด็กหญิงจันเอย | C15: ทน | M15: =COUNTIF(D15:L15,"✓") -> 0
A16: 11 | B16: เด็กชายศริตวรรธน์ | C16: การดี | M16: =COUNTIF(D16:L16,"✓") -> 0
A17: 12 | B17: เด็กหญิงมนัสนันท์ | C17: เหลืองอร่าม | M17: =COUNTIF(D17:L17,"✓") -> 0
... A20: 15 | B20: เด็กชายต้นกล้า | C20: ลิทธิศักดิ์ | M20: =COUNTIF(D20:L20,"✓") -> 0
A21: รวมจำนวนนักเรียนที่เล่นแต่ละมุม | D21: =COUNTIF(D6:D20,"✓") -> 0 | E21: =COUNTIF(E6:E20,"✓") -> 0 | F21: =COUNTIF(F6:F20,"✓") -> 0 | G21: =COUNTIF(G6:G20,"✓") -> 0 | H21: =COUNTIF(H6:H20,"✓") -> 0 | I21: =COUNTIF(I6:I20,"✓") -> 0 | J21: =COUNTIF(J6:J20,"✓") -> 0 | K21: =COUNTIF(K6:K20,"✓") -> 0 | L21: =COUNTIF(L6:L20,"✓") -> 0 | M21: =SUM(M6:M20) -> 0
A23: ลงชื่อ .................................................. ผู้บันทึก ( นางสาวชลดา กู่เฟี้ยม )

Sheet สัปดาห์ที่ 18
A1: แบบบันทึกการเล่นตามมุมประสบการณ์ของเด็กปฐมวัยรายสัปดาห์
A2: โรงเรียนเทศบาลบ้านเพ ๑ สังกัดกองการศึกษา เทศบาลตำบลบ้านเพ ชั้น อ.๑/๓
A3: สัปดาห์ที่ 18 | D3: วันที่ .............. ถึง .............. เดือน .............. พ.ศ. ..............
D4: มุมเสริมประสบการณ์ภายในห้องเรียน | J4: มุมเสริมประสบการณ์แหล่งเรียนรู้ นอกห้องเรียน | M4: สรุป มุมที่เล่น
A5: ที่ | B5: ชื่อ | C5: นามสกุล | D5: มุมบล็อก | E5: มุมนิทาน | F5: มุมแต่งตัว | G5: มุมสร้างสรรค์ | H5: มุมบทบาทสมมติ | I5: มุมสื่อ | J5: มุมทราย/น้ำ | K5: มุมธรรมชาติ | L5: มุมออกกำลังกาย | M5: จำนวน มุม
A6: 1 | B6: เด็กชายนันทิพัฒน์ | C6: ฤทธิ์นอก | M6: =COUNTIF(D6:L6,"✓") -> 0
A7: 2 | B7: เด็กหญิงปาณิสรา | C7: บางขุนทด | M7: =COUNTIF(D7:L7,"✓") -> 0
A8: 3 | B8: เด็กหญิงกรายทิพย์ | C8: พันธ์สวัสดิ์ | M8: =COUNTIF(D8:L8,"✓") -> 0
A9: 4 | B9: เด็กหญิงจารุวรรณ | C9: เหมือนประโคน | M9: =COUNTIF(D9:L9,"✓") -> 0
A10: 5 | B10: เด็กชายนิติพัฒน์ | C10: พูดเพราะ | M10: =COUNTIF(D10:L10,"✓") -> 0
A11: 6 | B11: เด็กชายธนวัฒน์ | C11: บางทุ่มแบน | M11: =COUNTIF(D11:L11,"✓") -> 0
A12: 7 | B12: เด็กชายปิยวัฒน์ | C12: กิ่งเกตุ | M12: =COUNTIF(D12:L12,"✓") -> 0
A13: 8 | B13: เด็กหญิงรัญจิดา | C13: แสนเจริญ | M13: =COUNTIF(D13:L13,"✓") -> 0
A14: 9 | B14: เด็กหญิงพรนัชชา | C14: เปลื้องกลาง | M14: =COUNTIF(D14:L14,"✓") -> 0
A15: 10 | B15: เด็กหญิงจันเอย | C15: ทน | M15: =COUNTIF(D15:L15,"✓") -> 0
A16: 11 | B16: เด็กชายศริตวรรธน์ | C16: การดี | M16: =COUNTIF(D16:L16,"✓") -> 0
A17: 12 | B17: เด็กหญิงมนัสนันท์ | C17: เหลืองอร่าม | M17: =COUNTIF(D17:L17,"✓") -> 0
... A20: 15 | B20: เด็กชายต้นกล้า | C20: ลิทธิศักดิ์ | M20: =COUNTIF(D20:L20,"✓") -> 0
A21: รวมจำนวนนักเรียนที่เล่นแต่ละมุม | D21: =COUNTIF(D6:D20,"✓") -> 0 | E21: =COUNTIF(E6:E20,"✓") -> 0 | F21: =COUNTIF(F6:F20,"✓") -> 0 | G21: =COUNTIF(G6:G20,"✓") -> 0 | H21: =COUNTIF(H6:H20,"✓") -> 0 | I21: =COUNTIF(I6:I20,"✓") -> 0 | J21: =COUNTIF(J6:J20,"✓") -> 0 | K21: =COUNTIF(K6:K20,"✓") -> 0 | L21: =COUNTIF(L6:L20,"✓") -> 0 | M21: =SUM(M6:M20) -> 0
A23: ลงชื่อ .................................................. ผู้บันทึก ( นางสาวชลดา กู่เฟี้ยม )

Sheet สัปดาห์ที่ 19
A1: แบบบันทึกการเล่นตามมุมประสบการณ์ของเด็กปฐมวัยรายสัปดาห์
A2: โรงเรียนเทศบาลบ้านเพ ๑ สังกัดกองการศึกษา เทศบาลตำบลบ้านเพ ชั้น อ.๑/๓
A3: สัปดาห์ที่ 19 | D3: วันที่ .............. ถึง .............. เดือน .............. พ.ศ. ..............
D4: มุมเสริมประสบการณ์ภายในห้องเรียน | J4: มุมเสริมประสบการณ์แหล่งเรียนรู้ นอกห้องเรียน | M4: สรุป มุมที่เล่น
A5: ที่ | B5: ชื่อ | C5: นามสกุล | D5: มุมบล็อก | E5: มุมนิทาน | F5: มุมแต่งตัว | G5: มุมสร้างสรรค์ | H5: มุมบทบาทสมมติ | I5: มุมสื่อ | J5: มุมทราย/น้ำ | K5: มุมธรรมชาติ | L5: มุมออกกำลังกาย | M5: จำนวน มุม
A6: 1 | B6: เด็กชายนันทิพัฒน์ | C6: ฤทธิ์นอก | M6: =COUNTIF(D6:L6,"✓") -> 0
A7: 2 | B7: เด็กหญิงปาณิสรา | C7: บางขุนทด | M7: =COUNTIF(D7:L7,"✓") -> 0
A8: 3 | B8: เด็กหญิงกรายทิพย์ | C8: พันธ์สวัสดิ์ | M8: =COUNTIF(D8:L8,"✓") -> 0
A9: 4 | B9: เด็กหญิงจารุวรรณ | C9: เหมือนประโคน | M9: =COUNTIF(D9:L9,"✓") -> 0
A10: 5 | B10: เด็กชายนิติพัฒน์ | C10: พูดเพราะ | M10: =COUNTIF(D10:L10,"✓") -> 0
A11: 6 | B11: เด็กชายธนวัฒน์ | C11: บางทุ่มแบน | M11: =COUNTIF(D11:L11,"✓") -> 0
A12: 7 | B12: เด็กชายปิยวัฒน์ | C12: กิ่งเกตุ | M12: =COUNTIF(D12:L12,"✓") -> 0
A13: 8 | B13: เด็กหญิงรัญจิดา | C13: แสนเจริญ | M13: =COUNTIF(D13:L13,"✓") -> 0
A14: 9 | B14: เด็กหญิงพรนัชชา | C14: เปลื้องกลาง | M14: =COUNTIF(D14:L14,"✓") -> 0
A15: 10 | B15: เด็กหญิงจันเอย | C15: ทน | M15: =COUNTIF(D15:L15,"✓") -> 0
A16: 11 | B16: เด็กชายศริตวรรธน์ | C16: การดี | M16: =COUNTIF(D16:L16,"✓") -> 0
A17: 12 | B17: เด็กหญิงมนัสนันท์ | C17: เหลืองอร่าม | M17: =COUNTIF(D17:L17,"✓") -> 0
... A20: 15 | B20: เด็กชายต้นกล้า | C20: ลิทธิศักดิ์ | M20: =COUNTIF(D20:L20,"✓") -> 0
A21: รวมจำนวนนักเรียนที่เล่นแต่ละมุม | D21: =COUNTIF(D6:D20,"✓") -> 0 | E21: =COUNTIF(E6:E20,"✓") -> 0 | F21: =COUNTIF(F6:F20,"✓") -> 0 | G21: =COUNTIF(G6:G20,"✓") -> 0 | H21: =COUNTIF(H6:H20,"✓") -> 0 | I21: =COUNTIF(I6:I20,"✓") -> 0 | J21: =COUNTIF(J6:J20,"✓") -> 0 | K21: =COUNTIF(K6:K20,"✓") -> 0 | L21: =COUNTIF(L6:L20,"✓") -> 0 | M21: =SUM(M6:M20) -> 0
A23: ลงชื่อ .................................................. ผู้บันทึก ( นางสาวชลดา กู่เฟี้ยม )

Sheet สัปดาห์ที่ 20
A1: แบบบันทึกการเล่นตามมุมประสบการณ์ของเด็กปฐมวัยรายสัปดาห์
A2: โรงเรียนเทศบาลบ้านเพ ๑ สังกัดกองการศึกษา เทศบาลตำบลบ้านเพ ชั้น อ.๑/๓
A3: สัปดาห์ที่ 20 | D3: วันที่ .............. ถึง .............. เดือน .............. พ.ศ. ..............
D4: มุมเสริมประสบการณ์ภายในห้องเรียน | J4: มุมเสริมประสบการณ์แหล่งเรียนรู้ นอกห้องเรียน | M4: สรุป มุมที่เล่น
A5: ที่ | B5: ชื่อ | C5: นามสกุล | D5: มุมบล็อก | E5: มุมนิทาน | F5: มุมแต่งตัว | G5: มุมสร้างสรรค์ | H5: มุมบทบาทสมมติ | I5: มุมสื่อ | J5: มุมทราย/น้ำ | K5: มุมธรรมชาติ | L5: มุมออกกำลังกาย | M5: จำนวน มุม
A6: 1 | B6: เด็กชายนันทิพัฒน์ | C6: ฤทธิ์นอก | M6: =COUNTIF(D6:L6,"✓") -> 0
A7: 2 | B7: เด็กหญิงปาณิสรา | C7: บางขุนทด | M7: =COUNTIF(D7:L7,"✓") -> 0
A8: 3 | B8: เด็กหญิงกรายทิพย์ | C8: พันธ์สวัสดิ์ | M8: =COUNTIF(D8:L8,"✓") -> 0
A9: 4 | B9: เด็กหญิงจารุวรรณ | C9: เหมือนประโคน | M9: =COUNTIF(D9:L9,"✓") -> 0
A10: 5 | B10: เด็กชายนิติพัฒน์ | C10: พูดเพราะ | M10: =COUNTIF(D10:L10,"✓") -> 0
A11: 6 | B11: เด็กชายธนวัฒน์ | C11: บางทุ่มแบน | M11: =COUNTIF(D11:L11,"✓") -> 0
A12: 7 | B12: เด็กชายปิยวัฒน์ | C12: กิ่งเกตุ | M12: =COUNTIF(D12:L12,"✓") -> 0
A13: 8 | B13: เด็กหญิงรัญจิดา | C13: แสนเจริญ | M13: =COUNTIF(D13:L13,"✓") -> 0
A14: 9 | B14: เด็กหญิงพรนัชชา | C14: เปลื้องกลาง | M14: =COUNTIF(D14:L14,"✓") -> 0
A15: 10 | B15: เด็กหญิงจันเอย | C15: ทน | M15: =COUNTIF(D15:L15,"✓") -> 0
A16: 11 | B16: เด็กชายศริตวรรธน์ | C16: การดี | M16: =COUNTIF(D16:L16,"✓") -> 0
A17: 12 | B17: เด็กหญิงมนัสนันท์ | C17: เหลืองอร่าม | M17: =COUNTIF(D17:L17,"✓") -> 0
... A20: 15 | B20: เด็กชายต้นกล้า | C20: ลิทธิศักดิ์ | M20: =COUNTIF(D20:L20,"✓") -> 0
A21: รวมจำนวนนักเรียนที่เล่นแต่ละมุม | D21: =COUNTIF(D6:D20,"✓") -> 0 | E21: =COUNTIF(E6:E20,"✓") -> 0 | F21: =COUNTIF(F6:F20,"✓") -> 0 | G21: =COUNTIF(G6:G20,"✓") -> 0 | H21: =COUNTIF(H6:H20,"✓") -> 0 | I21: =COUNTIF(I6:I20,"✓") -> 0 | J21: =COUNTIF(J6:J20,"✓") -> 0 | K21: =COUNTIF(K6:K20,"✓") -> 0 | L21: =COUNTIF(L6:L20,"✓") -> 0 | M21: =SUM(M6:M20) -> 0
A23: ลงชื่อ .................................................. ผู้บันทึก ( นางสาวชลดา กู่เฟี้ยม )

Sheet สรุปรายภาคเรียน
A1: สรุปผลการเล่นตามมุมประสบการณ์ รายภาคเรียน ชั้น อ.๑/๓
A2: โรงเรียนเทศบาลบ้านเพ ๑ ปีการศึกษา ๒๕๖๘
A3: ที่ | B3: ชื่อ | C3: นามสกุล | D3: รวม มุมบล็อก | E3: รวม มุมนิทาน | F3: รวม มุมแต่งตัว | G3: รวม มุมสร้างสรรค์ | H3: รวม มุมบทบาทสมมติ | I3: รวม มุมสื่อ | J3: รวม มุมทราย/น้ำ | K3: รวม มุมธรรมชาติ | L3: รวม มุมออกกำลังกาย | M3: รวมทั้งหมด
A4: 1 | B4: เด็กชายนันทิพัฒน์ | C4: ฤทธิ์นอก | D4: =SUMPRODUCT((('สัปดาห์ที่ 1'!D6="✓")*1+('สัปดาห์ที่ 2'!D6="✓")*1+('สัปดาห์ที่ 3'!D6="✓")*1+('สัปดาห์ที่ 4'!D6="✓")*1+('สัปดาห์ที่ 5'!D6="✓")*1+('สัปดาห์ที่ 6'!D6="✓")*1+('สัปดาห์ที่ 7'!D6="✓")*1+('สัปดาห์ที่ 8'!D6="✓")*1+('สัปดาห์ที่ 9'!D6="✓")*1+('สัปดาห์ที่ 10'!D6="✓")*1+('สัปดาห์ที่ 11'!D6="✓")*1+('สัปดาห์ที่ 12'!D6="✓")*1+('สัปดาห์ที่ 13'!D6="✓")*1+('สัปดาห์ที่ 14'!D6="✓")*1+('สัปดาห์ที่ 15'!D6="✓")*1+('สัปดาห์ที่ 16'!D6="✓")*1+('สัปดาห์ที่ 17'!D6="✓")*1+('สัปดาห์ที่ 18'!D6="✓")*1+('สัปดาห์ที่ 19'!D6="✓")*1+('สัปดาห์ที่ 20'!D6="✓")*1)) -> 0 | E4: =SUMPRODUCT((('สัปดาห์ที่ 1'!E6="✓")*1+('สัปดาห์ที่ 2'!E6="✓")*1+('สัปดาห์ที่ 3'!E6="✓")*1+('สัปดาห์ที่ 4'!E6="✓")*1+('สัปดาห์ที่ 5'!E6="✓")*1+('สัปดาห์ที่ 6'!E6="✓")*1+('สัปดาห์ที่ 7'!E6="✓")*1+('สัปดาห์ที่ 8'!E6="✓")*1+('สัปดาห์ที่ 9'!E6="✓")*1+('สัปดาห์ที่ 10'!E6="✓")*1+('สัปดาห์ที่ 11'!E6="✓")*1+('สัปดาห์ที่ 12'!E6="✓")*1+('สัปดาห์ที่ 13'!E6="✓")*1+('สัปดาห์ที่ 14'!E6="✓")*1+('สัปดาห์ที่ 15'!E6="✓")*1+('สัปดาห์ที่ 16'!E6="✓")*1+('สัปดาห์ที่ 17'!E6="✓")*1+('สัปดาห์ที่ 18'!E6="✓")*1+('สัปดาห์ที่ 19'!E6="✓")*1+('สัปดาห์ที่ 20'!E6="✓")*1)) -> 0 | F4: =SUMPRODUCT((('สัปดาห์ที่ 1'!F6="✓")*1+('สัปดาห์ที่ 2'!F6="✓")*1+('สัปดาห์ที่ 3'!F6="✓")*1+('สัปดาห์ที่ 4'!F6="✓")*1+('สัปดาห์ที่ 5'!F6="✓")*1+('สัปดาห์ที่ 6'!F6="✓")*1+('สัปดาห์ที่ 7'!F6="✓")*1+('สัปดาห์ที่ 8'!F6="✓")*1+('สัปดาห์ที่ 9'!F6="✓")*1+('สัปดาห์ที่ 10'!F6="✓")*1+('สัปดาห์ที่ 11'!F6="✓")*1+('สัปดาห์ที่ 12'!F6="✓")*1+('สัปดาห์ที่ 13'!F6="✓")*1+('สัปดาห์ที่ 14'!F6="✓")*1+('สัปดาห์ที่ 15'!F6="✓")*1+('สัปดาห์ที่ 16'!F6="✓")*1+('สัปดาห์ที่ 17'!F6="✓")*1+('สัปดาห์ที่ 18'!F6="✓")*1+('สัปดาห์ที่ 19'!F6="✓")*1+('สัปดาห์ที่ 20'!F6="✓")*1)) -> 0 | G4: =SUMPRODUCT((('สัปดาห์ที่ 1'!G6="✓")*1+('สัปดาห์ที่ 2'!G6="✓")*1+('สัปดาห์ที่ 3'!G6="✓")*1+('สัปดาห์ที่ 4'!G6="✓")*1+('สัปดาห์ที่ 5'!G6="✓")*1+('สัปดาห์ที่ 6'!G6="✓")*1+('สัปดาห์ที่ 7'!G6="✓")*1+('สัปดาห์ที่ 8'!G6="✓")*1+('สัปดาห์ที่ 9'!G6="✓")*1+('สัปดาห์ที่ 10'!G6="✓")*1+('สัปดาห์ที่ 11'!G6="✓")*1+('สัปดาห์ที่ 12'!G6="✓")*1+('สัปดาห์ที่ 13'!G6="✓")*1+('สัปดาห์ที่ 14'!G6="✓")*1+('สัปดาห์ที่ 15'!G6="✓")*1+('สัปดาห์ที่ 16'!G6="✓")*1+('สัปดาห์ที่ 17'!G6="✓")*1+('สัปดาห์ที่ 18'!G6="✓")*1+('สัปดาห์ที่ 19'!G6="✓")*1+('สัปดาห์ที่ 20'!G6="✓")*1)) -> 0 | H4: =SUMPRODUCT((('สัปดาห์ที่ 1'!H6="✓")*1+('สัปดาห์ที่ 2'!H6="✓")*1+('สัปดาห์ที่ 3'!H6="✓")*1+('สัปดาห์ที่ 4'!H6="✓")*1+('สัปดาห์ที่ 5'!H6="✓")*1+('สัปดาห์ที่ 6'!H6="✓")*1+('สัปดาห์ที่ 7'!H6="✓")*1+('สัปดาห์ที่ 8'!H6="✓")*1+('สัปดาห์ที่ 9'!H6="✓")*1+('สัปดาห์ที่ 10'!H6="✓")*1+('สัปดาห์ที่ 11'!H6="✓")*1+('สัปดาห์ที่ 12'!H6="✓")*1+('สัปดาห์ที่ 13'!H6="✓")*1+('สัปดาห์ที่ 14'!H6="✓")*1+('สัปดาห์ที่ 15'!H6="✓")*1+('สัปดาห์ที่ 16'!H6="✓")*1+('สัปดาห์ที่ 17'!H6="✓")*1+('สัปดาห์ที่ 18'!H6="✓")*1+('สัปดาห์ที่ 19'!H6="✓")*1+('สัปดาห์ที่ 20'!H6="✓")*1)) -> 0 | I4: =SUMPRODUCT((('สัปดาห์ที่ 1'!I6="✓")*1+('สัปดาห์ที่ 2'!I6="✓")*1+('สัปดาห์ที่ 3'!I6="✓")*1+('สัปดาห์ที่ 4'!I6="✓")*1+('สัปดาห์ที่ 5'!I6="✓")*1+('สัปดาห์ที่ 6'!I6="✓")*1+('สัปดาห์ที่ 7'!I6="✓")*1+('สัปดาห์ที่ 8'!I6="✓")*1+('สัปดาห์ที่ 9'!I6="✓")*1+('สัปดาห์ที่ 10'!I6="✓")*1+('สัปดาห์ที่ 11'!I6="✓")*1+('สัปดาห์ที่ 12'!I6="✓")*1+('สัปดาห์ที่ 13'!I6="✓")*1+('สัปดาห์ที่ 14'!I6="✓")*1+('สัปดาห์ที่ 15'!I6="✓")*1+('สัปดาห์ที่ 16'!I6="✓")*1+('สัปดาห์ที่ 17'!I6="✓")*1+('สัปดาห์ที่ 18'!I6="✓")*1+('สัปดาห์ที่ 19'!I6="✓")*1+('สัปดาห์ที่ 20'!I6="✓")*1)) -> 0 | J4: =SUMPRODUCT((('สัปดาห์ที่ 1'!J6="✓")*1+('สัปดาห์ที่ 2'!J6="✓")*1+('สัปดาห์ที่ 3'!J6="✓")*1+('สัปดาห์ที่ 4'!J6="✓")*1+('สัปดาห์ที่ 5'!J6="✓")*1+('สัปดาห์ที่ 6'!J6="✓")*1+('สัปดาห์ที่ 7'!J6="✓")*1+('สัปดาห์ที่ 8'!J6="✓")*1+('สัปดาห์ที่ 9'!J6="✓")*1+('สัปดาห์ที่ 10'!J6="✓")*1+('สัปดาห์ที่ 11'!J6="✓")*1+('สัปดาห์ที่ 12'!J6="✓")*1+('สัปดาห์ที่ 13'!J6="✓")*1+('สัปดาห์ที่ 14'!J6="✓")*1+('สัปดาห์ที่ 15'!J6="✓")*1+('สัปดาห์ที่ 16'!J6="✓")*1+('สัปดาห์ที่ 17'!J6="✓")*1+('สัปดาห์ที่ 18'!J6="✓")*1+('สัปดาห์ที่ 19'!J6="✓")*1+('สัปดาห์ที่ 20'!J6="✓")*1)) -> 0 | K4: =SUMPRODUCT((('สัปดาห์ที่ 1'!K6="✓")*1+('สัปดาห์ที่ 2'!K6="✓")*1+('สัปดาห์ที่ 3'!K6="✓")*1+('สัปดาห์ที่ 4'!K6="✓")*1+('สัปดาห์ที่ 5'!K6="✓")*1+('สัปดาห์ที่ 6'!K6="✓")*1+('สัปดาห์ที่ 7'!K6="✓")*1+('สัปดาห์ที่ 8'!K6="✓")*1+('สัปดาห์ที่ 9'!K6="✓")*1+('สัปดาห์ที่ 10'!K6="✓")*1+('สัปดาห์ที่ 11'!K6="✓")*1+('สัปดาห์ที่ 12'!K6="✓")*1+('สัปดาห์ที่ 13'!K6="✓")*1+('สัปดาห์ที่ 14'!K6="✓")*1+('สัปดาห์ที่ 15'!K6="✓")*1+('สัปดาห์ที่ 16'!K6="✓")*1+('สัปดาห์ที่ 17'!K6="✓")*1+('สัปดาห์ที่ 18'!K6="✓")*1+('สัปดาห์ที่ 19'!K6="✓")*1+('สัปดาห์ที่ 20'!K6="✓")*1)) -> 0 | L4: =SUMPRODUCT((('สัปดาห์ที่ 1'!L6="✓")*1+('สัปดาห์ที่ 2'!L6="✓")*1+('สัปดาห์ที่ 3'!L6="✓")*1+('สัปดาห์ที่ 4'!L6="✓")*1+('สัปดาห์ที่ 5'!L6="✓")*1+('สัปดาห์ที่ 6'!L6="✓")*1+('สัปดาห์ที่ 7'!L6="✓")*1+('สัปดาห์ที่ 8'!L6="✓")*1+('สัปดาห์ที่ 9'!L6="✓")*1+('สัปดาห์ที่ 10'!L6="✓")*1+('สัปดาห์ที่ 11'!L6="✓")*1+('สัปดาห์ที่ 12'!L6="✓")*1+('สัปดาห์ที่ 13'!L6="✓")*1+('สัปดาห์ที่ 14'!L6="✓")*1+('สัปดาห์ที่ 15'!L6="✓")*1+('สัปดาห์ที่ 16'!L6="✓")*1+('สัปดาห์ที่ 17'!L6="✓")*1+('สัปดาห์ที่ 18'!L6="✓")*1+('สัปดาห์ที่ 19'!L6="✓")*1+('สัปดาห์ที่ 20'!L6="✓")*1)) -> 0 | M4: =SUM(D4:L4) -> 0
A5: 2 | B5: เด็กหญิงปาณิสรา | C5: บางขุนทด | D5: =SUMPRODUCT((('สัปดาห์ที่ 1'!D7="✓")*1+('สัปดาห์ที่ 2'!D7="✓")*1+('สัปดาห์ที่ 3'!D7="✓")*1+('สัปดาห์ที่ 4'!D7="✓")*1+('สัปดาห์ที่ 5'!D7="✓")*1+('สัปดาห์ที่ 6'!D7="✓")*1+('สัปดาห์ที่ 7'!D7="✓")*1+('สัปดาห์ที่ 8'!D7="✓")*1+('สัปดาห์ที่ 9'!D7="✓")*1+('สัปดาห์ที่ 10'!D7="✓")*1+('สัปดาห์ที่ 11'!D7="✓")*1+('สัปดาห์ที่ 12'!D7="✓")*1+('สัปดาห์ที่ 13'!D7="✓")*1+('สัปดาห์ที่ 14'!D7="✓")*1+('สัปดาห์ที่ 15'!D7="✓")*1+('สัปดาห์ที่ 16'!D7="✓")*1+('สัปดาห์ที่ 17'!D7="✓")*1+('สัปดาห์ที่ 18'!D7="✓")*1+('สัปดาห์ที่ 19'!D7="✓")*1+('สัปดาห์ที่ 20'!D7="✓")*1)) -> 0 | E5: =SUMPRODUCT((('สัปดาห์ที่ 1'!E7="✓")*1+('สัปดาห์ที่ 2'!E7="✓")*1+('สัปดาห์ที่ 3'!E7="✓")*1+('สัปดาห์ที่ 4'!E7="✓")*1+('สัปดาห์ที่ 5'!E7="✓")*1+('สัปดาห์ที่ 6'!E7="✓")*1+('สัปดาห์ที่ 7'!E7="✓")*1+('สัปดาห์ที่ 8'!E7="✓")*1+('สัปดาห์ที่ 9'!E7="✓")*1+('สัปดาห์ที่ 10'!E7="✓")*1+('สัปดาห์ที่ 11'!E7="✓")*1+('สัปดาห์ที่ 12'!E7="✓")*1+('สัปดาห์ที่ 13'!E7="✓")*1+('สัปดาห์ที่ 14'!E7="✓")*1+('สัปดาห์ที่ 15'!E7="✓")*1+('สัปดาห์ที่ 16'!E7="✓")*1+('สัปดาห์ที่ 17'!E7="✓")*1+('สัปดาห์ที่ 18'!E7="✓")*1+('สัปดาห์ที่ 19'!E7="✓")*1+('สัปดาห์ที่ 20'!E7="✓")*1)) -> 0 | F5: =SUMPRODUCT((('สัปดาห์ที่ 1'!F7="✓")*1+('สัปดาห์ที่ 2'!F7="✓")*1+('สัปดาห์ที่ 3'!F7="✓")*1+('สัปดาห์ที่ 4'!F7="✓")*1+('สัปดาห์ที่ 5'!F7="✓")*1+('สัปดาห์ที่ 6'!F7="✓")*1+('สัปดาห์ที่ 7'!F7="✓")*1+('สัปดาห์ที่ 8'!F7="✓")*1+('สัปดาห์ที่ 9'!F7="✓")*1+('สัปดาห์ที่ 10'!F7="✓")*1+('สัปดาห์ที่ 11'!F7="✓")*1+('สัปดาห์ที่ 12'!F7="✓")*1+('สัปดาห์ที่ 13'!F7="✓")*1+('สัปดาห์ที่ 14'!F7="✓")*1+('สัปดาห์ที่ 15'!F7="✓")*1+('สัปดาห์ที่ 16'!F7="✓")*1+('สัปดาห์ที่ 17'!F7="✓")*1+('สัปดาห์ที่ 18'!F7="✓")*1+('สัปดาห์ที่ 19'!F7="✓")*1+('สัปดาห์ที่ 20'!F7="✓")*1)) -> 0 | G5: =SUMPRODUCT((('สัปดาห์ที่ 1'!G7="✓")*1+('สัปดาห์ที่ 2'!G7="✓")*1+('สัปดาห์ที่ 3'!G7="✓")*1+('สัปดาห์ที่ 4'!G7="✓")*1+('สัปดาห์ที่ 5'!G7="✓")*1+('สัปดาห์ที่ 6'!G7="✓")*1+('สัปดาห์ที่ 7'!G7="✓")*1+('สัปดาห์ที่ 8'!G7="✓")*1+('สัปดาห์ที่ 9'!G7="✓")*1+('สัปดาห์ที่ 10'!G7="✓")*1+('สัปดาห์ที่ 11'!G7="✓")*1+('สัปดาห์ที่ 12'!G7="✓")*1+('สัปดาห์ที่ 13'!G7="✓")*1+('สัปดาห์ที่ 14'!G7="✓")*1+('สัปดาห์ที่ 15'!G7="✓")*1+('สัปดาห์ที่ 16'!G7="✓")*1+('สัปดาห์ที่ 17'!G7="✓")*1+('สัปดาห์ที่ 18'!G7="✓")*1+('สัปดาห์ที่ 19'!G7="✓")*1+('สัปดาห์ที่ 20'!G7="✓")*1)) -> 0 | H5: =SUMPRODUCT((('สัปดาห์ที่ 1'!H7="✓")*1+('สัปดาห์ที่ 2'!H7="✓")*1+('สัปดาห์ที่ 3'!H7="✓")*1+('สัปดาห์ที่ 4'!H7="✓")*1+('สัปดาห์ที่ 5'!H7="✓")*1+('สัปดาห์ที่ 6'!H7="✓")*1+('สัปดาห์ที่ 7'!H7="✓")*1+('สัปดาห์ที่ 8'!H7="✓")*1+('สัปดาห์ที่ 9'!H7="✓")*1+('สัปดาห์ที่ 10'!H7="✓")*1+('สัปดาห์ที่ 11'!H7="✓")*1+('สัปดาห์ที่ 12'!H7="✓")*1+('สัปดาห์ที่ 13'!H7="✓")*1+('สัปดาห์ที่ 14'!H7="✓")*1+('สัปดาห์ที่ 15'!H7="✓")*1+('สัปดาห์ที่ 16'!H7="✓")*1+('สัปดาห์ที่ 17'!H7="✓")*1+('สัปดาห์ที่ 18'!H7="✓")*1+('สัปดาห์ที่ 19'!H7="✓")*1+('สัปดาห์ที่ 20'!H7="✓")*1)) -> 0 | I5: =SUMPRODUCT((('สัปดาห์ที่ 1'!I7="✓")*1+('สัปดาห์ที่ 2'!I7="✓")*1+('สัปดาห์ที่ 3'!I7="✓")*1+('สัปดาห์ที่ 4'!I7="✓")*1+('สัปดาห์ที่ 5'!I7="✓")*1+('สัปดาห์ที่ 6'!I7="✓")*1+('สัปดาห์ที่ 7'!I7="✓")*1+('สัปดาห์ที่ 8'!I7="✓")*1+('สัปดาห์ที่ 9'!I7="✓")*1+('สัปดาห์ที่ 10'!I7="✓")*1+('สัปดาห์ที่ 11'!I7="✓")*1+('สัปดาห์ที่ 12'!I7="✓")*1+('สัปดาห์ที่ 13'!I7="✓")*1+('สัปดาห์ที่ 14'!I7="✓")*1+('สัปดาห์ที่ 15'!I7="✓")*1+('สัปดาห์ที่ 16'!I7="✓")*1+('สัปดาห์ที่ 17'!I7="✓")*1+('สัปดาห์ที่ 18'!I7="✓")*1+('สัปดาห์ที่ 19'!I7="✓")*1+('สัปดาห์ที่ 20'!I7="✓")*1)) -> 0 | J5: =SUMPRODUCT((('สัปดาห์ที่ 1'!J7="✓")*1+('สัปดาห์ที่ 2'!J7="✓")*1+('สัปดาห์ที่ 3'!J7="✓")*1+('สัปดาห์ที่ 4'!J7="✓")*1+('สัปดาห์ที่ 5'!J7="✓")*1+('สัปดาห์ที่ 6'!J7="✓")*1+('สัปดาห์ที่ 7'!J7="✓")*1+('สัปดาห์ที่ 8'!J7="✓")*1+('สัปดาห์ที่ 9'!J7="✓")*1+('สัปดาห์ที่ 10'!J7="✓")*1+('สัปดาห์ที่ 11'!J7="✓")*1+('สัปดาห์ที่ 12'!J7="✓")*1+('สัปดาห์ที่ 13'!J7="✓")*1+('สัปดาห์ที่ 14'!J7="✓")*1+('สัปดาห์ที่ 15'!J7="✓")*1+('สัปดาห์ที่ 16'!J7="✓")*1+('สัปดาห์ที่ 17'!J7="✓")*1+('สัปดาห์ที่ 18'!J7="✓")*1+('สัปดาห์ที่ 19'!J7="✓")*1+('สัปดาห์ที่ 20'!J7="✓")*1)) -> 0 | K5: =SUMPRODUCT((('สัปดาห์ที่ 1'!K7="✓")*1+('สัปดาห์ที่ 2'!K7="✓")*1+('สัปดาห์ที่ 3'!K7="✓")*1+('สัปดาห์ที่ 4'!K7="✓")*1+('สัปดาห์ที่ 5'!K7="✓")*1+('สัปดาห์ที่ 6'!K7="✓")*1+('สัปดาห์ที่ 7'!K7="✓")*1+('สัปดาห์ที่ 8'!K7="✓")*1+('สัปดาห์ที่ 9'!K7="✓")*1+('สัปดาห์ที่ 10'!K7="✓")*1+('สัปดาห์ที่ 11'!K7="✓")*1+('สัปดาห์ที่ 12'!K7="✓")*1+('สัปดาห์ที่ 13'!K7="✓")*1+('สัปดาห์ที่ 14'!K7="✓")*1+('สัปดาห์ที่ 15'!K7="✓")*1+('สัปดาห์ที่ 16'!K7="✓")*1+('สัปดาห์ที่ 17'!K7="✓")*1+('สัปดาห์ที่ 18'!K7="✓")*1+('สัปดาห์ที่ 19'!K7="✓")*1+('สัปดาห์ที่ 20'!K7="✓")*1)) -> 0 | L5: =SUMPRODUCT((('สัปดาห์ที่ 1'!L7="✓")*1+('สัปดาห์ที่ 2'!L7="✓")*1+('สัปดาห์ที่ 3'!L7="✓")*1+('สัปดาห์ที่ 4'!L7="✓")*1+('สัปดาห์ที่ 5'!L7="✓")*1+('สัปดาห์ที่ 6'!L7="✓")*1+('สัปดาห์ที่ 7'!L7="✓")*1+('สัปดาห์ที่ 8'!L7="✓")*1+('สัปดาห์ที่ 9'!L7="✓")*1+('สัปดาห์ที่ 10'!L7="✓")*1+('สัปดาห์ที่ 11'!L7="✓")*1+('สัปดาห์ที่ 12'!L7="✓")*1+('สัปดาห์ที่ 13'!L7="✓")*1+('สัปดาห์ที่ 14'!L7="✓")*1+('สัปดาห์ที่ 15'!L7="✓")*1+('สัปดาห์ที่ 16'!L7="✓")*1+('สัปดาห์ที่ 17'!L7="✓")*1+('สัปดาห์ที่ 18'!L7="✓")*1+('สัปดาห์ที่ 19'!L7="✓")*1+('สัปดาห์ที่ 20'!L7="✓")*1)) -> 0 | M5: =SUM(D5:L5) -> 0
A6: 3 | B6: เด็กหญิงกรายทิพย์ | C6: พันธ์สวัสดิ์ | D6: =SUMPRODUCT((('สัปดาห์ที่ 1'!D8="✓")*1+('สัปดาห์ที่ 2'!D8="✓")*1+('สัปดาห์ที่ 3'!D8="✓")*1+('สัปดาห์ที่ 4'!D8="✓")*1+('สัปดาห์ที่ 5'!D8="✓")*1+('สัปดาห์ที่ 6'!D8="✓")*1+('สัปดาห์ที่ 7'!D8="✓")*1+('สัปดาห์ที่ 8'!D8="✓")*1+('สัปดาห์ที่ 9'!D8="✓")*1+('สัปดาห์ที่ 10'!D8="✓")*1+('สัปดาห์ที่ 11'!D8="✓")*1+('สัปดาห์ที่ 12'!D8="✓")*1+('สัปดาห์ที่ 13'!D8="✓")*1+('สัปดาห์ที่ 14'!D8="✓")*1+('สัปดาห์ที่ 15'!D8="✓")*1+('สัปดาห์ที่ 16'!D8="✓")*1+('สัปดาห์ที่ 17'!D8="✓")*1+('สัปดาห์ที่ 18'!D8="✓")*1+('สัปดาห์ที่ 19'!D8="✓")*1+('สัปดาห์ที่ 20'!D8="✓")*1)) -> 0 | E6: =SUMPRODUCT((('สัปดาห์ที่ 1'!E8="✓")*1+('สัปดาห์ที่ 2'!E8="✓")*1+('สัปดาห์ที่ 3'!E8="✓")*1+('สัปดาห์ที่ 4'!E8="✓")*1+('สัปดาห์ที่ 5'!E8="✓")*1+('สัปดาห์ที่ 6'!E8="✓")*1+('สัปดาห์ที่ 7'!E8="✓")*1+('สัปดาห์ที่ 8'!E8="✓")*1+('สัปดาห์ที่ 9'!E8="✓")*1+('สัปดาห์ที่ 10'!E8="✓")*1+('สัปดาห์ที่ 11'!E8="✓")*1+('สัปดาห์ที่ 12'!E8="✓")*1+('สัปดาห์ที่ 13'!E8="✓")*1+('สัปดาห์ที่ 14'!E8="✓")*1+('สัปดาห์ที่ 15'!E8="✓")*1+('สัปดาห์ที่ 16'!E8="✓")*1+('สัปดาห์ที่ 17'!E8="✓")*1+('สัปดาห์ที่ 18'!E8="✓")*1+('สัปดาห์ที่ 19'!E8="✓")*1+('สัปดาห์ที่ 20'!E8="✓")*1)) -> 0 | F6: =SUMPRODUCT((('สัปดาห์ที่ 1'!F8="✓")*1+('สัปดาห์ที่ 2'!F8="✓")*1+('สัปดาห์ที่ 3'!F8="✓")*1+('สัปดาห์ที่ 4'!F8="✓")*1+('สัปดาห์ที่ 5'!F8="✓")*1+('สัปดาห์ที่ 6'!F8="✓")*1+('สัปดาห์ที่ 7'!F8="✓")*1+('สัปดาห์ที่ 8'!F8="✓")*1+('สัปดาห์ที่ 9'!F8="✓")*1+('สัปดาห์ที่ 10'!F8="✓")*1+('สัปดาห์ที่ 11'!F8="✓")*1+('สัปดาห์ที่ 12'!F8="✓")*1+('สัปดาห์ที่ 13'!F8="✓")*1+('สัปดาห์ที่ 14'!F8="✓")*1+('สัปดาห์ที่ 15'!F8="✓")*1+('สัปดาห์ที่ 16'!F8="✓")*1+('สัปดาห์ที่ 17'!F8="✓")*1+('สัปดาห์ที่ 18'!F8="✓")*1+('สัปดาห์ที่ 19'!F8="✓")*1+('สัปดาห์ที่ 20'!F8="✓")*1)) -> 0 | G6: =SUMPRODUCT((('สัปดาห์ที่ 1'!G8="✓")*1+('สัปดาห์ที่ 2'!G8="✓")*1+('สัปดาห์ที่ 3'!G8="✓")*1+('สัปดาห์ที่ 4'!G8="✓")*1+('สัปดาห์ที่ 5'!G8="✓")*1+('สัปดาห์ที่ 6'!G8="✓")*1+('สัปดาห์ที่ 7'!G8="✓")*1+('สัปดาห์ที่ 8'!G8="✓")*1+('สัปดาห์ที่ 9'!G8="✓")*1+('สัปดาห์ที่ 10'!G8="✓")*1+('สัปดาห์ที่ 11'!G8="✓")*1+('สัปดาห์ที่ 12'!G8="✓")*1+('สัปดาห์ที่ 13'!G8="✓")*1+('สัปดาห์ที่ 14'!G8="✓")*1+('สัปดาห์ที่ 15'!G8="✓")*1+('สัปดาห์ที่ 16'!G8="✓")*1+('สัปดาห์ที่ 17'!G8="✓")*1+('สัปดาห์ที่ 18'!G8="✓")*1+('สัปดาห์ที่ 19'!G8="✓")*1+('สัปดาห์ที่ 20'!G8="✓")*1)) -> 0 | H6: =SUMPRODUCT((('สัปดาห์ที่ 1'!H8="✓")*1+('สัปดาห์ที่ 2'!H8="✓")*1+('สัปดาห์ที่ 3'!H8="✓")*1+('สัปดาห์ที่ 4'!H8="✓")*1+('สัปดาห์ที่ 5'!H8="✓")*1+('สัปดาห์ที่ 6'!H8="✓")*1+('สัปดาห์ที่ 7'!H8="✓")*1+('สัปดาห์ที่ 8'!H8="✓")*1+('สัปดาห์ที่ 9'!H8="✓")*1+('สัปดาห์ที่ 10'!H8="✓")*1+('สัปดาห์ที่ 11'!H8="✓")*1+('สัปดาห์ที่ 12'!H8="✓")*1+('สัปดาห์ที่ 13'!H8="✓")*1+('สัปดาห์ที่ 14'!H8="✓")*1+('สัปดาห์ที่ 15'!H8="✓")*1+('สัปดาห์ที่ 16'!H8="✓")*1+('สัปดาห์ที่ 17'!H8="✓")*1+('สัปดาห์ที่ 18'!H8="✓")*1+('สัปดาห์ที่ 19'!H8="✓")*1+('สัปดาห์ที่ 20'!H8="✓")*1)) -> 0 | I6: =SUMPRODUCT((('สัปดาห์ที่ 1'!I8="✓")*1+('สัปดาห์ที่ 2'!I8="✓")*1+('สัปดาห์ที่ 3'!I8="✓")*1+('สัปดาห์ที่ 4'!I8="✓")*1+('สัปดาห์ที่ 5'!I8="✓")*1+('สัปดาห์ที่ 6'!I8="✓")*1+('สัปดาห์ที่ 7'!I8="✓")*1+('สัปดาห์ที่ 8'!I8="✓")*1+('สัปดาห์ที่ 9'!I8="✓")*1+('สัปดาห์ที่ 10'!I8="✓")*1+('สัปดาห์ที่ 11'!I8="✓")*1+('สัปดาห์ที่ 12'!I8="✓")*1+('สัปดาห์ที่ 13'!I8="✓")*1+('สัปดาห์ที่ 14'!I8="✓")*1+('สัปดาห์ที่ 15'!I8="✓")*1+('สัปดาห์ที่ 16'!I8="✓")*1+('สัปดาห์ที่ 17'!I8="✓")*1+('สัปดาห์ที่ 18'!I8="✓")*1+('สัปดาห์ที่ 19'!I8="✓")*1+('สัปดาห์ที่ 20'!I8="✓")*1)) -> 0 | J6: =SUMPRODUCT((('สัปดาห์ที่ 1'!J8="✓")*1+('สัปดาห์ที่ 2'!J8="✓")*1+('สัปดาห์ที่ 3'!J8="✓")*1+('สัปดาห์ที่ 4'!J8="✓")*1+('สัปดาห์ที่ 5'!J8="✓")*1+('สัปดาห์ที่ 6'!J8="✓")*1+('สัปดาห์ที่ 7'!J8="✓")*1+('สัปดาห์ที่ 8'!J8="✓")*1+('สัปดาห์ที่ 9'!J8="✓")*1+('สัปดาห์ที่ 10'!J8="✓")*1+('สัปดาห์ที่ 11'!J8="✓")*1+('สัปดาห์ที่ 12'!J8="✓")*1+('สัปดาห์ที่ 13'!J8="✓")*1+('สัปดาห์ที่ 14'!J8="✓")*1+('สัปดาห์ที่ 15'!J8="✓")*1+('สัปดาห์ที่ 16'!J8="✓")*1+('สัปดาห์ที่ 17'!J8="✓")*1+('สัปดาห์ที่ 18'!J8="✓")*1+('สัปดาห์ที่ 19'!J8="✓")*1+('สัปดาห์ที่ 20'!J8="✓")*1)) -> 0 | K6: =SUMPRODUCT((('สัปดาห์ที่ 1'!K8="✓")*1+('สัปดาห์ที่ 2'!K8="✓")*1+('สัปดาห์ที่ 3'!K8="✓")*1+('สัปดาห์ที่ 4'!K8="✓")*1+('สัปดาห์ที่ 5'!K8="✓")*1+('สัปดาห์ที่ 6'!K8="✓")*1+('สัปดาห์ที่ 7'!K8="✓")*1+('สัปดาห์ที่ 8'!K8="✓")*1+('สัปดาห์ที่ 9'!K8="✓")*1+('สัปดาห์ที่ 10'!K8="✓")*1+('สัปดาห์ที่ 11'!K8="✓")*1+('สัปดาห์ที่ 12'!K8="✓")*1+('สัปดาห์ที่ 13'!K8="✓")*1+('สัปดาห์ที่ 14'!K8="✓")*1+('สัปดาห์ที่ 15'!K8="✓")*1+('สัปดาห์ที่ 16'!K8="✓")*1+('สัปดาห์ที่ 17'!K8="✓")*1+('สัปดาห์ที่ 18'!K8="✓")*1+('สัปดาห์ที่ 19'!K8="✓")*1+('สัปดาห์ที่ 20'!K8="✓")*1)) -> 0 | L6: =SUMPRODUCT((('สัปดาห์ที่ 1'!L8="✓")*1+('สัปดาห์ที่ 2'!L8="✓")*1+('สัปดาห์ที่ 3'!L8="✓")*1+('สัปดาห์ที่ 4'!L8="✓")*1+('สัปดาห์ที่ 5'!L8="✓")*1+('สัปดาห์ที่ 6'!L8="✓")*1+('สัปดาห์ที่ 7'!L8="✓")*1+('สัปดาห์ที่ 8'!L8="✓")*1+('สัปดาห์ที่ 9'!L8="✓")*1+('สัปดาห์ที่ 10'!L8="✓")*1+('สัปดาห์ที่ 11'!L8="✓")*1+('สัปดาห์ที่ 12'!L8="✓")*1+('สัปดาห์ที่ 13'!L8="✓")*1+('สัปดาห์ที่ 14'!L8="✓")*1+('สัปดาห์ที่ 15'!L8="✓")*1+('สัปดาห์ที่ 16'!L8="✓")*1+('สัปดาห์ที่ 17'!L8="✓")*1+('สัปดาห์ที่ 18'!L8="✓")*1+('สัปดาห์ที่ 19'!L8="✓")*1+('สัปดาห์ที่ 20'!L8="✓")*1)) -> 0 | M6: =SUM(D6:L6) -> 0
